{
  "version": 8,
  "blockIdVersion": 11,
  "anchorX": 0,
  "anchorY": 0,
  "anchorZ": 0,
  "blocks": [
    {
      "x": -16,
      "y": 0,
      "z": -12,
      "name": "Rock_Stone"
    },
    {
      "x": -16,
      "y": 1,
      "z": -12,
      "name": "Rock_Stone"
    },
    {
      "x": -16,
      "y": 2,
      "z": -12,
      "name": "Rock_Stone"
    },
    {
      "x": -16,
      "y": 3,
      "z": -12,
      "name": "Rock_Stone"
    },
    {
      "x": -16,
      "y": 4,
      "z": -12,
      "name": "Rock_Stone"
    },
    {
      "x": -16,
      "y": 5,
      "z": -12,
      "name": "Rock_Stone"
    },
    {
      "x": -16,
      "y": 6,
      "z": -12,
      "name": "Soil_Dirt"
    },
    {
      "x": -16,
      "y": 7,
      "z": -12,
      "name": "Soil_Dirt"
    },
    {
      "x": -16,
      "y": 8,
      "z": -12,
      "name": "Soil_Dirt"
    },
    {
      "x": -16,
      "y": 9,
      "z": -12,
      "name": "Soil_Grass"
    },
    {
      "x": -16,
      "y": 10,
      "z": -12,
      "name": "Empty"
    },
    {
      "x": -16,
      "y": 11,
      "z": -12,
      "name": "Empty"
    },
    {
      "x": -16,
      "y": 12,
      "z": -12,
      "name": "Empty"
    },
    {
      "x": -16,
      "y": 13,
      "z": -12,
      "name": "Empty"
    },
    {
      "x": -16,
      "y": 14,
      "z": -12,
      "name": "Empty"
    },
    {
      "x": -16,
      "y": 15,
      "z": -12,
      "name": "Empty"
    },
    {
      "x": -16,
      "y": 16,
      "z": -12,
      "name": "Empty"
    },
    {
      "x": -16,
      "y": 0,
      "z": -11,
      "name": "Rock_Stone"
    },
    {
      "x": -16,
      "y": 1,
      "z": -11,
      "name": "Rock_Stone"
    },
    {
      "x": -16,
      "y": 2,
      "z": -11,
      "name": "Rock_Stone"
    },
    {
      "x": -16,
      "y": 3,
      "z": -11,
      "name": "Rock_Stone"
    },
    {
      "x": -16,
      "y": 4,
      "z": -11,
      "name": "Rock_Stone"
    },
    {
      "x": -16,
      "y": 5,
      "z": -11,
      "name": "Rock_Stone"
    },
    {
      "x": -16,
      "y": 6,
      "z": -11,
      "name": "Soil_Dirt"
    },
    {
      "x": -16,
      "y": 7,
      "z": -11,
      "name": "Soil_Dirt"
    },
    {
      "x": -16,
      "y": 8,
      "z": -11,
      "name": "Soil_Dirt"
    },
    {
      "x": -16,
      "y": 9,
      "z": -11,
      "name": "Soil_Grass"
    },
    {
      "x": -16,
      "y": 10,
      "z": -11,
      "name": "Empty"
    },
    {
      "x": -16,
      "y": 11,
      "z": -11,
      "name": "Empty"
    },
    {
      "x": -16,
      "y": 12,
      "z": -11,
      "name": "Empty"
    },
    {
      "x": -16,
      "y": 13,
      "z": -11,
      "name": "Empty"
    },
    {
      "x": -16,
      "y": 14,
      "z": -11,
      "name": "Empty"
    },
    {
      "x": -16,
      "y": 15,
      "z": -11,
      "name": "Empty"
    },
    {
      "x": -16,
      "y": 16,
      "z": -11,
      "name": "Empty"
    },
    {
      "x": -16,
      "y": 0,
      "z": -10,
      "name": "Rock_Stone"
    },
    {
      "x": -16,
      "y": 1,
      "z": -10,
      "name": "Rock_Stone"
    },
    {
      "x": -16,
      "y": 2,
      "z": -10,
      "name": "Rock_Stone"
    },
    {
      "x": -16,
      "y": 3,
      "z": -10,
      "name": "Rock_Stone"
    },
    {
      "x": -16,
      "y": 4,
      "z": -10,
      "name": "Rock_Stone"
    },
    {
      "x": -16,
      "y": 5,
      "z": -10,
      "name": "Rock_Stone"
    },
    {
      "x": -16,
      "y": 6,
      "z": -10,
      "name": "Soil_Dirt"
    },
    {
      "x": -16,
      "y": 7,
      "z": -10,
      "name": "Soil_Dirt"
    },
    {
      "x": -16,
      "y": 8,
      "z": -10,
      "name": "Soil_Dirt"
    },
    {
      "x": -16,
      "y": 9,
      "z": -10,
      "name": "Soil_Grass"
    },
    {
      "x": -16,
      "y": 10,
      "z": -10,
      "name": "Empty"
    },
    {
      "x": -16,
      "y": 11,
      "z": -10,
      "name": "Empty"
    },
    {
      "x": -16,
      "y": 12,
      "z": -10,
      "name": "Empty"
    },
    {
      "x": -16,
      "y": 13,
      "z": -10,
      "name": "Empty"
    },
    {
      "x": -16,
      "y": 14,
      "z": -10,
      "name": "Empty"
    },
    {
      "x": -16,
      "y": 15,
      "z": -10,
      "name": "Empty"
    },
    {
      "x": -16,
      "y": 16,
      "z": -10,
      "name": "Empty"
    },
    {
      "x": -16,
      "y": 0,
      "z": -9,
      "name": "Rock_Stone"
    },
    {
      "x": -16,
      "y": 1,
      "z": -9,
      "name": "Rock_Stone"
    },
    {
      "x": -16,
      "y": 2,
      "z": -9,
      "name": "Rock_Stone"
    },
    {
      "x": -16,
      "y": 3,
      "z": -9,
      "name": "Rock_Stone"
    },
    {
      "x": -16,
      "y": 4,
      "z": -9,
      "name": "Rock_Stone"
    },
    {
      "x": -16,
      "y": 5,
      "z": -9,
      "name": "Rock_Stone"
    },
    {
      "x": -16,
      "y": 6,
      "z": -9,
      "name": "Soil_Dirt"
    },
    {
      "x": -16,
      "y": 7,
      "z": -9,
      "name": "Soil_Dirt"
    },
    {
      "x": -16,
      "y": 8,
      "z": -9,
      "name": "Soil_Dirt"
    },
    {
      "x": -16,
      "y": 9,
      "z": -9,
      "name": "Soil_Grass"
    },
    {
      "x": -16,
      "y": 10,
      "z": -9,
      "name": "Empty"
    },
    {
      "x": -16,
      "y": 11,
      "z": -9,
      "name": "Empty"
    },
    {
      "x": -16,
      "y": 12,
      "z": -9,
      "name": "Empty"
    },
    {
      "x": -16,
      "y": 13,
      "z": -9,
      "name": "Empty"
    },
    {
      "x": -16,
      "y": 14,
      "z": -9,
      "name": "Empty"
    },
    {
      "x": -16,
      "y": 15,
      "z": -9,
      "name": "Empty"
    },
    {
      "x": -16,
      "y": 16,
      "z": -9,
      "name": "Empty"
    },
    {
      "x": -16,
      "y": 0,
      "z": -8,
      "name": "Rock_Stone"
    },
    {
      "x": -16,
      "y": 1,
      "z": -8,
      "name": "Rock_Stone"
    },
    {
      "x": -16,
      "y": 2,
      "z": -8,
      "name": "Rock_Stone"
    },
    {
      "x": -16,
      "y": 3,
      "z": -8,
      "name": "Rock_Stone"
    },
    {
      "x": -16,
      "y": 4,
      "z": -8,
      "name": "Rock_Stone"
    },
    {
      "x": -16,
      "y": 5,
      "z": -8,
      "name": "Rock_Stone"
    },
    {
      "x": -16,
      "y": 6,
      "z": -8,
      "name": "Soil_Dirt"
    },
    {
      "x": -16,
      "y": 7,
      "z": -8,
      "name": "Soil_Dirt"
    },
    {
      "x": -16,
      "y": 8,
      "z": -8,
      "name": "Soil_Dirt"
    },
    {
      "x": -16,
      "y": 9,
      "z": -8,
      "name": "Soil_Grass"
    },
    {
      "x": -16,
      "y": 10,
      "z": -8,
      "name": "Empty"
    },
    {
      "x": -16,
      "y": 11,
      "z": -8,
      "name": "Empty"
    },
    {
      "x": -16,
      "y": 12,
      "z": -8,
      "name": "Empty"
    },
    {
      "x": -16,
      "y": 13,
      "z": -8,
      "name": "Empty"
    },
    {
      "x": -16,
      "y": 14,
      "z": -8,
      "name": "Empty"
    },
    {
      "x": -16,
      "y": 15,
      "z": -8,
      "name": "Empty"
    },
    {
      "x": -16,
      "y": 16,
      "z": -8,
      "name": "Empty"
    },
    {
      "x": -16,
      "y": 0,
      "z": -7,
      "name": "Rock_Stone"
    },
    {
      "x": -16,
      "y": 1,
      "z": -7,
      "name": "Rock_Stone"
    },
    {
      "x": -16,
      "y": 2,
      "z": -7,
      "name": "Rock_Stone"
    },
    {
      "x": -16,
      "y": 3,
      "z": -7,
      "name": "Rock_Stone"
    },
    {
      "x": -16,
      "y": 4,
      "z": -7,
      "name": "Rock_Stone"
    },
    {
      "x": -16,
      "y": 5,
      "z": -7,
      "name": "Rock_Stone"
    },
    {
      "x": -16,
      "y": 6,
      "z": -7,
      "name": "Soil_Dirt"
    },
    {
      "x": -16,
      "y": 7,
      "z": -7,
      "name": "Soil_Dirt"
    },
    {
      "x": -16,
      "y": 8,
      "z": -7,
      "name": "Soil_Dirt"
    },
    {
      "x": -16,
      "y": 9,
      "z": -7,
      "name": "Soil_Grass"
    },
    {
      "x": -16,
      "y": 10,
      "z": -7,
      "name": "Empty"
    },
    {
      "x": -16,
      "y": 11,
      "z": -7,
      "name": "Empty"
    },
    {
      "x": -16,
      "y": 12,
      "z": -7,
      "name": "Empty"
    },
    {
      "x": -16,
      "y": 13,
      "z": -7,
      "name": "Empty"
    },
    {
      "x": -16,
      "y": 14,
      "z": -7,
      "name": "Empty"
    },
    {
      "x": -16,
      "y": 15,
      "z": -7,
      "name": "Empty"
    },
    {
      "x": -16,
      "y": 16,
      "z": -7,
      "name": "Empty"
    },
    {
      "x": -16,
      "y": 0,
      "z": -6,
      "name": "Rock_Stone"
    },
    {
      "x": -16,
      "y": 1,
      "z": -6,
      "name": "Rock_Stone"
    },
    {
      "x": -16,
      "y": 2,
      "z": -6,
      "name": "Rock_Stone"
    },
    {
      "x": -16,
      "y": 3,
      "z": -6,
      "name": "Rock_Stone"
    },
    {
      "x": -16,
      "y": 4,
      "z": -6,
      "name": "Rock_Stone"
    },
    {
      "x": -16,
      "y": 5,
      "z": -6,
      "name": "Rock_Stone"
    },
    {
      "x": -16,
      "y": 6,
      "z": -6,
      "name": "Soil_Dirt"
    },
    {
      "x": -16,
      "y": 7,
      "z": -6,
      "name": "Soil_Dirt"
    },
    {
      "x": -16,
      "y": 8,
      "z": -6,
      "name": "Soil_Dirt"
    },
    {
      "x": -16,
      "y": 9,
      "z": -6,
      "name": "Soil_Grass"
    },
    {
      "x": -16,
      "y": 10,
      "z": -6,
      "name": "Empty"
    },
    {
      "x": -16,
      "y": 11,
      "z": -6,
      "name": "Empty"
    },
    {
      "x": -16,
      "y": 12,
      "z": -6,
      "name": "Empty"
    },
    {
      "x": -16,
      "y": 13,
      "z": -6,
      "name": "Empty"
    },
    {
      "x": -16,
      "y": 14,
      "z": -6,
      "name": "Empty"
    },
    {
      "x": -16,
      "y": 15,
      "z": -6,
      "name": "Empty"
    },
    {
      "x": -16,
      "y": 16,
      "z": -6,
      "name": "Empty"
    },
    {
      "x": -16,
      "y": 0,
      "z": -5,
      "name": "Rock_Stone"
    },
    {
      "x": -16,
      "y": 1,
      "z": -5,
      "name": "Rock_Stone"
    },
    {
      "x": -16,
      "y": 2,
      "z": -5,
      "name": "Rock_Stone"
    },
    {
      "x": -16,
      "y": 3,
      "z": -5,
      "name": "Rock_Stone"
    },
    {
      "x": -16,
      "y": 4,
      "z": -5,
      "name": "Rock_Stone"
    },
    {
      "x": -16,
      "y": 5,
      "z": -5,
      "name": "Rock_Stone"
    },
    {
      "x": -16,
      "y": 6,
      "z": -5,
      "name": "Soil_Dirt"
    },
    {
      "x": -16,
      "y": 7,
      "z": -5,
      "name": "Soil_Dirt"
    },
    {
      "x": -16,
      "y": 8,
      "z": -5,
      "name": "Soil_Dirt"
    },
    {
      "x": -16,
      "y": 9,
      "z": -5,
      "name": "Soil_Grass"
    },
    {
      "x": -16,
      "y": 10,
      "z": -5,
      "name": "Empty"
    },
    {
      "x": -16,
      "y": 11,
      "z": -5,
      "name": "Empty"
    },
    {
      "x": -16,
      "y": 12,
      "z": -5,
      "name": "Empty"
    },
    {
      "x": -16,
      "y": 13,
      "z": -5,
      "name": "Empty"
    },
    {
      "x": -16,
      "y": 14,
      "z": -5,
      "name": "Empty"
    },
    {
      "x": -16,
      "y": 15,
      "z": -5,
      "name": "Empty"
    },
    {
      "x": -16,
      "y": 16,
      "z": -5,
      "name": "Empty"
    },
    {
      "x": -16,
      "y": 0,
      "z": -4,
      "name": "Rock_Stone"
    },
    {
      "x": -16,
      "y": 1,
      "z": -4,
      "name": "Rock_Stone"
    },
    {
      "x": -16,
      "y": 2,
      "z": -4,
      "name": "Rock_Stone"
    },
    {
      "x": -16,
      "y": 3,
      "z": -4,
      "name": "Rock_Stone"
    },
    {
      "x": -16,
      "y": 4,
      "z": -4,
      "name": "Rock_Stone"
    },
    {
      "x": -16,
      "y": 5,
      "z": -4,
      "name": "Rock_Stone"
    },
    {
      "x": -16,
      "y": 6,
      "z": -4,
      "name": "Soil_Dirt"
    },
    {
      "x": -16,
      "y": 7,
      "z": -4,
      "name": "Soil_Dirt"
    },
    {
      "x": -16,
      "y": 8,
      "z": -4,
      "name": "Soil_Dirt"
    },
    {
      "x": -16,
      "y": 9,
      "z": -4,
      "name": "Soil_Grass"
    },
    {
      "x": -16,
      "y": 10,
      "z": -4,
      "name": "Empty"
    },
    {
      "x": -16,
      "y": 11,
      "z": -4,
      "name": "Empty"
    },
    {
      "x": -16,
      "y": 12,
      "z": -4,
      "name": "Empty"
    },
    {
      "x": -16,
      "y": 13,
      "z": -4,
      "name": "Empty"
    },
    {
      "x": -16,
      "y": 14,
      "z": -4,
      "name": "Empty"
    },
    {
      "x": -16,
      "y": 15,
      "z": -4,
      "name": "Empty"
    },
    {
      "x": -16,
      "y": 16,
      "z": -4,
      "name": "Empty"
    },
    {
      "x": -16,
      "y": 0,
      "z": -3,
      "name": "Rock_Stone"
    },
    {
      "x": -16,
      "y": 1,
      "z": -3,
      "name": "Rock_Stone"
    },
    {
      "x": -16,
      "y": 2,
      "z": -3,
      "name": "Rock_Stone"
    },
    {
      "x": -16,
      "y": 3,
      "z": -3,
      "name": "Rock_Stone"
    },
    {
      "x": -16,
      "y": 4,
      "z": -3,
      "name": "Rock_Stone"
    },
    {
      "x": -16,
      "y": 5,
      "z": -3,
      "name": "Rock_Stone"
    },
    {
      "x": -16,
      "y": 6,
      "z": -3,
      "name": "Soil_Dirt"
    },
    {
      "x": -16,
      "y": 7,
      "z": -3,
      "name": "Soil_Dirt"
    },
    {
      "x": -16,
      "y": 8,
      "z": -3,
      "name": "Soil_Dirt"
    },
    {
      "x": -16,
      "y": 9,
      "z": -3,
      "name": "Soil_Grass"
    },
    {
      "x": -16,
      "y": 10,
      "z": -3,
      "name": "Empty"
    },
    {
      "x": -16,
      "y": 11,
      "z": -3,
      "name": "Empty"
    },
    {
      "x": -16,
      "y": 12,
      "z": -3,
      "name": "Empty"
    },
    {
      "x": -16,
      "y": 13,
      "z": -3,
      "name": "Empty"
    },
    {
      "x": -16,
      "y": 14,
      "z": -3,
      "name": "Empty"
    },
    {
      "x": -16,
      "y": 15,
      "z": -3,
      "name": "Empty"
    },
    {
      "x": -16,
      "y": 16,
      "z": -3,
      "name": "Empty"
    },
    {
      "x": -16,
      "y": 0,
      "z": -2,
      "name": "Rock_Stone"
    },
    {
      "x": -16,
      "y": 1,
      "z": -2,
      "name": "Rock_Stone"
    },
    {
      "x": -16,
      "y": 2,
      "z": -2,
      "name": "Rock_Stone"
    },
    {
      "x": -16,
      "y": 3,
      "z": -2,
      "name": "Rock_Stone"
    },
    {
      "x": -16,
      "y": 4,
      "z": -2,
      "name": "Rock_Stone"
    },
    {
      "x": -16,
      "y": 5,
      "z": -2,
      "name": "Rock_Stone"
    },
    {
      "x": -16,
      "y": 6,
      "z": -2,
      "name": "Soil_Dirt"
    },
    {
      "x": -16,
      "y": 7,
      "z": -2,
      "name": "Soil_Dirt"
    },
    {
      "x": -16,
      "y": 8,
      "z": -2,
      "name": "Soil_Dirt"
    },
    {
      "x": -16,
      "y": 9,
      "z": -2,
      "name": "Soil_Grass"
    },
    {
      "x": -16,
      "y": 10,
      "z": -2,
      "name": "Empty"
    },
    {
      "x": -16,
      "y": 11,
      "z": -2,
      "name": "Empty"
    },
    {
      "x": -16,
      "y": 12,
      "z": -2,
      "name": "Empty"
    },
    {
      "x": -16,
      "y": 13,
      "z": -2,
      "name": "Empty"
    },
    {
      "x": -16,
      "y": 14,
      "z": -2,
      "name": "Empty"
    },
    {
      "x": -16,
      "y": 15,
      "z": -2,
      "name": "Empty"
    },
    {
      "x": -16,
      "y": 16,
      "z": -2,
      "name": "Empty"
    },
    {
      "x": -16,
      "y": 0,
      "z": -1,
      "name": "Rock_Stone"
    },
    {
      "x": -16,
      "y": 1,
      "z": -1,
      "name": "Rock_Stone"
    },
    {
      "x": -16,
      "y": 2,
      "z": -1,
      "name": "Rock_Stone"
    },
    {
      "x": -16,
      "y": 3,
      "z": -1,
      "name": "Rock_Stone"
    },
    {
      "x": -16,
      "y": 4,
      "z": -1,
      "name": "Rock_Stone"
    },
    {
      "x": -16,
      "y": 5,
      "z": -1,
      "name": "Rock_Stone"
    },
    {
      "x": -16,
      "y": 6,
      "z": -1,
      "name": "Soil_Dirt"
    },
    {
      "x": -16,
      "y": 7,
      "z": -1,
      "name": "Soil_Dirt"
    },
    {
      "x": -16,
      "y": 8,
      "z": -1,
      "name": "Soil_Dirt"
    },
    {
      "x": -16,
      "y": 9,
      "z": -1,
      "name": "Soil_Grass"
    },
    {
      "x": -16,
      "y": 10,
      "z": -1,
      "name": "Empty"
    },
    {
      "x": -16,
      "y": 11,
      "z": -1,
      "name": "Empty"
    },
    {
      "x": -16,
      "y": 12,
      "z": -1,
      "name": "Empty"
    },
    {
      "x": -16,
      "y": 13,
      "z": -1,
      "name": "Empty"
    },
    {
      "x": -16,
      "y": 14,
      "z": -1,
      "name": "Empty"
    },
    {
      "x": -16,
      "y": 15,
      "z": -1,
      "name": "Empty"
    },
    {
      "x": -16,
      "y": 16,
      "z": -1,
      "name": "Empty"
    },
    {
      "x": -16,
      "y": 0,
      "z": 0,
      "name": "Rock_Stone"
    },
    {
      "x": -16,
      "y": 1,
      "z": 0,
      "name": "Rock_Stone"
    },
    {
      "x": -16,
      "y": 2,
      "z": 0,
      "name": "Rock_Stone"
    },
    {
      "x": -16,
      "y": 3,
      "z": 0,
      "name": "Rock_Stone"
    },
    {
      "x": -16,
      "y": 4,
      "z": 0,
      "name": "Rock_Stone"
    },
    {
      "x": -16,
      "y": 5,
      "z": 0,
      "name": "Rock_Stone"
    },
    {
      "x": -16,
      "y": 6,
      "z": 0,
      "name": "Soil_Dirt"
    },
    {
      "x": -16,
      "y": 7,
      "z": 0,
      "name": "Soil_Dirt"
    },
    {
      "x": -16,
      "y": 8,
      "z": 0,
      "name": "Soil_Dirt"
    },
    {
      "x": -16,
      "y": 9,
      "z": 0,
      "name": "Soil_Grass"
    },
    {
      "x": -16,
      "y": 10,
      "z": 0,
      "name": "Empty"
    },
    {
      "x": -16,
      "y": 11,
      "z": 0,
      "name": "Empty"
    },
    {
      "x": -16,
      "y": 12,
      "z": 0,
      "name": "Empty"
    },
    {
      "x": -16,
      "y": 13,
      "z": 0,
      "name": "Empty"
    },
    {
      "x": -16,
      "y": 14,
      "z": 0,
      "name": "Empty"
    },
    {
      "x": -16,
      "y": 15,
      "z": 0,
      "name": "Empty"
    },
    {
      "x": -16,
      "y": 16,
      "z": 0,
      "name": "Empty"
    },
    {
      "x": -16,
      "y": 0,
      "z": 1,
      "name": "Rock_Stone"
    },
    {
      "x": -16,
      "y": 1,
      "z": 1,
      "name": "Rock_Stone"
    },
    {
      "x": -16,
      "y": 2,
      "z": 1,
      "name": "Rock_Stone"
    },
    {
      "x": -16,
      "y": 3,
      "z": 1,
      "name": "Rock_Stone"
    },
    {
      "x": -16,
      "y": 4,
      "z": 1,
      "name": "Rock_Stone"
    },
    {
      "x": -16,
      "y": 5,
      "z": 1,
      "name": "Rock_Stone"
    },
    {
      "x": -16,
      "y": 6,
      "z": 1,
      "name": "Soil_Dirt"
    },
    {
      "x": -16,
      "y": 7,
      "z": 1,
      "name": "Soil_Dirt"
    },
    {
      "x": -16,
      "y": 8,
      "z": 1,
      "name": "Soil_Dirt"
    },
    {
      "x": -16,
      "y": 9,
      "z": 1,
      "name": "Soil_Grass"
    },
    {
      "x": -16,
      "y": 10,
      "z": 1,
      "name": "Empty"
    },
    {
      "x": -16,
      "y": 11,
      "z": 1,
      "name": "Empty"
    },
    {
      "x": -16,
      "y": 12,
      "z": 1,
      "name": "Empty"
    },
    {
      "x": -16,
      "y": 13,
      "z": 1,
      "name": "Empty"
    },
    {
      "x": -16,
      "y": 14,
      "z": 1,
      "name": "Empty"
    },
    {
      "x": -16,
      "y": 15,
      "z": 1,
      "name": "Empty"
    },
    {
      "x": -16,
      "y": 16,
      "z": 1,
      "name": "Empty"
    },
    {
      "x": -16,
      "y": 0,
      "z": 2,
      "name": "Rock_Stone"
    },
    {
      "x": -16,
      "y": 1,
      "z": 2,
      "name": "Rock_Stone"
    },
    {
      "x": -16,
      "y": 2,
      "z": 2,
      "name": "Rock_Stone"
    },
    {
      "x": -16,
      "y": 3,
      "z": 2,
      "name": "Rock_Stone"
    },
    {
      "x": -16,
      "y": 4,
      "z": 2,
      "name": "Rock_Stone"
    },
    {
      "x": -16,
      "y": 5,
      "z": 2,
      "name": "Rock_Stone"
    },
    {
      "x": -16,
      "y": 6,
      "z": 2,
      "name": "Soil_Dirt"
    },
    {
      "x": -16,
      "y": 7,
      "z": 2,
      "name": "Soil_Dirt"
    },
    {
      "x": -16,
      "y": 8,
      "z": 2,
      "name": "Soil_Dirt"
    },
    {
      "x": -16,
      "y": 9,
      "z": 2,
      "name": "Soil_Grass"
    },
    {
      "x": -16,
      "y": 10,
      "z": 2,
      "name": "Empty"
    },
    {
      "x": -16,
      "y": 11,
      "z": 2,
      "name": "Empty"
    },
    {
      "x": -16,
      "y": 12,
      "z": 2,
      "name": "Empty"
    },
    {
      "x": -16,
      "y": 13,
      "z": 2,
      "name": "Empty"
    },
    {
      "x": -16,
      "y": 14,
      "z": 2,
      "name": "Empty"
    },
    {
      "x": -16,
      "y": 15,
      "z": 2,
      "name": "Empty"
    },
    {
      "x": -16,
      "y": 16,
      "z": 2,
      "name": "Empty"
    },
    {
      "x": -16,
      "y": 0,
      "z": 3,
      "name": "Rock_Stone"
    },
    {
      "x": -16,
      "y": 1,
      "z": 3,
      "name": "Rock_Stone"
    },
    {
      "x": -16,
      "y": 2,
      "z": 3,
      "name": "Rock_Stone"
    },
    {
      "x": -16,
      "y": 3,
      "z": 3,
      "name": "Rock_Stone"
    },
    {
      "x": -16,
      "y": 4,
      "z": 3,
      "name": "Rock_Stone"
    },
    {
      "x": -16,
      "y": 5,
      "z": 3,
      "name": "Rock_Stone"
    },
    {
      "x": -16,
      "y": 6,
      "z": 3,
      "name": "Soil_Dirt"
    },
    {
      "x": -16,
      "y": 7,
      "z": 3,
      "name": "Soil_Dirt"
    },
    {
      "x": -16,
      "y": 8,
      "z": 3,
      "name": "Soil_Dirt"
    },
    {
      "x": -16,
      "y": 9,
      "z": 3,
      "name": "Soil_Grass"
    },
    {
      "x": -16,
      "y": 10,
      "z": 3,
      "name": "Empty"
    },
    {
      "x": -16,
      "y": 11,
      "z": 3,
      "name": "Empty"
    },
    {
      "x": -16,
      "y": 12,
      "z": 3,
      "name": "Empty"
    },
    {
      "x": -16,
      "y": 13,
      "z": 3,
      "name": "Empty"
    },
    {
      "x": -16,
      "y": 14,
      "z": 3,
      "name": "Empty"
    },
    {
      "x": -16,
      "y": 15,
      "z": 3,
      "name": "Empty"
    },
    {
      "x": -16,
      "y": 16,
      "z": 3,
      "name": "Empty"
    },
    {
      "x": -16,
      "y": 0,
      "z": 4,
      "name": "Rock_Stone"
    },
    {
      "x": -16,
      "y": 1,
      "z": 4,
      "name": "Rock_Stone"
    },
    {
      "x": -16,
      "y": 2,
      "z": 4,
      "name": "Rock_Stone"
    },
    {
      "x": -16,
      "y": 3,
      "z": 4,
      "name": "Rock_Stone"
    },
    {
      "x": -16,
      "y": 4,
      "z": 4,
      "name": "Rock_Stone"
    },
    {
      "x": -16,
      "y": 5,
      "z": 4,
      "name": "Rock_Stone"
    },
    {
      "x": -16,
      "y": 6,
      "z": 4,
      "name": "Rock_Stone"
    },
    {
      "x": -16,
      "y": 7,
      "z": 4,
      "name": "Rock_Stone"
    },
    {
      "x": -16,
      "y": 8,
      "z": 4,
      "name": "Soil_Dirt"
    },
    {
      "x": -16,
      "y": 9,
      "z": 4,
      "name": "Soil_Grass"
    },
    {
      "x": -16,
      "y": 10,
      "z": 4,
      "name": "Empty"
    },
    {
      "x": -16,
      "y": 11,
      "z": 4,
      "name": "Empty"
    },
    {
      "x": -16,
      "y": 12,
      "z": 4,
      "name": "Empty"
    },
    {
      "x": -16,
      "y": 13,
      "z": 4,
      "name": "Empty"
    },
    {
      "x": -16,
      "y": 14,
      "z": 4,
      "name": "Empty"
    },
    {
      "x": -16,
      "y": 15,
      "z": 4,
      "name": "Empty"
    },
    {
      "x": -16,
      "y": 16,
      "z": 4,
      "name": "Empty"
    },
    {
      "x": -16,
      "y": 0,
      "z": 5,
      "name": "Rock_Stone"
    },
    {
      "x": -16,
      "y": 1,
      "z": 5,
      "name": "Rock_Stone"
    },
    {
      "x": -16,
      "y": 2,
      "z": 5,
      "name": "Rock_Stone"
    },
    {
      "x": -16,
      "y": 3,
      "z": 5,
      "name": "Rock_Stone"
    },
    {
      "x": -16,
      "y": 4,
      "z": 5,
      "name": "Rock_Stone"
    },
    {
      "x": -16,
      "y": 5,
      "z": 5,
      "name": "Rock_Stone"
    },
    {
      "x": -16,
      "y": 6,
      "z": 5,
      "name": "Rock_Stone"
    },
    {
      "x": -16,
      "y": 7,
      "z": 5,
      "name": "Rock_Stone"
    },
    {
      "x": -16,
      "y": 8,
      "z": 5,
      "name": "Rock_Stone"
    },
    {
      "x": -16,
      "y": 9,
      "z": 5,
      "name": "Soil_Grass"
    },
    {
      "x": -16,
      "y": 10,
      "z": 5,
      "name": "Empty"
    },
    {
      "x": -16,
      "y": 11,
      "z": 5,
      "name": "Empty"
    },
    {
      "x": -16,
      "y": 12,
      "z": 5,
      "name": "Empty"
    },
    {
      "x": -16,
      "y": 13,
      "z": 5,
      "name": "Empty"
    },
    {
      "x": -16,
      "y": 14,
      "z": 5,
      "name": "Empty"
    },
    {
      "x": -16,
      "y": 15,
      "z": 5,
      "name": "Empty"
    },
    {
      "x": -16,
      "y": 16,
      "z": 5,
      "name": "Empty"
    },
    {
      "x": -16,
      "y": 0,
      "z": 6,
      "name": "Rock_Stone"
    },
    {
      "x": -16,
      "y": 1,
      "z": 6,
      "name": "Rock_Stone"
    },
    {
      "x": -16,
      "y": 2,
      "z": 6,
      "name": "Rock_Stone"
    },
    {
      "x": -16,
      "y": 3,
      "z": 6,
      "name": "Rock_Stone"
    },
    {
      "x": -16,
      "y": 4,
      "z": 6,
      "name": "Rock_Stone"
    },
    {
      "x": -16,
      "y": 5,
      "z": 6,
      "name": "Rock_Stone"
    },
    {
      "x": -16,
      "y": 6,
      "z": 6,
      "name": "Rock_Stone"
    },
    {
      "x": -16,
      "y": 7,
      "z": 6,
      "name": "Rock_Stone"
    },
    {
      "x": -16,
      "y": 8,
      "z": 6,
      "name": "Rock_Stone"
    },
    {
      "x": -16,
      "y": 9,
      "z": 6,
      "name": "Rock_Stone"
    },
    {
      "x": -16,
      "y": 10,
      "z": 6,
      "name": "Empty"
    },
    {
      "x": -16,
      "y": 11,
      "z": 6,
      "name": "Empty"
    },
    {
      "x": -16,
      "y": 12,
      "z": 6,
      "name": "Empty"
    },
    {
      "x": -16,
      "y": 13,
      "z": 6,
      "name": "Empty"
    },
    {
      "x": -16,
      "y": 14,
      "z": 6,
      "name": "Empty"
    },
    {
      "x": -16,
      "y": 15,
      "z": 6,
      "name": "Empty"
    },
    {
      "x": -16,
      "y": 16,
      "z": 6,
      "name": "Empty"
    },
    {
      "x": -16,
      "y": 0,
      "z": 7,
      "name": "Rock_Stone"
    },
    {
      "x": -16,
      "y": 1,
      "z": 7,
      "name": "Rock_Stone"
    },
    {
      "x": -16,
      "y": 2,
      "z": 7,
      "name": "Rock_Stone"
    },
    {
      "x": -16,
      "y": 3,
      "z": 7,
      "name": "Rock_Stone"
    },
    {
      "x": -16,
      "y": 4,
      "z": 7,
      "name": "Rock_Stone"
    },
    {
      "x": -16,
      "y": 5,
      "z": 7,
      "name": "Rock_Stone"
    },
    {
      "x": -16,
      "y": 6,
      "z": 7,
      "name": "Rock_Stone"
    },
    {
      "x": -16,
      "y": 7,
      "z": 7,
      "name": "Rock_Stone"
    },
    {
      "x": -16,
      "y": 8,
      "z": 7,
      "name": "Rock_Stone"
    },
    {
      "x": -16,
      "y": 9,
      "z": 7,
      "name": "Soil_Grass"
    },
    {
      "x": -16,
      "y": 10,
      "z": 7,
      "name": "Empty"
    },
    {
      "x": -16,
      "y": 11,
      "z": 7,
      "name": "Empty"
    },
    {
      "x": -16,
      "y": 12,
      "z": 7,
      "name": "Empty"
    },
    {
      "x": -16,
      "y": 13,
      "z": 7,
      "name": "Empty"
    },
    {
      "x": -16,
      "y": 14,
      "z": 7,
      "name": "Empty"
    },
    {
      "x": -16,
      "y": 15,
      "z": 7,
      "name": "Empty"
    },
    {
      "x": -16,
      "y": 16,
      "z": 7,
      "name": "Empty"
    },
    {
      "x": -16,
      "y": 0,
      "z": 8,
      "name": "Rock_Stone"
    },
    {
      "x": -16,
      "y": 1,
      "z": 8,
      "name": "Rock_Stone"
    },
    {
      "x": -16,
      "y": 2,
      "z": 8,
      "name": "Rock_Stone"
    },
    {
      "x": -16,
      "y": 3,
      "z": 8,
      "name": "Rock_Stone"
    },
    {
      "x": -16,
      "y": 4,
      "z": 8,
      "name": "Rock_Stone"
    },
    {
      "x": -16,
      "y": 5,
      "z": 8,
      "name": "Rock_Stone"
    },
    {
      "x": -16,
      "y": 6,
      "z": 8,
      "name": "Rock_Stone"
    },
    {
      "x": -16,
      "y": 7,
      "z": 8,
      "name": "Rock_Stone"
    },
    {
      "x": -16,
      "y": 8,
      "z": 8,
      "name": "Soil_Dirt"
    },
    {
      "x": -16,
      "y": 9,
      "z": 8,
      "name": "Soil_Grass"
    },
    {
      "x": -16,
      "y": 10,
      "z": 8,
      "name": "Empty"
    },
    {
      "x": -16,
      "y": 11,
      "z": 8,
      "name": "Empty"
    },
    {
      "x": -16,
      "y": 12,
      "z": 8,
      "name": "Empty"
    },
    {
      "x": -16,
      "y": 13,
      "z": 8,
      "name": "Empty"
    },
    {
      "x": -16,
      "y": 14,
      "z": 8,
      "name": "Empty"
    },
    {
      "x": -16,
      "y": 15,
      "z": 8,
      "name": "Empty"
    },
    {
      "x": -16,
      "y": 16,
      "z": 8,
      "name": "Empty"
    },
    {
      "x": -16,
      "y": 0,
      "z": 9,
      "name": "Rock_Stone"
    },
    {
      "x": -16,
      "y": 1,
      "z": 9,
      "name": "Rock_Stone"
    },
    {
      "x": -16,
      "y": 2,
      "z": 9,
      "name": "Rock_Stone"
    },
    {
      "x": -16,
      "y": 3,
      "z": 9,
      "name": "Rock_Stone"
    },
    {
      "x": -16,
      "y": 4,
      "z": 9,
      "name": "Rock_Stone"
    },
    {
      "x": -16,
      "y": 5,
      "z": 9,
      "name": "Rock_Stone"
    },
    {
      "x": -16,
      "y": 6,
      "z": 9,
      "name": "Soil_Dirt"
    },
    {
      "x": -16,
      "y": 7,
      "z": 9,
      "name": "Soil_Dirt"
    },
    {
      "x": -16,
      "y": 8,
      "z": 9,
      "name": "Soil_Dirt"
    },
    {
      "x": -16,
      "y": 9,
      "z": 9,
      "name": "Soil_Grass"
    },
    {
      "x": -16,
      "y": 10,
      "z": 9,
      "name": "Empty"
    },
    {
      "x": -16,
      "y": 11,
      "z": 9,
      "name": "Empty"
    },
    {
      "x": -16,
      "y": 12,
      "z": 9,
      "name": "Empty"
    },
    {
      "x": -16,
      "y": 13,
      "z": 9,
      "name": "Empty"
    },
    {
      "x": -16,
      "y": 14,
      "z": 9,
      "name": "Empty"
    },
    {
      "x": -16,
      "y": 15,
      "z": 9,
      "name": "Empty"
    },
    {
      "x": -16,
      "y": 16,
      "z": 9,
      "name": "Empty"
    },
    {
      "x": -16,
      "y": 0,
      "z": 10,
      "name": "Rock_Stone"
    },
    {
      "x": -16,
      "y": 1,
      "z": 10,
      "name": "Rock_Stone"
    },
    {
      "x": -16,
      "y": 2,
      "z": 10,
      "name": "Rock_Stone"
    },
    {
      "x": -16,
      "y": 3,
      "z": 10,
      "name": "Rock_Stone"
    },
    {
      "x": -16,
      "y": 4,
      "z": 10,
      "name": "Rock_Stone"
    },
    {
      "x": -16,
      "y": 5,
      "z": 10,
      "name": "Rock_Stone"
    },
    {
      "x": -16,
      "y": 6,
      "z": 10,
      "name": "Soil_Dirt"
    },
    {
      "x": -16,
      "y": 7,
      "z": 10,
      "name": "Soil_Dirt"
    },
    {
      "x": -16,
      "y": 8,
      "z": 10,
      "name": "Soil_Dirt"
    },
    {
      "x": -16,
      "y": 9,
      "z": 10,
      "name": "Soil_Grass"
    },
    {
      "x": -16,
      "y": 10,
      "z": 10,
      "name": "Empty"
    },
    {
      "x": -16,
      "y": 11,
      "z": 10,
      "name": "Empty"
    },
    {
      "x": -16,
      "y": 12,
      "z": 10,
      "name": "Empty"
    },
    {
      "x": -16,
      "y": 13,
      "z": 10,
      "name": "Empty"
    },
    {
      "x": -16,
      "y": 14,
      "z": 10,
      "name": "Empty"
    },
    {
      "x": -16,
      "y": 15,
      "z": 10,
      "name": "Empty"
    },
    {
      "x": -16,
      "y": 16,
      "z": 10,
      "name": "Empty"
    },
    {
      "x": -16,
      "y": 0,
      "z": 11,
      "name": "Rock_Stone"
    },
    {
      "x": -16,
      "y": 1,
      "z": 11,
      "name": "Rock_Stone"
    },
    {
      "x": -16,
      "y": 2,
      "z": 11,
      "name": "Rock_Stone"
    },
    {
      "x": -16,
      "y": 3,
      "z": 11,
      "name": "Rock_Stone"
    },
    {
      "x": -16,
      "y": 4,
      "z": 11,
      "name": "Rock_Stone"
    },
    {
      "x": -16,
      "y": 5,
      "z": 11,
      "name": "Rock_Stone"
    },
    {
      "x": -16,
      "y": 6,
      "z": 11,
      "name": "Soil_Dirt"
    },
    {
      "x": -16,
      "y": 7,
      "z": 11,
      "name": "Soil_Dirt"
    },
    {
      "x": -16,
      "y": 8,
      "z": 11,
      "name": "Soil_Dirt"
    },
    {
      "x": -16,
      "y": 9,
      "z": 11,
      "name": "Soil_Grass"
    },
    {
      "x": -16,
      "y": 10,
      "z": 11,
      "name": "Empty"
    },
    {
      "x": -16,
      "y": 11,
      "z": 11,
      "name": "Empty"
    },
    {
      "x": -16,
      "y": 12,
      "z": 11,
      "name": "Empty"
    },
    {
      "x": -16,
      "y": 13,
      "z": 11,
      "name": "Empty"
    },
    {
      "x": -16,
      "y": 14,
      "z": 11,
      "name": "Empty"
    },
    {
      "x": -16,
      "y": 15,
      "z": 11,
      "name": "Empty"
    },
    {
      "x": -16,
      "y": 16,
      "z": 11,
      "name": "Empty"
    },
    {
      "x": -16,
      "y": 0,
      "z": 12,
      "name": "Rock_Stone"
    },
    {
      "x": -16,
      "y": 1,
      "z": 12,
      "name": "Rock_Stone"
    },
    {
      "x": -16,
      "y": 2,
      "z": 12,
      "name": "Rock_Stone"
    },
    {
      "x": -16,
      "y": 3,
      "z": 12,
      "name": "Rock_Stone"
    },
    {
      "x": -16,
      "y": 4,
      "z": 12,
      "name": "Rock_Stone"
    },
    {
      "x": -16,
      "y": 5,
      "z": 12,
      "name": "Rock_Stone"
    },
    {
      "x": -16,
      "y": 6,
      "z": 12,
      "name": "Soil_Dirt"
    },
    {
      "x": -16,
      "y": 7,
      "z": 12,
      "name": "Soil_Dirt"
    },
    {
      "x": -16,
      "y": 8,
      "z": 12,
      "name": "Soil_Dirt"
    },
    {
      "x": -16,
      "y": 9,
      "z": 12,
      "name": "Soil_Grass"
    },
    {
      "x": -16,
      "y": 10,
      "z": 12,
      "name": "Empty"
    },
    {
      "x": -16,
      "y": 11,
      "z": 12,
      "name": "Empty"
    },
    {
      "x": -16,
      "y": 12,
      "z": 12,
      "name": "Empty"
    },
    {
      "x": -16,
      "y": 13,
      "z": 12,
      "name": "Empty"
    },
    {
      "x": -16,
      "y": 14,
      "z": 12,
      "name": "Empty"
    },
    {
      "x": -16,
      "y": 15,
      "z": 12,
      "name": "Empty"
    },
    {
      "x": -16,
      "y": 16,
      "z": 12,
      "name": "Empty"
    },
    {
      "x": -15,
      "y": 0,
      "z": -12,
      "name": "Rock_Stone"
    },
    {
      "x": -15,
      "y": 1,
      "z": -12,
      "name": "Rock_Stone"
    },
    {
      "x": -15,
      "y": 2,
      "z": -12,
      "name": "Rock_Stone"
    },
    {
      "x": -15,
      "y": 3,
      "z": -12,
      "name": "Rock_Stone"
    },
    {
      "x": -15,
      "y": 4,
      "z": -12,
      "name": "Rock_Stone"
    },
    {
      "x": -15,
      "y": 5,
      "z": -12,
      "name": "Rock_Stone"
    },
    {
      "x": -15,
      "y": 6,
      "z": -12,
      "name": "Soil_Dirt"
    },
    {
      "x": -15,
      "y": 7,
      "z": -12,
      "name": "Soil_Dirt"
    },
    {
      "x": -15,
      "y": 8,
      "z": -12,
      "name": "Soil_Dirt"
    },
    {
      "x": -15,
      "y": 9,
      "z": -12,
      "name": "Soil_Grass"
    },
    {
      "x": -15,
      "y": 10,
      "z": -12,
      "name": "Empty"
    },
    {
      "x": -15,
      "y": 11,
      "z": -12,
      "name": "Empty"
    },
    {
      "x": -15,
      "y": 12,
      "z": -12,
      "name": "Empty"
    },
    {
      "x": -15,
      "y": 13,
      "z": -12,
      "name": "Empty"
    },
    {
      "x": -15,
      "y": 14,
      "z": -12,
      "name": "Empty"
    },
    {
      "x": -15,
      "y": 15,
      "z": -12,
      "name": "Empty"
    },
    {
      "x": -15,
      "y": 16,
      "z": -12,
      "name": "Empty"
    },
    {
      "x": -15,
      "y": 0,
      "z": -11,
      "name": "Rock_Stone"
    },
    {
      "x": -15,
      "y": 1,
      "z": -11,
      "name": "Rock_Stone"
    },
    {
      "x": -15,
      "y": 2,
      "z": -11,
      "name": "Rock_Stone"
    },
    {
      "x": -15,
      "y": 3,
      "z": -11,
      "name": "Rock_Stone"
    },
    {
      "x": -15,
      "y": 4,
      "z": -11,
      "name": "Rock_Stone"
    },
    {
      "x": -15,
      "y": 5,
      "z": -11,
      "name": "Rock_Stone"
    },
    {
      "x": -15,
      "y": 6,
      "z": -11,
      "name": "Soil_Dirt"
    },
    {
      "x": -15,
      "y": 7,
      "z": -11,
      "name": "Soil_Dirt"
    },
    {
      "x": -15,
      "y": 8,
      "z": -11,
      "name": "Soil_Dirt"
    },
    {
      "x": -15,
      "y": 9,
      "z": -11,
      "name": "Soil_Grass"
    },
    {
      "x": -15,
      "y": 10,
      "z": -11,
      "name": "Empty"
    },
    {
      "x": -15,
      "y": 11,
      "z": -11,
      "name": "Empty"
    },
    {
      "x": -15,
      "y": 12,
      "z": -11,
      "name": "Empty"
    },
    {
      "x": -15,
      "y": 13,
      "z": -11,
      "name": "Empty"
    },
    {
      "x": -15,
      "y": 14,
      "z": -11,
      "name": "Empty"
    },
    {
      "x": -15,
      "y": 15,
      "z": -11,
      "name": "Empty"
    },
    {
      "x": -15,
      "y": 16,
      "z": -11,
      "name": "Empty"
    },
    {
      "x": -15,
      "y": 0,
      "z": -10,
      "name": "Rock_Stone"
    },
    {
      "x": -15,
      "y": 1,
      "z": -10,
      "name": "Rock_Stone"
    },
    {
      "x": -15,
      "y": 2,
      "z": -10,
      "name": "Rock_Stone"
    },
    {
      "x": -15,
      "y": 3,
      "z": -10,
      "name": "Rock_Stone"
    },
    {
      "x": -15,
      "y": 4,
      "z": -10,
      "name": "Rock_Stone"
    },
    {
      "x": -15,
      "y": 5,
      "z": -10,
      "name": "Rock_Stone"
    },
    {
      "x": -15,
      "y": 6,
      "z": -10,
      "name": "Soil_Dirt"
    },
    {
      "x": -15,
      "y": 7,
      "z": -10,
      "name": "Soil_Dirt"
    },
    {
      "x": -15,
      "y": 8,
      "z": -10,
      "name": "Soil_Dirt"
    },
    {
      "x": -15,
      "y": 9,
      "z": -10,
      "name": "Soil_Grass"
    },
    {
      "x": -15,
      "y": 10,
      "z": -10,
      "name": "Empty"
    },
    {
      "x": -15,
      "y": 11,
      "z": -10,
      "name": "Empty"
    },
    {
      "x": -15,
      "y": 12,
      "z": -10,
      "name": "Empty"
    },
    {
      "x": -15,
      "y": 13,
      "z": -10,
      "name": "Empty"
    },
    {
      "x": -15,
      "y": 14,
      "z": -10,
      "name": "Empty"
    },
    {
      "x": -15,
      "y": 15,
      "z": -10,
      "name": "Empty"
    },
    {
      "x": -15,
      "y": 16,
      "z": -10,
      "name": "Empty"
    },
    {
      "x": -15,
      "y": 0,
      "z": -9,
      "name": "Rock_Stone"
    },
    {
      "x": -15,
      "y": 1,
      "z": -9,
      "name": "Rock_Stone"
    },
    {
      "x": -15,
      "y": 2,
      "z": -9,
      "name": "Rock_Stone"
    },
    {
      "x": -15,
      "y": 3,
      "z": -9,
      "name": "Rock_Stone"
    },
    {
      "x": -15,
      "y": 4,
      "z": -9,
      "name": "Rock_Stone"
    },
    {
      "x": -15,
      "y": 5,
      "z": -9,
      "name": "Rock_Stone"
    },
    {
      "x": -15,
      "y": 6,
      "z": -9,
      "name": "Soil_Dirt"
    },
    {
      "x": -15,
      "y": 7,
      "z": -9,
      "name": "Soil_Dirt"
    },
    {
      "x": -15,
      "y": 8,
      "z": -9,
      "name": "Soil_Dirt"
    },
    {
      "x": -15,
      "y": 9,
      "z": -9,
      "name": "Soil_Grass"
    },
    {
      "x": -15,
      "y": 10,
      "z": -9,
      "name": "Empty"
    },
    {
      "x": -15,
      "y": 11,
      "z": -9,
      "name": "Empty"
    },
    {
      "x": -15,
      "y": 12,
      "z": -9,
      "name": "Empty"
    },
    {
      "x": -15,
      "y": 13,
      "z": -9,
      "name": "Empty"
    },
    {
      "x": -15,
      "y": 14,
      "z": -9,
      "name": "Empty"
    },
    {
      "x": -15,
      "y": 15,
      "z": -9,
      "name": "Empty"
    },
    {
      "x": -15,
      "y": 16,
      "z": -9,
      "name": "Empty"
    },
    {
      "x": -15,
      "y": 0,
      "z": -8,
      "name": "Rock_Stone"
    },
    {
      "x": -15,
      "y": 1,
      "z": -8,
      "name": "Rock_Stone"
    },
    {
      "x": -15,
      "y": 2,
      "z": -8,
      "name": "Rock_Stone"
    },
    {
      "x": -15,
      "y": 3,
      "z": -8,
      "name": "Rock_Stone"
    },
    {
      "x": -15,
      "y": 4,
      "z": -8,
      "name": "Rock_Stone"
    },
    {
      "x": -15,
      "y": 5,
      "z": -8,
      "name": "Rock_Stone"
    },
    {
      "x": -15,
      "y": 6,
      "z": -8,
      "name": "Soil_Dirt"
    },
    {
      "x": -15,
      "y": 7,
      "z": -8,
      "name": "Soil_Dirt"
    },
    {
      "x": -15,
      "y": 8,
      "z": -8,
      "name": "Soil_Dirt"
    },
    {
      "x": -15,
      "y": 9,
      "z": -8,
      "name": "Soil_Grass"
    },
    {
      "x": -15,
      "y": 10,
      "z": -8,
      "name": "Empty"
    },
    {
      "x": -15,
      "y": 11,
      "z": -8,
      "name": "Empty"
    },
    {
      "x": -15,
      "y": 12,
      "z": -8,
      "name": "Empty"
    },
    {
      "x": -15,
      "y": 13,
      "z": -8,
      "name": "Empty"
    },
    {
      "x": -15,
      "y": 14,
      "z": -8,
      "name": "Empty"
    },
    {
      "x": -15,
      "y": 15,
      "z": -8,
      "name": "Empty"
    },
    {
      "x": -15,
      "y": 16,
      "z": -8,
      "name": "Empty"
    },
    {
      "x": -15,
      "y": 0,
      "z": -7,
      "name": "Rock_Stone"
    },
    {
      "x": -15,
      "y": 1,
      "z": -7,
      "name": "Rock_Stone"
    },
    {
      "x": -15,
      "y": 2,
      "z": -7,
      "name": "Rock_Stone"
    },
    {
      "x": -15,
      "y": 3,
      "z": -7,
      "name": "Rock_Stone"
    },
    {
      "x": -15,
      "y": 4,
      "z": -7,
      "name": "Rock_Stone"
    },
    {
      "x": -15,
      "y": 5,
      "z": -7,
      "name": "Rock_Stone"
    },
    {
      "x": -15,
      "y": 6,
      "z": -7,
      "name": "Soil_Dirt"
    },
    {
      "x": -15,
      "y": 7,
      "z": -7,
      "name": "Soil_Dirt"
    },
    {
      "x": -15,
      "y": 8,
      "z": -7,
      "name": "Soil_Dirt"
    },
    {
      "x": -15,
      "y": 9,
      "z": -7,
      "name": "Soil_Grass"
    },
    {
      "x": -15,
      "y": 10,
      "z": -7,
      "name": "Empty"
    },
    {
      "x": -15,
      "y": 11,
      "z": -7,
      "name": "Empty"
    },
    {
      "x": -15,
      "y": 12,
      "z": -7,
      "name": "Empty"
    },
    {
      "x": -15,
      "y": 13,
      "z": -7,
      "name": "Empty"
    },
    {
      "x": -15,
      "y": 14,
      "z": -7,
      "name": "Empty"
    },
    {
      "x": -15,
      "y": 15,
      "z": -7,
      "name": "Empty"
    },
    {
      "x": -15,
      "y": 16,
      "z": -7,
      "name": "Empty"
    },
    {
      "x": -15,
      "y": 0,
      "z": -6,
      "name": "Rock_Stone"
    },
    {
      "x": -15,
      "y": 1,
      "z": -6,
      "name": "Rock_Stone"
    },
    {
      "x": -15,
      "y": 2,
      "z": -6,
      "name": "Rock_Stone"
    },
    {
      "x": -15,
      "y": 3,
      "z": -6,
      "name": "Rock_Stone"
    },
    {
      "x": -15,
      "y": 4,
      "z": -6,
      "name": "Rock_Stone"
    },
    {
      "x": -15,
      "y": 5,
      "z": -6,
      "name": "Rock_Stone"
    },
    {
      "x": -15,
      "y": 6,
      "z": -6,
      "name": "Soil_Dirt"
    },
    {
      "x": -15,
      "y": 7,
      "z": -6,
      "name": "Soil_Dirt"
    },
    {
      "x": -15,
      "y": 8,
      "z": -6,
      "name": "Soil_Dirt"
    },
    {
      "x": -15,
      "y": 9,
      "z": -6,
      "name": "Soil_Grass"
    },
    {
      "x": -15,
      "y": 10,
      "z": -6,
      "name": "Empty"
    },
    {
      "x": -15,
      "y": 11,
      "z": -6,
      "name": "Empty"
    },
    {
      "x": -15,
      "y": 12,
      "z": -6,
      "name": "Empty"
    },
    {
      "x": -15,
      "y": 13,
      "z": -6,
      "name": "Empty"
    },
    {
      "x": -15,
      "y": 14,
      "z": -6,
      "name": "Empty"
    },
    {
      "x": -15,
      "y": 15,
      "z": -6,
      "name": "Empty"
    },
    {
      "x": -15,
      "y": 16,
      "z": -6,
      "name": "Empty"
    },
    {
      "x": -15,
      "y": 0,
      "z": -5,
      "name": "Rock_Stone"
    },
    {
      "x": -15,
      "y": 1,
      "z": -5,
      "name": "Rock_Stone"
    },
    {
      "x": -15,
      "y": 2,
      "z": -5,
      "name": "Rock_Stone"
    },
    {
      "x": -15,
      "y": 3,
      "z": -5,
      "name": "Rock_Stone"
    },
    {
      "x": -15,
      "y": 4,
      "z": -5,
      "name": "Rock_Stone"
    },
    {
      "x": -15,
      "y": 5,
      "z": -5,
      "name": "Rock_Stone"
    },
    {
      "x": -15,
      "y": 6,
      "z": -5,
      "name": "Soil_Dirt"
    },
    {
      "x": -15,
      "y": 7,
      "z": -5,
      "name": "Soil_Dirt"
    },
    {
      "x": -15,
      "y": 8,
      "z": -5,
      "name": "Soil_Dirt"
    },
    {
      "x": -15,
      "y": 9,
      "z": -5,
      "name": "Soil_Grass"
    },
    {
      "x": -15,
      "y": 10,
      "z": -5,
      "name": "Empty"
    },
    {
      "x": -15,
      "y": 11,
      "z": -5,
      "name": "Empty"
    },
    {
      "x": -15,
      "y": 12,
      "z": -5,
      "name": "Empty"
    },
    {
      "x": -15,
      "y": 13,
      "z": -5,
      "name": "Empty"
    },
    {
      "x": -15,
      "y": 14,
      "z": -5,
      "name": "Empty"
    },
    {
      "x": -15,
      "y": 15,
      "z": -5,
      "name": "Empty"
    },
    {
      "x": -15,
      "y": 16,
      "z": -5,
      "name": "Empty"
    },
    {
      "x": -15,
      "y": 0,
      "z": -4,
      "name": "Rock_Stone"
    },
    {
      "x": -15,
      "y": 1,
      "z": -4,
      "name": "Rock_Stone"
    },
    {
      "x": -15,
      "y": 2,
      "z": -4,
      "name": "Rock_Stone"
    },
    {
      "x": -15,
      "y": 3,
      "z": -4,
      "name": "Rock_Stone"
    },
    {
      "x": -15,
      "y": 4,
      "z": -4,
      "name": "Rock_Stone"
    },
    {
      "x": -15,
      "y": 5,
      "z": -4,
      "name": "Rock_Stone"
    },
    {
      "x": -15,
      "y": 6,
      "z": -4,
      "name": "Soil_Dirt"
    },
    {
      "x": -15,
      "y": 7,
      "z": -4,
      "name": "Soil_Dirt"
    },
    {
      "x": -15,
      "y": 8,
      "z": -4,
      "name": "Soil_Dirt"
    },
    {
      "x": -15,
      "y": 9,
      "z": -4,
      "name": "Soil_Grass"
    },
    {
      "x": -15,
      "y": 10,
      "z": -4,
      "name": "Empty"
    },
    {
      "x": -15,
      "y": 11,
      "z": -4,
      "name": "Empty"
    },
    {
      "x": -15,
      "y": 12,
      "z": -4,
      "name": "Empty"
    },
    {
      "x": -15,
      "y": 13,
      "z": -4,
      "name": "Empty"
    },
    {
      "x": -15,
      "y": 14,
      "z": -4,
      "name": "Empty"
    },
    {
      "x": -15,
      "y": 15,
      "z": -4,
      "name": "Empty"
    },
    {
      "x": -15,
      "y": 16,
      "z": -4,
      "name": "Empty"
    },
    {
      "x": -15,
      "y": 0,
      "z": -3,
      "name": "Rock_Stone"
    },
    {
      "x": -15,
      "y": 1,
      "z": -3,
      "name": "Rock_Stone"
    },
    {
      "x": -15,
      "y": 2,
      "z": -3,
      "name": "Rock_Stone"
    },
    {
      "x": -15,
      "y": 3,
      "z": -3,
      "name": "Rock_Stone"
    },
    {
      "x": -15,
      "y": 4,
      "z": -3,
      "name": "Rock_Stone"
    },
    {
      "x": -15,
      "y": 5,
      "z": -3,
      "name": "Rock_Stone"
    },
    {
      "x": -15,
      "y": 6,
      "z": -3,
      "name": "Soil_Dirt"
    },
    {
      "x": -15,
      "y": 7,
      "z": -3,
      "name": "Soil_Dirt"
    },
    {
      "x": -15,
      "y": 8,
      "z": -3,
      "name": "Soil_Dirt"
    },
    {
      "x": -15,
      "y": 9,
      "z": -3,
      "name": "Soil_Grass"
    },
    {
      "x": -15,
      "y": 10,
      "z": -3,
      "name": "Empty"
    },
    {
      "x": -15,
      "y": 11,
      "z": -3,
      "name": "Empty"
    },
    {
      "x": -15,
      "y": 12,
      "z": -3,
      "name": "Empty"
    },
    {
      "x": -15,
      "y": 13,
      "z": -3,
      "name": "Empty"
    },
    {
      "x": -15,
      "y": 14,
      "z": -3,
      "name": "Empty"
    },
    {
      "x": -15,
      "y": 15,
      "z": -3,
      "name": "Empty"
    },
    {
      "x": -15,
      "y": 16,
      "z": -3,
      "name": "Empty"
    },
    {
      "x": -15,
      "y": 0,
      "z": -2,
      "name": "Rock_Stone"
    },
    {
      "x": -15,
      "y": 1,
      "z": -2,
      "name": "Rock_Stone"
    },
    {
      "x": -15,
      "y": 2,
      "z": -2,
      "name": "Rock_Stone"
    },
    {
      "x": -15,
      "y": 3,
      "z": -2,
      "name": "Rock_Stone"
    },
    {
      "x": -15,
      "y": 4,
      "z": -2,
      "name": "Rock_Stone"
    },
    {
      "x": -15,
      "y": 5,
      "z": -2,
      "name": "Rock_Stone"
    },
    {
      "x": -15,
      "y": 6,
      "z": -2,
      "name": "Soil_Dirt"
    },
    {
      "x": -15,
      "y": 7,
      "z": -2,
      "name": "Soil_Dirt"
    },
    {
      "x": -15,
      "y": 8,
      "z": -2,
      "name": "Soil_Dirt"
    },
    {
      "x": -15,
      "y": 9,
      "z": -2,
      "name": "Soil_Grass"
    },
    {
      "x": -15,
      "y": 10,
      "z": -2,
      "name": "Empty"
    },
    {
      "x": -15,
      "y": 11,
      "z": -2,
      "name": "Empty"
    },
    {
      "x": -15,
      "y": 12,
      "z": -2,
      "name": "Empty"
    },
    {
      "x": -15,
      "y": 13,
      "z": -2,
      "name": "Empty"
    },
    {
      "x": -15,
      "y": 14,
      "z": -2,
      "name": "Empty"
    },
    {
      "x": -15,
      "y": 15,
      "z": -2,
      "name": "Empty"
    },
    {
      "x": -15,
      "y": 16,
      "z": -2,
      "name": "Empty"
    },
    {
      "x": -15,
      "y": 0,
      "z": -1,
      "name": "Rock_Stone"
    },
    {
      "x": -15,
      "y": 1,
      "z": -1,
      "name": "Rock_Stone"
    },
    {
      "x": -15,
      "y": 2,
      "z": -1,
      "name": "Rock_Stone"
    },
    {
      "x": -15,
      "y": 3,
      "z": -1,
      "name": "Rock_Stone"
    },
    {
      "x": -15,
      "y": 4,
      "z": -1,
      "name": "Rock_Stone"
    },
    {
      "x": -15,
      "y": 5,
      "z": -1,
      "name": "Rock_Stone"
    },
    {
      "x": -15,
      "y": 6,
      "z": -1,
      "name": "Soil_Dirt"
    },
    {
      "x": -15,
      "y": 7,
      "z": -1,
      "name": "Soil_Dirt"
    },
    {
      "x": -15,
      "y": 8,
      "z": -1,
      "name": "Soil_Dirt"
    },
    {
      "x": -15,
      "y": 9,
      "z": -1,
      "name": "Soil_Grass"
    },
    {
      "x": -15,
      "y": 10,
      "z": -1,
      "name": "Empty"
    },
    {
      "x": -15,
      "y": 11,
      "z": -1,
      "name": "Empty"
    },
    {
      "x": -15,
      "y": 12,
      "z": -1,
      "name": "Empty"
    },
    {
      "x": -15,
      "y": 13,
      "z": -1,
      "name": "Empty"
    },
    {
      "x": -15,
      "y": 14,
      "z": -1,
      "name": "Empty"
    },
    {
      "x": -15,
      "y": 15,
      "z": -1,
      "name": "Empty"
    },
    {
      "x": -15,
      "y": 16,
      "z": -1,
      "name": "Empty"
    },
    {
      "x": -15,
      "y": 0,
      "z": 0,
      "name": "Rock_Stone"
    },
    {
      "x": -15,
      "y": 1,
      "z": 0,
      "name": "Rock_Stone"
    },
    {
      "x": -15,
      "y": 2,
      "z": 0,
      "name": "Rock_Stone"
    },
    {
      "x": -15,
      "y": 3,
      "z": 0,
      "name": "Rock_Stone"
    },
    {
      "x": -15,
      "y": 4,
      "z": 0,
      "name": "Rock_Stone"
    },
    {
      "x": -15,
      "y": 5,
      "z": 0,
      "name": "Rock_Stone"
    },
    {
      "x": -15,
      "y": 6,
      "z": 0,
      "name": "Soil_Dirt"
    },
    {
      "x": -15,
      "y": 7,
      "z": 0,
      "name": "Soil_Dirt"
    },
    {
      "x": -15,
      "y": 8,
      "z": 0,
      "name": "Soil_Dirt"
    },
    {
      "x": -15,
      "y": 9,
      "z": 0,
      "name": "Soil_Grass"
    },
    {
      "x": -15,
      "y": 10,
      "z": 0,
      "name": "Empty"
    },
    {
      "x": -15,
      "y": 11,
      "z": 0,
      "name": "Empty"
    },
    {
      "x": -15,
      "y": 12,
      "z": 0,
      "name": "Empty"
    },
    {
      "x": -15,
      "y": 13,
      "z": 0,
      "name": "Empty"
    },
    {
      "x": -15,
      "y": 14,
      "z": 0,
      "name": "Empty"
    },
    {
      "x": -15,
      "y": 15,
      "z": 0,
      "name": "Empty"
    },
    {
      "x": -15,
      "y": 16,
      "z": 0,
      "name": "Empty"
    },
    {
      "x": -15,
      "y": 0,
      "z": 1,
      "name": "Rock_Stone"
    },
    {
      "x": -15,
      "y": 1,
      "z": 1,
      "name": "Rock_Stone"
    },
    {
      "x": -15,
      "y": 2,
      "z": 1,
      "name": "Rock_Stone"
    },
    {
      "x": -15,
      "y": 3,
      "z": 1,
      "name": "Rock_Stone"
    },
    {
      "x": -15,
      "y": 4,
      "z": 1,
      "name": "Rock_Stone"
    },
    {
      "x": -15,
      "y": 5,
      "z": 1,
      "name": "Rock_Stone"
    },
    {
      "x": -15,
      "y": 6,
      "z": 1,
      "name": "Soil_Dirt"
    },
    {
      "x": -15,
      "y": 7,
      "z": 1,
      "name": "Soil_Dirt"
    },
    {
      "x": -15,
      "y": 8,
      "z": 1,
      "name": "Soil_Dirt"
    },
    {
      "x": -15,
      "y": 9,
      "z": 1,
      "name": "Soil_Grass"
    },
    {
      "x": -15,
      "y": 10,
      "z": 1,
      "name": "Empty"
    },
    {
      "x": -15,
      "y": 11,
      "z": 1,
      "name": "Empty"
    },
    {
      "x": -15,
      "y": 12,
      "z": 1,
      "name": "Empty"
    },
    {
      "x": -15,
      "y": 13,
      "z": 1,
      "name": "Empty"
    },
    {
      "x": -15,
      "y": 14,
      "z": 1,
      "name": "Empty"
    },
    {
      "x": -15,
      "y": 15,
      "z": 1,
      "name": "Empty"
    },
    {
      "x": -15,
      "y": 16,
      "z": 1,
      "name": "Empty"
    },
    {
      "x": -15,
      "y": 0,
      "z": 2,
      "name": "Rock_Stone"
    },
    {
      "x": -15,
      "y": 1,
      "z": 2,
      "name": "Rock_Stone"
    },
    {
      "x": -15,
      "y": 2,
      "z": 2,
      "name": "Rock_Stone"
    },
    {
      "x": -15,
      "y": 3,
      "z": 2,
      "name": "Rock_Stone"
    },
    {
      "x": -15,
      "y": 4,
      "z": 2,
      "name": "Rock_Stone"
    },
    {
      "x": -15,
      "y": 5,
      "z": 2,
      "name": "Rock_Stone"
    },
    {
      "x": -15,
      "y": 6,
      "z": 2,
      "name": "Rock_Stone"
    },
    {
      "x": -15,
      "y": 7,
      "z": 2,
      "name": "Soil_Dirt"
    },
    {
      "x": -15,
      "y": 8,
      "z": 2,
      "name": "Soil_Dirt"
    },
    {
      "x": -15,
      "y": 9,
      "z": 2,
      "name": "Soil_Grass"
    },
    {
      "x": -15,
      "y": 10,
      "z": 2,
      "name": "Empty"
    },
    {
      "x": -15,
      "y": 11,
      "z": 2,
      "name": "Empty"
    },
    {
      "x": -15,
      "y": 12,
      "z": 2,
      "name": "Empty"
    },
    {
      "x": -15,
      "y": 13,
      "z": 2,
      "name": "Empty"
    },
    {
      "x": -15,
      "y": 14,
      "z": 2,
      "name": "Empty"
    },
    {
      "x": -15,
      "y": 15,
      "z": 2,
      "name": "Empty"
    },
    {
      "x": -15,
      "y": 16,
      "z": 2,
      "name": "Empty"
    },
    {
      "x": -15,
      "y": 0,
      "z": 3,
      "name": "Rock_Stone"
    },
    {
      "x": -15,
      "y": 1,
      "z": 3,
      "name": "Rock_Stone"
    },
    {
      "x": -15,
      "y": 2,
      "z": 3,
      "name": "Rock_Stone"
    },
    {
      "x": -15,
      "y": 3,
      "z": 3,
      "name": "Rock_Stone"
    },
    {
      "x": -15,
      "y": 4,
      "z": 3,
      "name": "Rock_Stone"
    },
    {
      "x": -15,
      "y": 5,
      "z": 3,
      "name": "Rock_Stone"
    },
    {
      "x": -15,
      "y": 6,
      "z": 3,
      "name": "Rock_Stone"
    },
    {
      "x": -15,
      "y": 7,
      "z": 3,
      "name": "Rock_Stone"
    },
    {
      "x": -15,
      "y": 8,
      "z": 3,
      "name": "Rock_Stone"
    },
    {
      "x": -15,
      "y": 9,
      "z": 3,
      "name": "Rock_Stone"
    },
    {
      "x": -15,
      "y": 10,
      "z": 3,
      "name": "Empty"
    },
    {
      "x": -15,
      "y": 11,
      "z": 3,
      "name": "Empty"
    },
    {
      "x": -15,
      "y": 12,
      "z": 3,
      "name": "Empty"
    },
    {
      "x": -15,
      "y": 13,
      "z": 3,
      "name": "Empty"
    },
    {
      "x": -15,
      "y": 14,
      "z": 3,
      "name": "Empty"
    },
    {
      "x": -15,
      "y": 15,
      "z": 3,
      "name": "Empty"
    },
    {
      "x": -15,
      "y": 16,
      "z": 3,
      "name": "Empty"
    },
    {
      "x": -15,
      "y": 0,
      "z": 4,
      "name": "Rock_Stone"
    },
    {
      "x": -15,
      "y": 1,
      "z": 4,
      "name": "Ore_Iron_Stone"
    },
    {
      "x": -15,
      "y": 2,
      "z": 4,
      "name": "Rock_Stone"
    },
    {
      "x": -15,
      "y": 3,
      "z": 4,
      "name": "Rock_Stone"
    },
    {
      "x": -15,
      "y": 4,
      "z": 4,
      "name": "Rock_Stone"
    },
    {
      "x": -15,
      "y": 5,
      "z": 4,
      "name": "Rock_Stone"
    },
    {
      "x": -15,
      "y": 6,
      "z": 4,
      "name": "Rock_Stone"
    },
    {
      "x": -15,
      "y": 7,
      "z": 4,
      "name": "Rock_Stone"
    },
    {
      "x": -15,
      "y": 8,
      "z": 4,
      "name": "Rock_Stone"
    },
    {
      "x": -15,
      "y": 9,
      "z": 4,
      "name": "Rock_Stone"
    },
    {
      "x": -15,
      "y": 10,
      "z": 4,
      "name": "Empty"
    },
    {
      "x": -15,
      "y": 11,
      "z": 4,
      "name": "Empty"
    },
    {
      "x": -15,
      "y": 12,
      "z": 4,
      "name": "Empty"
    },
    {
      "x": -15,
      "y": 13,
      "z": 4,
      "name": "Empty"
    },
    {
      "x": -15,
      "y": 14,
      "z": 4,
      "name": "Empty"
    },
    {
      "x": -15,
      "y": 15,
      "z": 4,
      "name": "Empty"
    },
    {
      "x": -15,
      "y": 16,
      "z": 4,
      "name": "Empty"
    },
    {
      "x": -15,
      "y": 0,
      "z": 5,
      "name": "Rock_Stone"
    },
    {
      "x": -15,
      "y": 1,
      "z": 5,
      "name": "Rock_Stone"
    },
    {
      "x": -15,
      "y": 2,
      "z": 5,
      "name": "Rock_Stone"
    },
    {
      "x": -15,
      "y": 3,
      "z": 5,
      "name": "Rock_Stone"
    },
    {
      "x": -15,
      "y": 4,
      "z": 5,
      "name": "Rock_Stone"
    },
    {
      "x": -15,
      "y": 5,
      "z": 5,
      "name": "Rock_Stone"
    },
    {
      "x": -15,
      "y": 6,
      "z": 5,
      "name": "Rock_Stone"
    },
    {
      "x": -15,
      "y": 7,
      "z": 5,
      "name": "Rock_Stone"
    },
    {
      "x": -15,
      "y": 8,
      "z": 5,
      "name": "Rock_Stone"
    },
    {
      "x": -15,
      "y": 9,
      "z": 5,
      "name": "Rock_Stone"
    },
    {
      "x": -15,
      "y": 10,
      "z": 5,
      "name": "Empty"
    },
    {
      "x": -15,
      "y": 11,
      "z": 5,
      "name": "Empty"
    },
    {
      "x": -15,
      "y": 12,
      "z": 5,
      "name": "Empty"
    },
    {
      "x": -15,
      "y": 13,
      "z": 5,
      "name": "Empty"
    },
    {
      "x": -15,
      "y": 14,
      "z": 5,
      "name": "Empty"
    },
    {
      "x": -15,
      "y": 15,
      "z": 5,
      "name": "Empty"
    },
    {
      "x": -15,
      "y": 16,
      "z": 5,
      "name": "Empty"
    },
    {
      "x": -15,
      "y": 0,
      "z": 6,
      "name": "Rock_Stone"
    },
    {
      "x": -15,
      "y": 1,
      "z": 6,
      "name": "Rock_Stone"
    },
    {
      "x": -15,
      "y": 2,
      "z": 6,
      "name": "Rock_Stone"
    },
    {
      "x": -15,
      "y": 3,
      "z": 6,
      "name": "Rock_Stone"
    },
    {
      "x": -15,
      "y": 4,
      "z": 6,
      "name": "Rock_Stone"
    },
    {
      "x": -15,
      "y": 5,
      "z": 6,
      "name": "Rock_Stone"
    },
    {
      "x": -15,
      "y": 6,
      "z": 6,
      "name": "Rock_Stone"
    },
    {
      "x": -15,
      "y": 7,
      "z": 6,
      "name": "Rock_Stone"
    },
    {
      "x": -15,
      "y": 8,
      "z": 6,
      "name": "Rock_Stone"
    },
    {
      "x": -15,
      "y": 9,
      "z": 6,
      "name": "Rock_Stone"
    },
    {
      "x": -15,
      "y": 10,
      "z": 6,
      "name": "Empty"
    },
    {
      "x": -15,
      "y": 11,
      "z": 6,
      "name": "Empty"
    },
    {
      "x": -15,
      "y": 12,
      "z": 6,
      "name": "Empty"
    },
    {
      "x": -15,
      "y": 13,
      "z": 6,
      "name": "Empty"
    },
    {
      "x": -15,
      "y": 14,
      "z": 6,
      "name": "Empty"
    },
    {
      "x": -15,
      "y": 15,
      "z": 6,
      "name": "Empty"
    },
    {
      "x": -15,
      "y": 16,
      "z": 6,
      "name": "Empty"
    },
    {
      "x": -15,
      "y": 0,
      "z": 7,
      "name": "Rock_Stone"
    },
    {
      "x": -15,
      "y": 1,
      "z": 7,
      "name": "Rock_Stone"
    },
    {
      "x": -15,
      "y": 2,
      "z": 7,
      "name": "Rock_Stone"
    },
    {
      "x": -15,
      "y": 3,
      "z": 7,
      "name": "Rock_Stone"
    },
    {
      "x": -15,
      "y": 4,
      "z": 7,
      "name": "Rock_Stone"
    },
    {
      "x": -15,
      "y": 5,
      "z": 7,
      "name": "Rock_Stone"
    },
    {
      "x": -15,
      "y": 6,
      "z": 7,
      "name": "Rock_Stone"
    },
    {
      "x": -15,
      "y": 7,
      "z": 7,
      "name": "Rock_Stone"
    },
    {
      "x": -15,
      "y": 8,
      "z": 7,
      "name": "Rock_Stone"
    },
    {
      "x": -15,
      "y": 9,
      "z": 7,
      "name": "Rock_Stone"
    },
    {
      "x": -15,
      "y": 10,
      "z": 7,
      "name": "Empty"
    },
    {
      "x": -15,
      "y": 11,
      "z": 7,
      "name": "Empty"
    },
    {
      "x": -15,
      "y": 12,
      "z": 7,
      "name": "Empty"
    },
    {
      "x": -15,
      "y": 13,
      "z": 7,
      "name": "Empty"
    },
    {
      "x": -15,
      "y": 14,
      "z": 7,
      "name": "Empty"
    },
    {
      "x": -15,
      "y": 15,
      "z": 7,
      "name": "Empty"
    },
    {
      "x": -15,
      "y": 16,
      "z": 7,
      "name": "Empty"
    },
    {
      "x": -15,
      "y": 0,
      "z": 8,
      "name": "Rock_Stone"
    },
    {
      "x": -15,
      "y": 1,
      "z": 8,
      "name": "Rock_Stone"
    },
    {
      "x": -15,
      "y": 2,
      "z": 8,
      "name": "Rock_Stone"
    },
    {
      "x": -15,
      "y": 3,
      "z": 8,
      "name": "Rock_Stone"
    },
    {
      "x": -15,
      "y": 4,
      "z": 8,
      "name": "Rock_Stone"
    },
    {
      "x": -15,
      "y": 5,
      "z": 8,
      "name": "Rock_Stone"
    },
    {
      "x": -15,
      "y": 6,
      "z": 8,
      "name": "Rock_Stone"
    },
    {
      "x": -15,
      "y": 7,
      "z": 8,
      "name": "Rock_Stone"
    },
    {
      "x": -15,
      "y": 8,
      "z": 8,
      "name": "Rock_Stone"
    },
    {
      "x": -15,
      "y": 9,
      "z": 8,
      "name": "Rock_Stone"
    },
    {
      "x": -15,
      "y": 10,
      "z": 8,
      "name": "Empty"
    },
    {
      "x": -15,
      "y": 11,
      "z": 8,
      "name": "Empty"
    },
    {
      "x": -15,
      "y": 12,
      "z": 8,
      "name": "Empty"
    },
    {
      "x": -15,
      "y": 13,
      "z": 8,
      "name": "Empty"
    },
    {
      "x": -15,
      "y": 14,
      "z": 8,
      "name": "Empty"
    },
    {
      "x": -15,
      "y": 15,
      "z": 8,
      "name": "Empty"
    },
    {
      "x": -15,
      "y": 16,
      "z": 8,
      "name": "Empty"
    },
    {
      "x": -15,
      "y": 0,
      "z": 9,
      "name": "Rock_Stone"
    },
    {
      "x": -15,
      "y": 1,
      "z": 9,
      "name": "Rock_Stone"
    },
    {
      "x": -15,
      "y": 2,
      "z": 9,
      "name": "Rock_Stone"
    },
    {
      "x": -15,
      "y": 3,
      "z": 9,
      "name": "Rock_Stone"
    },
    {
      "x": -15,
      "y": 4,
      "z": 9,
      "name": "Rock_Stone"
    },
    {
      "x": -15,
      "y": 5,
      "z": 9,
      "name": "Rock_Stone"
    },
    {
      "x": -15,
      "y": 6,
      "z": 9,
      "name": "Rock_Stone"
    },
    {
      "x": -15,
      "y": 7,
      "z": 9,
      "name": "Rock_Stone"
    },
    {
      "x": -15,
      "y": 8,
      "z": 9,
      "name": "Rock_Stone"
    },
    {
      "x": -15,
      "y": 9,
      "z": 9,
      "name": "Rock_Stone"
    },
    {
      "x": -15,
      "y": 10,
      "z": 9,
      "name": "Empty"
    },
    {
      "x": -15,
      "y": 11,
      "z": 9,
      "name": "Empty"
    },
    {
      "x": -15,
      "y": 12,
      "z": 9,
      "name": "Empty"
    },
    {
      "x": -15,
      "y": 13,
      "z": 9,
      "name": "Empty"
    },
    {
      "x": -15,
      "y": 14,
      "z": 9,
      "name": "Empty"
    },
    {
      "x": -15,
      "y": 15,
      "z": 9,
      "name": "Empty"
    },
    {
      "x": -15,
      "y": 16,
      "z": 9,
      "name": "Empty"
    },
    {
      "x": -15,
      "y": 0,
      "z": 10,
      "name": "Rock_Stone"
    },
    {
      "x": -15,
      "y": 1,
      "z": 10,
      "name": "Rock_Stone"
    },
    {
      "x": -15,
      "y": 2,
      "z": 10,
      "name": "Rock_Stone"
    },
    {
      "x": -15,
      "y": 3,
      "z": 10,
      "name": "Rock_Stone"
    },
    {
      "x": -15,
      "y": 4,
      "z": 10,
      "name": "Rock_Stone"
    },
    {
      "x": -15,
      "y": 5,
      "z": 10,
      "name": "Rock_Stone"
    },
    {
      "x": -15,
      "y": 6,
      "z": 10,
      "name": "Rock_Stone"
    },
    {
      "x": -15,
      "y": 7,
      "z": 10,
      "name": "Soil_Dirt"
    },
    {
      "x": -15,
      "y": 8,
      "z": 10,
      "name": "Soil_Dirt"
    },
    {
      "x": -15,
      "y": 9,
      "z": 10,
      "name": "Soil_Grass"
    },
    {
      "x": -15,
      "y": 10,
      "z": 10,
      "name": "Empty"
    },
    {
      "x": -15,
      "y": 11,
      "z": 10,
      "name": "Empty"
    },
    {
      "x": -15,
      "y": 12,
      "z": 10,
      "name": "Empty"
    },
    {
      "x": -15,
      "y": 13,
      "z": 10,
      "name": "Empty"
    },
    {
      "x": -15,
      "y": 14,
      "z": 10,
      "name": "Empty"
    },
    {
      "x": -15,
      "y": 15,
      "z": 10,
      "name": "Empty"
    },
    {
      "x": -15,
      "y": 16,
      "z": 10,
      "name": "Empty"
    },
    {
      "x": -15,
      "y": 0,
      "z": 11,
      "name": "Rock_Stone"
    },
    {
      "x": -15,
      "y": 1,
      "z": 11,
      "name": "Rock_Stone"
    },
    {
      "x": -15,
      "y": 2,
      "z": 11,
      "name": "Rock_Stone"
    },
    {
      "x": -15,
      "y": 3,
      "z": 11,
      "name": "Rock_Stone"
    },
    {
      "x": -15,
      "y": 4,
      "z": 11,
      "name": "Rock_Stone"
    },
    {
      "x": -15,
      "y": 5,
      "z": 11,
      "name": "Rock_Stone"
    },
    {
      "x": -15,
      "y": 6,
      "z": 11,
      "name": "Soil_Dirt"
    },
    {
      "x": -15,
      "y": 7,
      "z": 11,
      "name": "Soil_Dirt"
    },
    {
      "x": -15,
      "y": 8,
      "z": 11,
      "name": "Soil_Dirt"
    },
    {
      "x": -15,
      "y": 9,
      "z": 11,
      "name": "Soil_Grass"
    },
    {
      "x": -15,
      "y": 10,
      "z": 11,
      "name": "Empty"
    },
    {
      "x": -15,
      "y": 11,
      "z": 11,
      "name": "Empty"
    },
    {
      "x": -15,
      "y": 12,
      "z": 11,
      "name": "Empty"
    },
    {
      "x": -15,
      "y": 13,
      "z": 11,
      "name": "Empty"
    },
    {
      "x": -15,
      "y": 14,
      "z": 11,
      "name": "Empty"
    },
    {
      "x": -15,
      "y": 15,
      "z": 11,
      "name": "Empty"
    },
    {
      "x": -15,
      "y": 16,
      "z": 11,
      "name": "Empty"
    },
    {
      "x": -15,
      "y": 0,
      "z": 12,
      "name": "Rock_Stone"
    },
    {
      "x": -15,
      "y": 1,
      "z": 12,
      "name": "Rock_Stone"
    },
    {
      "x": -15,
      "y": 2,
      "z": 12,
      "name": "Rock_Stone"
    },
    {
      "x": -15,
      "y": 3,
      "z": 12,
      "name": "Rock_Stone"
    },
    {
      "x": -15,
      "y": 4,
      "z": 12,
      "name": "Rock_Stone"
    },
    {
      "x": -15,
      "y": 5,
      "z": 12,
      "name": "Rock_Stone"
    },
    {
      "x": -15,
      "y": 6,
      "z": 12,
      "name": "Soil_Dirt"
    },
    {
      "x": -15,
      "y": 7,
      "z": 12,
      "name": "Soil_Dirt"
    },
    {
      "x": -15,
      "y": 8,
      "z": 12,
      "name": "Soil_Dirt"
    },
    {
      "x": -15,
      "y": 9,
      "z": 12,
      "name": "Soil_Grass"
    },
    {
      "x": -15,
      "y": 10,
      "z": 12,
      "name": "Empty"
    },
    {
      "x": -15,
      "y": 11,
      "z": 12,
      "name": "Empty"
    },
    {
      "x": -15,
      "y": 12,
      "z": 12,
      "name": "Empty"
    },
    {
      "x": -15,
      "y": 13,
      "z": 12,
      "name": "Empty"
    },
    {
      "x": -15,
      "y": 14,
      "z": 12,
      "name": "Empty"
    },
    {
      "x": -15,
      "y": 15,
      "z": 12,
      "name": "Empty"
    },
    {
      "x": -15,
      "y": 16,
      "z": 12,
      "name": "Empty"
    },
    {
      "x": -14,
      "y": 0,
      "z": -12,
      "name": "Rock_Stone"
    },
    {
      "x": -14,
      "y": 1,
      "z": -12,
      "name": "Rock_Stone"
    },
    {
      "x": -14,
      "y": 2,
      "z": -12,
      "name": "Rock_Stone"
    },
    {
      "x": -14,
      "y": 3,
      "z": -12,
      "name": "Rock_Stone"
    },
    {
      "x": -14,
      "y": 4,
      "z": -12,
      "name": "Rock_Stone"
    },
    {
      "x": -14,
      "y": 5,
      "z": -12,
      "name": "Rock_Stone"
    },
    {
      "x": -14,
      "y": 6,
      "z": -12,
      "name": "Soil_Dirt"
    },
    {
      "x": -14,
      "y": 7,
      "z": -12,
      "name": "Soil_Dirt"
    },
    {
      "x": -14,
      "y": 8,
      "z": -12,
      "name": "Soil_Dirt"
    },
    {
      "x": -14,
      "y": 9,
      "z": -12,
      "name": "Soil_Grass"
    },
    {
      "x": -14,
      "y": 10,
      "z": -12,
      "name": "Empty"
    },
    {
      "x": -14,
      "y": 11,
      "z": -12,
      "name": "Empty"
    },
    {
      "x": -14,
      "y": 12,
      "z": -12,
      "name": "Empty"
    },
    {
      "x": -14,
      "y": 13,
      "z": -12,
      "name": "Empty"
    },
    {
      "x": -14,
      "y": 14,
      "z": -12,
      "name": "Empty"
    },
    {
      "x": -14,
      "y": 15,
      "z": -12,
      "name": "Empty"
    },
    {
      "x": -14,
      "y": 16,
      "z": -12,
      "name": "Empty"
    },
    {
      "x": -14,
      "y": 0,
      "z": -11,
      "name": "Rock_Stone"
    },
    {
      "x": -14,
      "y": 1,
      "z": -11,
      "name": "Rock_Stone"
    },
    {
      "x": -14,
      "y": 2,
      "z": -11,
      "name": "Rock_Stone"
    },
    {
      "x": -14,
      "y": 3,
      "z": -11,
      "name": "Rock_Stone"
    },
    {
      "x": -14,
      "y": 4,
      "z": -11,
      "name": "Rock_Stone"
    },
    {
      "x": -14,
      "y": 5,
      "z": -11,
      "name": "Rock_Stone"
    },
    {
      "x": -14,
      "y": 6,
      "z": -11,
      "name": "Soil_Dirt"
    },
    {
      "x": -14,
      "y": 7,
      "z": -11,
      "name": "Soil_Dirt"
    },
    {
      "x": -14,
      "y": 8,
      "z": -11,
      "name": "Soil_Dirt"
    },
    {
      "x": -14,
      "y": 9,
      "z": -11,
      "name": "Soil_Grass"
    },
    {
      "x": -14,
      "y": 10,
      "z": -11,
      "name": "Empty"
    },
    {
      "x": -14,
      "y": 11,
      "z": -11,
      "name": "Empty"
    },
    {
      "x": -14,
      "y": 12,
      "z": -11,
      "name": "Empty"
    },
    {
      "x": -14,
      "y": 13,
      "z": -11,
      "name": "Empty"
    },
    {
      "x": -14,
      "y": 14,
      "z": -11,
      "name": "Empty"
    },
    {
      "x": -14,
      "y": 15,
      "z": -11,
      "name": "Empty"
    },
    {
      "x": -14,
      "y": 16,
      "z": -11,
      "name": "Empty"
    },
    {
      "x": -14,
      "y": 0,
      "z": -10,
      "name": "Rock_Stone"
    },
    {
      "x": -14,
      "y": 1,
      "z": -10,
      "name": "Rock_Stone"
    },
    {
      "x": -14,
      "y": 2,
      "z": -10,
      "name": "Rock_Stone"
    },
    {
      "x": -14,
      "y": 3,
      "z": -10,
      "name": "Rock_Stone"
    },
    {
      "x": -14,
      "y": 4,
      "z": -10,
      "name": "Rock_Stone"
    },
    {
      "x": -14,
      "y": 5,
      "z": -10,
      "name": "Rock_Stone"
    },
    {
      "x": -14,
      "y": 6,
      "z": -10,
      "name": "Soil_Dirt"
    },
    {
      "x": -14,
      "y": 7,
      "z": -10,
      "name": "Soil_Dirt"
    },
    {
      "x": -14,
      "y": 8,
      "z": -10,
      "name": "Soil_Dirt"
    },
    {
      "x": -14,
      "y": 9,
      "z": -10,
      "name": "Soil_Grass"
    },
    {
      "x": -14,
      "y": 10,
      "z": -10,
      "name": "Empty"
    },
    {
      "x": -14,
      "y": 11,
      "z": -10,
      "name": "Empty"
    },
    {
      "x": -14,
      "y": 12,
      "z": -10,
      "name": "Empty"
    },
    {
      "x": -14,
      "y": 13,
      "z": -10,
      "name": "Empty"
    },
    {
      "x": -14,
      "y": 14,
      "z": -10,
      "name": "Empty"
    },
    {
      "x": -14,
      "y": 15,
      "z": -10,
      "name": "Empty"
    },
    {
      "x": -14,
      "y": 16,
      "z": -10,
      "name": "Empty"
    },
    {
      "x": -14,
      "y": 0,
      "z": -9,
      "name": "Rock_Stone"
    },
    {
      "x": -14,
      "y": 1,
      "z": -9,
      "name": "Rock_Stone"
    },
    {
      "x": -14,
      "y": 2,
      "z": -9,
      "name": "Rock_Stone"
    },
    {
      "x": -14,
      "y": 3,
      "z": -9,
      "name": "Rock_Stone"
    },
    {
      "x": -14,
      "y": 4,
      "z": -9,
      "name": "Rock_Stone"
    },
    {
      "x": -14,
      "y": 5,
      "z": -9,
      "name": "Rock_Stone"
    },
    {
      "x": -14,
      "y": 6,
      "z": -9,
      "name": "Soil_Dirt"
    },
    {
      "x": -14,
      "y": 7,
      "z": -9,
      "name": "Soil_Dirt"
    },
    {
      "x": -14,
      "y": 8,
      "z": -9,
      "name": "Soil_Dirt"
    },
    {
      "x": -14,
      "y": 9,
      "z": -9,
      "name": "Soil_Grass"
    },
    {
      "x": -14,
      "y": 10,
      "z": -9,
      "name": "Empty"
    },
    {
      "x": -14,
      "y": 11,
      "z": -9,
      "name": "Empty"
    },
    {
      "x": -14,
      "y": 12,
      "z": -9,
      "name": "Empty"
    },
    {
      "x": -14,
      "y": 13,
      "z": -9,
      "name": "Empty"
    },
    {
      "x": -14,
      "y": 14,
      "z": -9,
      "name": "Empty"
    },
    {
      "x": -14,
      "y": 15,
      "z": -9,
      "name": "Empty"
    },
    {
      "x": -14,
      "y": 16,
      "z": -9,
      "name": "Empty"
    },
    {
      "x": -14,
      "y": 0,
      "z": -8,
      "name": "Rock_Stone"
    },
    {
      "x": -14,
      "y": 1,
      "z": -8,
      "name": "Rock_Stone"
    },
    {
      "x": -14,
      "y": 2,
      "z": -8,
      "name": "Rock_Stone"
    },
    {
      "x": -14,
      "y": 3,
      "z": -8,
      "name": "Rock_Stone"
    },
    {
      "x": -14,
      "y": 4,
      "z": -8,
      "name": "Rock_Stone"
    },
    {
      "x": -14,
      "y": 5,
      "z": -8,
      "name": "Rock_Stone"
    },
    {
      "x": -14,
      "y": 6,
      "z": -8,
      "name": "Soil_Dirt"
    },
    {
      "x": -14,
      "y": 7,
      "z": -8,
      "name": "Soil_Dirt"
    },
    {
      "x": -14,
      "y": 8,
      "z": -8,
      "name": "Soil_Dirt"
    },
    {
      "x": -14,
      "y": 9,
      "z": -8,
      "name": "Soil_Grass"
    },
    {
      "x": -14,
      "y": 10,
      "z": -8,
      "name": "Empty"
    },
    {
      "x": -14,
      "y": 11,
      "z": -8,
      "name": "Empty"
    },
    {
      "x": -14,
      "y": 12,
      "z": -8,
      "name": "Empty"
    },
    {
      "x": -14,
      "y": 13,
      "z": -8,
      "name": "Empty"
    },
    {
      "x": -14,
      "y": 14,
      "z": -8,
      "name": "Empty"
    },
    {
      "x": -14,
      "y": 15,
      "z": -8,
      "name": "Empty"
    },
    {
      "x": -14,
      "y": 16,
      "z": -8,
      "name": "Empty"
    },
    {
      "x": -14,
      "y": 0,
      "z": -7,
      "name": "Rock_Stone"
    },
    {
      "x": -14,
      "y": 1,
      "z": -7,
      "name": "Rock_Stone"
    },
    {
      "x": -14,
      "y": 2,
      "z": -7,
      "name": "Rock_Stone"
    },
    {
      "x": -14,
      "y": 3,
      "z": -7,
      "name": "Rock_Stone"
    },
    {
      "x": -14,
      "y": 4,
      "z": -7,
      "name": "Rock_Stone"
    },
    {
      "x": -14,
      "y": 5,
      "z": -7,
      "name": "Rock_Stone"
    },
    {
      "x": -14,
      "y": 6,
      "z": -7,
      "name": "Soil_Dirt"
    },
    {
      "x": -14,
      "y": 7,
      "z": -7,
      "name": "Soil_Dirt"
    },
    {
      "x": -14,
      "y": 8,
      "z": -7,
      "name": "Soil_Dirt"
    },
    {
      "x": -14,
      "y": 9,
      "z": -7,
      "name": "Soil_Grass"
    },
    {
      "x": -14,
      "y": 10,
      "z": -7,
      "name": "Empty"
    },
    {
      "x": -14,
      "y": 11,
      "z": -7,
      "name": "Empty"
    },
    {
      "x": -14,
      "y": 12,
      "z": -7,
      "name": "Empty"
    },
    {
      "x": -14,
      "y": 13,
      "z": -7,
      "name": "Empty"
    },
    {
      "x": -14,
      "y": 14,
      "z": -7,
      "name": "Empty"
    },
    {
      "x": -14,
      "y": 15,
      "z": -7,
      "name": "Empty"
    },
    {
      "x": -14,
      "y": 16,
      "z": -7,
      "name": "Empty"
    },
    {
      "x": -14,
      "y": 0,
      "z": -6,
      "name": "Rock_Stone"
    },
    {
      "x": -14,
      "y": 1,
      "z": -6,
      "name": "Rock_Stone"
    },
    {
      "x": -14,
      "y": 2,
      "z": -6,
      "name": "Rock_Stone"
    },
    {
      "x": -14,
      "y": 3,
      "z": -6,
      "name": "Rock_Stone"
    },
    {
      "x": -14,
      "y": 4,
      "z": -6,
      "name": "Rock_Stone"
    },
    {
      "x": -14,
      "y": 5,
      "z": -6,
      "name": "Rock_Stone"
    },
    {
      "x": -14,
      "y": 6,
      "z": -6,
      "name": "Soil_Dirt"
    },
    {
      "x": -14,
      "y": 7,
      "z": -6,
      "name": "Soil_Dirt"
    },
    {
      "x": -14,
      "y": 8,
      "z": -6,
      "name": "Soil_Dirt"
    },
    {
      "x": -14,
      "y": 9,
      "z": -6,
      "name": "Soil_Grass"
    },
    {
      "x": -14,
      "y": 10,
      "z": -6,
      "name": "Empty"
    },
    {
      "x": -14,
      "y": 11,
      "z": -6,
      "name": "Empty"
    },
    {
      "x": -14,
      "y": 12,
      "z": -6,
      "name": "Empty"
    },
    {
      "x": -14,
      "y": 13,
      "z": -6,
      "name": "Empty"
    },
    {
      "x": -14,
      "y": 14,
      "z": -6,
      "name": "Empty"
    },
    {
      "x": -14,
      "y": 15,
      "z": -6,
      "name": "Empty"
    },
    {
      "x": -14,
      "y": 16,
      "z": -6,
      "name": "Empty"
    },
    {
      "x": -14,
      "y": 0,
      "z": -5,
      "name": "Rock_Stone"
    },
    {
      "x": -14,
      "y": 1,
      "z": -5,
      "name": "Rock_Stone"
    },
    {
      "x": -14,
      "y": 2,
      "z": -5,
      "name": "Rock_Stone"
    },
    {
      "x": -14,
      "y": 3,
      "z": -5,
      "name": "Rock_Stone"
    },
    {
      "x": -14,
      "y": 4,
      "z": -5,
      "name": "Rock_Stone"
    },
    {
      "x": -14,
      "y": 5,
      "z": -5,
      "name": "Rock_Stone"
    },
    {
      "x": -14,
      "y": 6,
      "z": -5,
      "name": "Soil_Dirt"
    },
    {
      "x": -14,
      "y": 7,
      "z": -5,
      "name": "Soil_Dirt"
    },
    {
      "x": -14,
      "y": 8,
      "z": -5,
      "name": "Soil_Dirt"
    },
    {
      "x": -14,
      "y": 9,
      "z": -5,
      "name": "Soil_Grass"
    },
    {
      "x": -14,
      "y": 10,
      "z": -5,
      "name": "Empty"
    },
    {
      "x": -14,
      "y": 11,
      "z": -5,
      "name": "Empty"
    },
    {
      "x": -14,
      "y": 12,
      "z": -5,
      "name": "Empty"
    },
    {
      "x": -14,
      "y": 13,
      "z": -5,
      "name": "Empty"
    },
    {
      "x": -14,
      "y": 14,
      "z": -5,
      "name": "Empty"
    },
    {
      "x": -14,
      "y": 15,
      "z": -5,
      "name": "Empty"
    },
    {
      "x": -14,
      "y": 16,
      "z": -5,
      "name": "Empty"
    },
    {
      "x": -14,
      "y": 0,
      "z": -4,
      "name": "Rock_Stone"
    },
    {
      "x": -14,
      "y": 1,
      "z": -4,
      "name": "Rock_Stone"
    },
    {
      "x": -14,
      "y": 2,
      "z": -4,
      "name": "Rock_Stone"
    },
    {
      "x": -14,
      "y": 3,
      "z": -4,
      "name": "Rock_Stone"
    },
    {
      "x": -14,
      "y": 4,
      "z": -4,
      "name": "Rock_Stone"
    },
    {
      "x": -14,
      "y": 5,
      "z": -4,
      "name": "Rock_Stone"
    },
    {
      "x": -14,
      "y": 6,
      "z": -4,
      "name": "Soil_Dirt"
    },
    {
      "x": -14,
      "y": 7,
      "z": -4,
      "name": "Soil_Dirt"
    },
    {
      "x": -14,
      "y": 8,
      "z": -4,
      "name": "Soil_Dirt"
    },
    {
      "x": -14,
      "y": 9,
      "z": -4,
      "name": "Soil_Grass"
    },
    {
      "x": -14,
      "y": 10,
      "z": -4,
      "name": "Empty"
    },
    {
      "x": -14,
      "y": 11,
      "z": -4,
      "name": "Empty"
    },
    {
      "x": -14,
      "y": 12,
      "z": -4,
      "name": "Empty"
    },
    {
      "x": -14,
      "y": 13,
      "z": -4,
      "name": "Empty"
    },
    {
      "x": -14,
      "y": 14,
      "z": -4,
      "name": "Empty"
    },
    {
      "x": -14,
      "y": 15,
      "z": -4,
      "name": "Empty"
    },
    {
      "x": -14,
      "y": 16,
      "z": -4,
      "name": "Empty"
    },
    {
      "x": -14,
      "y": 0,
      "z": -3,
      "name": "Rock_Stone"
    },
    {
      "x": -14,
      "y": 1,
      "z": -3,
      "name": "Rock_Stone"
    },
    {
      "x": -14,
      "y": 2,
      "z": -3,
      "name": "Rock_Stone"
    },
    {
      "x": -14,
      "y": 3,
      "z": -3,
      "name": "Rock_Stone"
    },
    {
      "x": -14,
      "y": 4,
      "z": -3,
      "name": "Rock_Stone"
    },
    {
      "x": -14,
      "y": 5,
      "z": -3,
      "name": "Rock_Stone"
    },
    {
      "x": -14,
      "y": 6,
      "z": -3,
      "name": "Soil_Dirt"
    },
    {
      "x": -14,
      "y": 7,
      "z": -3,
      "name": "Soil_Dirt"
    },
    {
      "x": -14,
      "y": 8,
      "z": -3,
      "name": "Soil_Dirt"
    },
    {
      "x": -14,
      "y": 9,
      "z": -3,
      "name": "Soil_Grass"
    },
    {
      "x": -14,
      "y": 10,
      "z": -3,
      "name": "Empty"
    },
    {
      "x": -14,
      "y": 11,
      "z": -3,
      "name": "Empty"
    },
    {
      "x": -14,
      "y": 12,
      "z": -3,
      "name": "Empty"
    },
    {
      "x": -14,
      "y": 13,
      "z": -3,
      "name": "Empty"
    },
    {
      "x": -14,
      "y": 14,
      "z": -3,
      "name": "Empty"
    },
    {
      "x": -14,
      "y": 15,
      "z": -3,
      "name": "Empty"
    },
    {
      "x": -14,
      "y": 16,
      "z": -3,
      "name": "Empty"
    },
    {
      "x": -14,
      "y": 0,
      "z": -2,
      "name": "Rock_Stone"
    },
    {
      "x": -14,
      "y": 1,
      "z": -2,
      "name": "Rock_Stone"
    },
    {
      "x": -14,
      "y": 2,
      "z": -2,
      "name": "Rock_Stone"
    },
    {
      "x": -14,
      "y": 3,
      "z": -2,
      "name": "Rock_Stone"
    },
    {
      "x": -14,
      "y": 4,
      "z": -2,
      "name": "Rock_Stone"
    },
    {
      "x": -14,
      "y": 5,
      "z": -2,
      "name": "Rock_Stone"
    },
    {
      "x": -14,
      "y": 6,
      "z": -2,
      "name": "Soil_Dirt"
    },
    {
      "x": -14,
      "y": 7,
      "z": -2,
      "name": "Soil_Dirt"
    },
    {
      "x": -14,
      "y": 8,
      "z": -2,
      "name": "Soil_Dirt"
    },
    {
      "x": -14,
      "y": 9,
      "z": -2,
      "name": "Soil_Grass"
    },
    {
      "x": -14,
      "y": 10,
      "z": -2,
      "name": "Empty"
    },
    {
      "x": -14,
      "y": 11,
      "z": -2,
      "name": "Empty"
    },
    {
      "x": -14,
      "y": 12,
      "z": -2,
      "name": "Empty"
    },
    {
      "x": -14,
      "y": 13,
      "z": -2,
      "name": "Empty"
    },
    {
      "x": -14,
      "y": 14,
      "z": -2,
      "name": "Empty"
    },
    {
      "x": -14,
      "y": 15,
      "z": -2,
      "name": "Empty"
    },
    {
      "x": -14,
      "y": 16,
      "z": -2,
      "name": "Empty"
    },
    {
      "x": -14,
      "y": 0,
      "z": -1,
      "name": "Rock_Stone"
    },
    {
      "x": -14,
      "y": 1,
      "z": -1,
      "name": "Rock_Stone"
    },
    {
      "x": -14,
      "y": 2,
      "z": -1,
      "name": "Rock_Stone"
    },
    {
      "x": -14,
      "y": 3,
      "z": -1,
      "name": "Rock_Stone"
    },
    {
      "x": -14,
      "y": 4,
      "z": -1,
      "name": "Rock_Stone"
    },
    {
      "x": -14,
      "y": 5,
      "z": -1,
      "name": "Rock_Stone"
    },
    {
      "x": -14,
      "y": 6,
      "z": -1,
      "name": "Soil_Dirt"
    },
    {
      "x": -14,
      "y": 7,
      "z": -1,
      "name": "Soil_Dirt"
    },
    {
      "x": -14,
      "y": 8,
      "z": -1,
      "name": "Soil_Dirt"
    },
    {
      "x": -14,
      "y": 9,
      "z": -1,
      "name": "Soil_Grass"
    },
    {
      "x": -14,
      "y": 10,
      "z": -1,
      "name": "Empty"
    },
    {
      "x": -14,
      "y": 11,
      "z": -1,
      "name": "Empty"
    },
    {
      "x": -14,
      "y": 12,
      "z": -1,
      "name": "Empty"
    },
    {
      "x": -14,
      "y": 13,
      "z": -1,
      "name": "Empty"
    },
    {
      "x": -14,
      "y": 14,
      "z": -1,
      "name": "Empty"
    },
    {
      "x": -14,
      "y": 15,
      "z": -1,
      "name": "Empty"
    },
    {
      "x": -14,
      "y": 16,
      "z": -1,
      "name": "Empty"
    },
    {
      "x": -14,
      "y": 0,
      "z": 0,
      "name": "Rock_Stone"
    },
    {
      "x": -14,
      "y": 1,
      "z": 0,
      "name": "Rock_Stone"
    },
    {
      "x": -14,
      "y": 2,
      "z": 0,
      "name": "Rock_Stone"
    },
    {
      "x": -14,
      "y": 3,
      "z": 0,
      "name": "Rock_Stone"
    },
    {
      "x": -14,
      "y": 4,
      "z": 0,
      "name": "Rock_Stone"
    },
    {
      "x": -14,
      "y": 5,
      "z": 0,
      "name": "Rock_Stone"
    },
    {
      "x": -14,
      "y": 6,
      "z": 0,
      "name": "Soil_Dirt"
    },
    {
      "x": -14,
      "y": 7,
      "z": 0,
      "name": "Soil_Dirt"
    },
    {
      "x": -14,
      "y": 8,
      "z": 0,
      "name": "Soil_Dirt"
    },
    {
      "x": -14,
      "y": 9,
      "z": 0,
      "name": "Soil_Grass"
    },
    {
      "x": -14,
      "y": 10,
      "z": 0,
      "name": "Empty"
    },
    {
      "x": -14,
      "y": 11,
      "z": 0,
      "name": "Empty"
    },
    {
      "x": -14,
      "y": 12,
      "z": 0,
      "name": "Empty"
    },
    {
      "x": -14,
      "y": 13,
      "z": 0,
      "name": "Empty"
    },
    {
      "x": -14,
      "y": 14,
      "z": 0,
      "name": "Empty"
    },
    {
      "x": -14,
      "y": 15,
      "z": 0,
      "name": "Empty"
    },
    {
      "x": -14,
      "y": 16,
      "z": 0,
      "name": "Empty"
    },
    {
      "x": -14,
      "y": 0,
      "z": 1,
      "name": "Rock_Stone"
    },
    {
      "x": -14,
      "y": 1,
      "z": 1,
      "name": "Rock_Stone"
    },
    {
      "x": -14,
      "y": 2,
      "z": 1,
      "name": "Rock_Stone"
    },
    {
      "x": -14,
      "y": 3,
      "z": 1,
      "name": "Rock_Stone"
    },
    {
      "x": -14,
      "y": 4,
      "z": 1,
      "name": "Rock_Stone"
    },
    {
      "x": -14,
      "y": 5,
      "z": 1,
      "name": "Rock_Stone"
    },
    {
      "x": -14,
      "y": 6,
      "z": 1,
      "name": "Rock_Stone"
    },
    {
      "x": -14,
      "y": 7,
      "z": 1,
      "name": "Soil_Dirt"
    },
    {
      "x": -14,
      "y": 8,
      "z": 1,
      "name": "Soil_Dirt"
    },
    {
      "x": -14,
      "y": 9,
      "z": 1,
      "name": "Soil_Grass"
    },
    {
      "x": -14,
      "y": 10,
      "z": 1,
      "name": "Empty"
    },
    {
      "x": -14,
      "y": 11,
      "z": 1,
      "name": "Empty"
    },
    {
      "x": -14,
      "y": 12,
      "z": 1,
      "name": "Empty"
    },
    {
      "x": -14,
      "y": 13,
      "z": 1,
      "name": "Empty"
    },
    {
      "x": -14,
      "y": 14,
      "z": 1,
      "name": "Empty"
    },
    {
      "x": -14,
      "y": 15,
      "z": 1,
      "name": "Empty"
    },
    {
      "x": -14,
      "y": 16,
      "z": 1,
      "name": "Empty"
    },
    {
      "x": -14,
      "y": 0,
      "z": 2,
      "name": "Rock_Stone"
    },
    {
      "x": -14,
      "y": 1,
      "z": 2,
      "name": "Rock_Stone"
    },
    {
      "x": -14,
      "y": 2,
      "z": 2,
      "name": "Rock_Stone"
    },
    {
      "x": -14,
      "y": 3,
      "z": 2,
      "name": "Rock_Stone"
    },
    {
      "x": -14,
      "y": 4,
      "z": 2,
      "name": "Rock_Stone"
    },
    {
      "x": -14,
      "y": 5,
      "z": 2,
      "name": "Rock_Stone"
    },
    {
      "x": -14,
      "y": 6,
      "z": 2,
      "name": "Rock_Stone"
    },
    {
      "x": -14,
      "y": 7,
      "z": 2,
      "name": "Ore_Iron_Stone"
    },
    {
      "x": -14,
      "y": 8,
      "z": 2,
      "name": "Ore_Iron_Stone"
    },
    {
      "x": -14,
      "y": 9,
      "z": 2,
      "name": "Rock_Stone"
    },
    {
      "x": -14,
      "y": 10,
      "z": 2,
      "name": "Empty"
    },
    {
      "x": -14,
      "y": 11,
      "z": 2,
      "name": "Empty"
    },
    {
      "x": -14,
      "y": 12,
      "z": 2,
      "name": "Empty"
    },
    {
      "x": -14,
      "y": 13,
      "z": 2,
      "name": "Empty"
    },
    {
      "x": -14,
      "y": 14,
      "z": 2,
      "name": "Empty"
    },
    {
      "x": -14,
      "y": 15,
      "z": 2,
      "name": "Empty"
    },
    {
      "x": -14,
      "y": 16,
      "z": 2,
      "name": "Empty"
    },
    {
      "x": -14,
      "y": 0,
      "z": 3,
      "name": "Rock_Stone"
    },
    {
      "x": -14,
      "y": 1,
      "z": 3,
      "name": "Rock_Stone"
    },
    {
      "x": -14,
      "y": 2,
      "z": 3,
      "name": "Rock_Stone"
    },
    {
      "x": -14,
      "y": 3,
      "z": 3,
      "name": "Rock_Stone"
    },
    {
      "x": -14,
      "y": 4,
      "z": 3,
      "name": "Rock_Stone"
    },
    {
      "x": -14,
      "y": 5,
      "z": 3,
      "name": "Rock_Stone"
    },
    {
      "x": -14,
      "y": 6,
      "z": 3,
      "name": "Rock_Stone"
    },
    {
      "x": -14,
      "y": 7,
      "z": 3,
      "name": "Rock_Stone"
    },
    {
      "x": -14,
      "y": 8,
      "z": 3,
      "name": "Rock_Stone"
    },
    {
      "x": -14,
      "y": 9,
      "z": 3,
      "name": "Rock_Stone"
    },
    {
      "x": -14,
      "y": 10,
      "z": 3,
      "name": "Empty"
    },
    {
      "x": -14,
      "y": 11,
      "z": 3,
      "name": "Empty"
    },
    {
      "x": -14,
      "y": 12,
      "z": 3,
      "name": "Empty"
    },
    {
      "x": -14,
      "y": 13,
      "z": 3,
      "name": "Empty"
    },
    {
      "x": -14,
      "y": 14,
      "z": 3,
      "name": "Empty"
    },
    {
      "x": -14,
      "y": 15,
      "z": 3,
      "name": "Empty"
    },
    {
      "x": -14,
      "y": 16,
      "z": 3,
      "name": "Empty"
    },
    {
      "x": -14,
      "y": 0,
      "z": 4,
      "name": "Rock_Stone"
    },
    {
      "x": -14,
      "y": 1,
      "z": 4,
      "name": "Rock_Stone"
    },
    {
      "x": -14,
      "y": 2,
      "z": 4,
      "name": "Rock_Stone"
    },
    {
      "x": -14,
      "y": 3,
      "z": 4,
      "name": "Rock_Stone"
    },
    {
      "x": -14,
      "y": 4,
      "z": 4,
      "name": "Rock_Stone"
    },
    {
      "x": -14,
      "y": 5,
      "z": 4,
      "name": "Rock_Stone"
    },
    {
      "x": -14,
      "y": 6,
      "z": 4,
      "name": "Rock_Stone"
    },
    {
      "x": -14,
      "y": 7,
      "z": 4,
      "name": "Rock_Stone"
    },
    {
      "x": -14,
      "y": 8,
      "z": 4,
      "name": "Rock_Stone"
    },
    {
      "x": -14,
      "y": 9,
      "z": 4,
      "name": "Rock_Stone"
    },
    {
      "x": -14,
      "y": 10,
      "z": 4,
      "name": "*Wood_Softwood_Fence_State_Definitions_Corner",
      "rotation": 1
    },
    {
      "x": -14,
      "y": 11,
      "z": 4,
      "name": "Empty"
    },
    {
      "x": -14,
      "y": 12,
      "z": 4,
      "name": "Empty"
    },
    {
      "x": -14,
      "y": 13,
      "z": 4,
      "name": "Empty"
    },
    {
      "x": -14,
      "y": 14,
      "z": 4,
      "name": "Empty"
    },
    {
      "x": -14,
      "y": 15,
      "z": 4,
      "name": "Empty"
    },
    {
      "x": -14,
      "y": 16,
      "z": 4,
      "name": "Empty"
    },
    {
      "x": -14,
      "y": 0,
      "z": 5,
      "name": "Rock_Stone"
    },
    {
      "x": -14,
      "y": 1,
      "z": 5,
      "name": "Rock_Stone"
    },
    {
      "x": -14,
      "y": 2,
      "z": 5,
      "name": "Rock_Stone"
    },
    {
      "x": -14,
      "y": 3,
      "z": 5,
      "name": "Rock_Stone"
    },
    {
      "x": -14,
      "y": 4,
      "z": 5,
      "name": "Rock_Stone"
    },
    {
      "x": -14,
      "y": 5,
      "z": 5,
      "name": "Rock_Stone"
    },
    {
      "x": -14,
      "y": 6,
      "z": 5,
      "name": "Rock_Stone"
    },
    {
      "x": -14,
      "y": 7,
      "z": 5,
      "name": "Empty"
    },
    {
      "x": -14,
      "y": 8,
      "z": 5,
      "name": "Rock_Stone"
    },
    {
      "x": -14,
      "y": 9,
      "z": 5,
      "name": "Rock_Stone"
    },
    {
      "x": -14,
      "y": 10,
      "z": 5,
      "name": "Wood_Softwood_Fence",
      "rotation": 3
    },
    {
      "x": -14,
      "y": 11,
      "z": 5,
      "name": "Empty"
    },
    {
      "x": -14,
      "y": 12,
      "z": 5,
      "name": "Empty"
    },
    {
      "x": -14,
      "y": 13,
      "z": 5,
      "name": "Empty"
    },
    {
      "x": -14,
      "y": 14,
      "z": 5,
      "name": "Empty"
    },
    {
      "x": -14,
      "y": 15,
      "z": 5,
      "name": "Empty"
    },
    {
      "x": -14,
      "y": 16,
      "z": 5,
      "name": "Empty"
    },
    {
      "x": -14,
      "y": 0,
      "z": 6,
      "name": "Rock_Stone"
    },
    {
      "x": -14,
      "y": 1,
      "z": 6,
      "name": "Rock_Stone"
    },
    {
      "x": -14,
      "y": 2,
      "z": 6,
      "name": "Rock_Stone"
    },
    {
      "x": -14,
      "y": 3,
      "z": 6,
      "name": "Rock_Stone"
    },
    {
      "x": -14,
      "y": 4,
      "z": 6,
      "name": "Rock_Stone"
    },
    {
      "x": -14,
      "y": 5,
      "z": 6,
      "name": "Rock_Stone"
    },
    {
      "x": -14,
      "y": 6,
      "z": 6,
      "name": "Rock_Stone"
    },
    {
      "x": -14,
      "y": 7,
      "z": 6,
      "name": "Empty"
    },
    {
      "x": -14,
      "y": 8,
      "z": 6,
      "name": "Rock_Stone"
    },
    {
      "x": -14,
      "y": 9,
      "z": 6,
      "name": "Rock_Stone"
    },
    {
      "x": -14,
      "y": 10,
      "z": 6,
      "name": "Wood_Softwood_Fence",
      "rotation": 3
    },
    {
      "x": -14,
      "y": 11,
      "z": 6,
      "name": "Empty"
    },
    {
      "x": -14,
      "y": 12,
      "z": 6,
      "name": "Empty"
    },
    {
      "x": -14,
      "y": 13,
      "z": 6,
      "name": "Empty"
    },
    {
      "x": -14,
      "y": 14,
      "z": 6,
      "name": "Empty"
    },
    {
      "x": -14,
      "y": 15,
      "z": 6,
      "name": "Empty"
    },
    {
      "x": -14,
      "y": 16,
      "z": 6,
      "name": "Empty"
    },
    {
      "x": -14,
      "y": 0,
      "z": 7,
      "name": "Rock_Stone"
    },
    {
      "x": -14,
      "y": 1,
      "z": 7,
      "name": "Rock_Stone"
    },
    {
      "x": -14,
      "y": 2,
      "z": 7,
      "name": "Rock_Stone"
    },
    {
      "x": -14,
      "y": 3,
      "z": 7,
      "name": "Rock_Stone"
    },
    {
      "x": -14,
      "y": 4,
      "z": 7,
      "name": "Rock_Stone"
    },
    {
      "x": -14,
      "y": 5,
      "z": 7,
      "name": "Rock_Stone"
    },
    {
      "x": -14,
      "y": 6,
      "z": 7,
      "name": "Rock_Stone"
    },
    {
      "x": -14,
      "y": 7,
      "z": 7,
      "name": "Empty"
    },
    {
      "x": -14,
      "y": 8,
      "z": 7,
      "name": "Rock_Stone"
    },
    {
      "x": -14,
      "y": 9,
      "z": 7,
      "name": "Rock_Stone"
    },
    {
      "x": -14,
      "y": 10,
      "z": 7,
      "name": "Wood_Softwood_Fence",
      "rotation": 3
    },
    {
      "x": -14,
      "y": 11,
      "z": 7,
      "name": "Empty"
    },
    {
      "x": -14,
      "y": 12,
      "z": 7,
      "name": "Empty"
    },
    {
      "x": -14,
      "y": 13,
      "z": 7,
      "name": "Empty"
    },
    {
      "x": -14,
      "y": 14,
      "z": 7,
      "name": "Empty"
    },
    {
      "x": -14,
      "y": 15,
      "z": 7,
      "name": "Empty"
    },
    {
      "x": -14,
      "y": 16,
      "z": 7,
      "name": "Empty"
    },
    {
      "x": -14,
      "y": 0,
      "z": 8,
      "name": "Rock_Stone"
    },
    {
      "x": -14,
      "y": 1,
      "z": 8,
      "name": "Rock_Stone"
    },
    {
      "x": -14,
      "y": 2,
      "z": 8,
      "name": "Rock_Stone"
    },
    {
      "x": -14,
      "y": 3,
      "z": 8,
      "name": "Rock_Stone"
    },
    {
      "x": -14,
      "y": 4,
      "z": 8,
      "name": "Rock_Stone"
    },
    {
      "x": -14,
      "y": 5,
      "z": 8,
      "name": "Rock_Stone"
    },
    {
      "x": -14,
      "y": 6,
      "z": 8,
      "name": "Rock_Stone"
    },
    {
      "x": -14,
      "y": 7,
      "z": 8,
      "name": "Rock_Stone"
    },
    {
      "x": -14,
      "y": 8,
      "z": 8,
      "name": "Rock_Stone"
    },
    {
      "x": -14,
      "y": 9,
      "z": 8,
      "name": "Rock_Stone"
    },
    {
      "x": -14,
      "y": 10,
      "z": 8,
      "name": "*Wood_Softwood_Fence_State_Definitions_Corner",
      "rotation": 2
    },
    {
      "x": -14,
      "y": 11,
