{
  "version": 8,
  "blockIdVersion": 11,
  "anchorX": 0,
  "anchorY": 0,
  "anchorZ": 0,
  "blocks": [
    {
      "x": -5,
      "y": 0,
      "z": -7,
      "name": "Rock_Stone_Cobble"
    },
    {
      "x": -5,
      "y": 1,
      "z": -7,
      "name": "Empty"
    },
    {
      "x": -5,
      "y": 2,
      "z": -7,
      "name": "Empty"
    },
    {
      "x": -5,
      "y": 3,
      "z": -7,
      "name": "Empty"
    },
    {
      "x": -5,
      "y": 4,
      "z": -7,
      "name": "Wood_Redwood_Roof_Hollow",
      "rotation": 2
    },
    {
      "x": -5,
      "y": 5,
      "z": -7,
      "name": "Empty"
    },
    {
      "x": -5,
      "y": 6,
      "z": -7,
      "name": "Empty"
    },
    {
      "x": -5,
      "y": 7,
      "z": -7,
      "name": "Empty"
    },
    {
      "x": -5,
      "y": 8,
      "z": -7,
      "name": "Empty"
    },
    {
      "x": -5,
      "y": 9,
      "z": -7,
      "name": "Empty"
    },
    {
      "x": -5,
      "y": 10,
      "z": -7,
      "name": "Empty"
    },
    {
      "x": -5,
      "y": 11,
      "z": -7,
      "name": "Empty"
    },
    {
      "x": -5,
      "y": 12,
      "z": -7,
      "name": "Empty"
    },
    {
      "x": -5,
      "y": 13,
      "z": -7,
      "name": "Empty"
    },
    {
      "x": -5,
      "y": 14,
      "z": -7,
      "name": "Empty"
    },
    {
      "x": -5,
      "y": 0,
      "z": -6,
      "name": "Rock_Stone_Cobble"
    },
    {
      "x": -5,
      "y": 1,
      "z": -6,
      "name": "Empty"
    },
    {
      "x": -5,
      "y": 2,
      "z": -6,
      "name": "Empty"
    },
    {
      "x": -5,
      "y": 3,
      "z": -6,
      "name": "Empty"
    },
    {
      "x": -5,
      "y": 4,
      "z": -6,
      "name": "Wood_Beech_Branch_Corner",
      "support": 15,
      "rotation": 3
    },
    {
      "x": -5,
      "y": 5,
      "z": -6,
      "name": "Wood_Redwood_Roof",
      "rotation": 2
    },
    {
      "x": -5,
      "y": 6,
      "z": -6,
      "name": "Empty"
    },
    {
      "x": -5,
      "y": 7,
      "z": -6,
      "name": "Empty"
    },
    {
      "x": -5,
      "y": 8,
      "z": -6,
      "name": "Empty"
    },
    {
      "x": -5,
      "y": 9,
      "z": -6,
      "name": "Empty"
    },
    {
      "x": -5,
      "y": 10,
      "z": -6,
      "name": "Empty"
    },
    {
      "x": -5,
      "y": 11,
      "z": -6,
      "name": "Empty"
    },
    {
      "x": -5,
      "y": 12,
      "z": -6,
      "name": "Empty"
    },
    {
      "x": -5,
      "y": 13,
      "z": -6,
      "name": "Empty"
    },
    {
      "x": -5,
      "y": 14,
      "z": -6,
      "name": "Empty"
    },
    {
      "x": -5,
      "y": 0,
      "z": -5,
      "name": "Rock_Stone_Cobble",
      "rotation": 1
    },
    {
      "x": -5,
      "y": 1,
      "z": -5,
      "name": "Furniture_Tavern_Planter",
      "rotation": 1
    },
    {
      "x": -5,
      "y": 2,
      "z": -5,
      "name": "Plant_Flower_Common_Pink2",
      "rotation": 1
    },
    {
      "x": -5,
      "y": 3,
      "z": -5,
      "name": "Empty"
    },
    {
      "x": -5,
      "y": 4,
      "z": -5,
      "name": "Wood_Beech_Branch_Short",
      "support": 15,
      "rotation": 3
    },
    {
      "x": -5,
      "y": 5,
      "z": -5,
      "name": "Wood_Softwood_Planks_Half",
      "rotation": 35
    },
    {
      "x": -5,
      "y": 6,
      "z": -5,
      "name": "Wood_Redwood_Roof",
      "rotation": 2
    },
    {
      "x": -5,
      "y": 7,
      "z": -5,
      "name": "Empty"
    },
    {
      "x": -5,
      "y": 8,
      "z": -5,
      "name": "Empty"
    },
    {
      "x": -5,
      "y": 9,
      "z": -5,
      "name": "Empty"
    },
    {
      "x": -5,
      "y": 10,
      "z": -5,
      "name": "Empty"
    },
    {
      "x": -5,
      "y": 11,
      "z": -5,
      "name": "Empty"
    },
    {
      "x": -5,
      "y": 12,
      "z": -5,
      "name": "Empty"
    },
    {
      "x": -5,
      "y": 13,
      "z": -5,
      "name": "Empty"
    },
    {
      "x": -5,
      "y": 14,
      "z": -5,
      "name": "Empty"
    },
    {
      "x": -5,
      "y": 0,
      "z": -4,
      "name": "Rock_Stone_Cobble",
      "rotation": 1
    },
    {
      "x": -5,
      "y": 1,
      "z": -4,
      "name": "Empty"
    },
    {
      "x": -5,
      "y": 2,
      "z": -4,
      "name": "Empty"
    },
    {
      "x": -5,
      "y": 3,
      "z": -4,
      "name": "Plant_Vine_Wall",
      "support": 15,
      "rotation": 3
    },
    {
      "x": -5,
      "y": 4,
      "z": -4,
      "name": "Plant_Vine",
      "support": 15,
      "rotation": 3
    },
    {
      "x": -5,
      "y": 5,
      "z": -4,
      "name": "Plant_Vine_Wall",
      "support": 15,
      "rotation": 3
    },
    {
      "x": -5,
      "y": 6,
      "z": -4,
      "name": "Wood_Softwood_Planks_Half",
      "rotation": 35
    },
    {
      "x": -5,
      "y": 7,
      "z": -4,
      "name": "Wood_Redwood_Roof",
      "rotation": 2
    },
    {
      "x": -5,
      "y": 8,
      "z": -4,
      "name": "Empty"
    },
    {
      "x": -5,
      "y": 9,
      "z": -4,
      "name": "Empty"
    },
    {
      "x": -5,
      "y": 10,
      "z": -4,
      "name": "Empty"
    },
    {
      "x": -5,
      "y": 11,
      "z": -4,
      "name": "Empty"
    },
    {
      "x": -5,
      "y": 12,
      "z": -4,
      "name": "Empty"
    },
    {
      "x": -5,
      "y": 13,
      "z": -4,
      "name": "Empty"
    },
    {
      "x": -5,
      "y": 14,
      "z": -4,
      "name": "Empty"
    },
    {
      "x": -5,
      "y": 0,
      "z": -3,
      "name": "Rock_Stone_Cobble",
      "rotation": 1
    },
    {
      "x": -5,
      "y": 1,
      "z": -3,
      "name": "Empty"
    },
    {
      "x": -5,
      "y": 2,
      "z": -3,
      "name": "Empty"
    },
    {
      "x": -5,
      "y": 3,
      "z": -3,
      "name": "Empty"
    },
    {
      "x": -5,
      "y": 4,
      "z": -3,
      "name": "Wood_Beech_Branch_Short",
      "support": 15,
      "rotation": 3
    },
    {
      "x": -5,
      "y": 5,
      "z": -3,
      "name": "Empty"
    },
    {
      "x": -5,
      "y": 6,
      "z": -3,
      "name": "Wood_Beech_Branch_Corner",
      "support": 15,
      "rotation": 3
    },
    {
      "x": -5,
      "y": 7,
      "z": -3,
      "name": "Wood_Beech_Trunk",
      "support": 15,
      "rotation": 7
    },
    {
      "x": -5,
      "y": 8,
      "z": -3,
      "name": "Wood_Redwood_Roof_Flat",
      "rotation": 3
    },
    {
      "x": -5,
      "y": 9,
      "z": -3,
      "name": "Empty"
    },
    {
      "x": -5,
      "y": 10,
      "z": -3,
      "name": "Empty"
    },
    {
      "x": -5,
      "y": 11,
      "z": -3,
      "name": "Empty"
    },
    {
      "x": -5,
      "y": 12,
      "z": -3,
      "name": "Empty"
    },
    {
      "x": -5,
      "y": 13,
      "z": -3,
      "name": "Empty"
    },
    {
      "x": -5,
      "y": 14,
      "z": -3,
      "name": "Empty"
    },
    {
      "x": -5,
      "y": 0,
      "z": -2,
      "name": "Rock_Stone_Cobble"
    },
    {
      "x": -5,
      "y": 1,
      "z": -2,
      "name": "Empty"
    },
    {
      "x": -5,
      "y": 2,
      "z": -2,
      "name": "Empty"
    },
    {
      "x": -5,
      "y": 3,
      "z": -2,
      "name": "Empty"
    },
    {
      "x": -5,
      "y": 4,
      "z": -2,
      "name": "Empty"
    },
    {
      "x": -5,
      "y": 5,
      "z": -2,
      "name": "Empty"
    },
    {
      "x": -5,
      "y": 6,
      "z": -2,
      "name": "Wood_Softwood_Planks_Half",
      "rotation": 35
    },
    {
      "x": -5,
      "y": 7,
      "z": -2,
      "name": "Wood_Redwood_Roof"
    },
    {
      "x": -5,
      "y": 8,
      "z": -2,
      "name": "Empty"
    },
    {
      "x": -5,
      "y": 9,
      "z": -2,
      "name": "Empty"
    },
    {
      "x": -5,
      "y": 10,
      "z": -2,
      "name": "Empty"
    },
    {
      "x": -5,
      "y": 11,
      "z": -2,
      "name": "Empty"
    },
    {
      "x": -5,
      "y": 12,
      "z": -2,
      "name": "Empty"
    },
    {
      "x": -5,
      "y": 13,
      "z": -2,
      "name": "Empty"
    },
    {
      "x": -5,
      "y": 14,
      "z": -2,
      "name": "Empty"
    },
    {
      "x": -5,
      "y": 0,
      "z": -1,
      "name": "Rock_Stone_Cobble",
      "rotation": 1
    },
    {
      "x": -5,
      "y": 1,
      "z": -1,
      "name": "Furniture_Village_Crate",
      "rotation": 1
    },
    {
      "x": -5,
      "y": 2,
      "z": -1,
      "name": "Furniture_Tavern_Barrel",
      "rotation": 1
    },
    {
      "x": -5,
      "y": 3,
      "z": -1,
      "name": "Empty"
    },
    {
      "x": -5,
      "y": 4,
      "z": -1,
      "name": "Wood_Beech_Branch_Short",
      "support": 15,
      "rotation": 3
    },
    {
      "x": -5,
      "y": 5,
      "z": -1,
      "name": "Wood_Softwood_Planks_Half",
      "rotation": 35
    },
    {
      "x": -5,
      "y": 6,
      "z": -1,
      "name": "Wood_Redwood_Roof"
    },
    {
      "x": -5,
      "y": 7,
      "z": -1,
      "name": "Empty"
    },
    {
      "x": -5,
      "y": 8,
      "z": -1,
      "name": "Empty"
    },
    {
      "x": -5,
      "y": 9,
      "z": -1,
      "name": "Empty"
    },
    {
      "x": -5,
      "y": 10,
      "z": -1,
      "name": "Empty"
    },
    {
      "x": -5,
      "y": 11,
      "z": -1,
      "name": "Empty"
    },
    {
      "x": -5,
      "y": 12,
      "z": -1,
      "name": "Empty"
    },
    {
      "x": -5,
      "y": 13,
      "z": -1,
      "name": "Empty"
    },
    {
      "x": -5,
      "y": 14,
      "z": -1,
      "name": "Empty"
    },
    {
      "x": -5,
      "y": 0,
      "z": 0,
      "name": "Rock_Stone_Cobble",
      "rotation": 1
    },
    {
      "x": -5,
      "y": 1,
      "z": 0,
      "name": "Furniture_Tavern_Barrel",
      "rotation": 1
    },
    {
      "x": -5,
      "y": 2,
      "z": 0,
      "name": "Plant_Vine_Wall",
      "support": 15,
      "rotation": 3
    },
    {
      "x": -5,
      "y": 3,
      "z": 0,
      "name": "Plant_Vine",
      "support": 15,
      "rotation": 3
    },
    {
      "x": -5,
      "y": 4,
      "z": 0,
      "name": "Wood_Beech_Branch_Corner",
      "support": 15,
      "rotation": 3
    },
    {
      "x": -5,
      "y": 5,
      "z": 0,
      "name": "Wood_Redwood_Roof"
    },
    {
      "x": -5,
      "y": 6,
      "z": 0,
      "name": "Empty"
    },
    {
      "x": -5,
      "y": 7,
      "z": 0,
      "name": "Empty"
    },
    {
      "x": -5,
      "y": 8,
      "z": 0,
      "name": "Empty"
    },
    {
      "x": -5,
      "y": 9,
      "z": 0,
      "name": "Empty"
    },
    {
      "x": -5,
      "y": 10,
      "z": 0,
      "name": "Empty"
    },
    {
      "x": -5,
      "y": 11,
      "z": 0,
      "name": "Empty"
    },
    {
      "x": -5,
      "y": 12,
      "z": 0,
      "name": "Empty"
    },
    {
      "x": -5,
      "y": 13,
      "z": 0,
      "name": "Empty"
    },
    {
      "x": -5,
      "y": 14,
      "z": 0,
      "name": "Empty"
    },
    {
      "x": -5,
      "y": 0,
      "z": 1,
      "name": "Rock_Stone_Cobble"
    },
    {
      "x": -5,
      "y": 1,
      "z": 1,
      "name": "Empty"
    },
    {
      "x": -5,
      "y": 2,
      "z": 1,
      "name": "Empty"
    },
    {
      "x": -5,
      "y": 3,
      "z": 1,
      "name": "Empty"
    },
    {
      "x": -5,
      "y": 4,
      "z": 1,
      "name": "*Wood_Redwood_Roof_Hollow_State_Definitions_Inverted_Corner_Left",
      "rotation": 3
    },
    {
      "x": -5,
      "y": 5,
      "z": 1,
      "name": "Empty"
    },
    {
      "x": -5,
      "y": 6,
      "z": 1,
      "name": "Empty"
    },
    {
      "x": -5,
      "y": 7,
      "z": 1,
      "name": "Empty"
    },
    {
      "x": -5,
      "y": 8,
      "z": 1,
      "name": "Empty"
    },
    {
      "x": -5,
      "y": 9,
      "z": 1,
      "name": "Empty"
    },
    {
      "x": -5,
      "y": 10,
      "z": 1,
      "name": "Empty"
    },
    {
      "x": -5,
      "y": 11,
      "z": 1,
      "name": "Empty"
    },
    {
      "x": -5,
      "y": 12,
      "z": 1,
      "name": "Empty"
    },
    {
      "x": -5,
      "y": 13,
      "z": 1,
      "name": "Empty"
    },
    {
      "x": -5,
      "y": 14,
      "z": 1,
      "name": "Empty"
    },
    {
      "x": -5,
      "y": 0,
      "z": 2,
      "name": "Rock_Stone_Cobble"
    },
    {
      "x": -5,
      "y": 1,
      "z": 2,
      "name": "Empty"
    },
    {
      "x": -5,
      "y": 2,
      "z": 2,
      "name": "Empty"
    },
    {
      "x": -5,
      "y": 3,
      "z": 2,
      "name": "Empty"
    },
    {
      "x": -5,
      "y": 4,
      "z": 2,
      "name": "Wood_Redwood_Roof_Hollow",
      "rotation": 3
    },
    {
      "x": -5,
      "y": 5,
      "z": 2,
      "name": "Empty"
    },
    {
      "x": -5,
      "y": 6,
      "z": 2,
      "name": "Empty"
    },
    {
      "x": -5,
      "y": 7,
      "z": 2,
      "name": "Empty"
    },
    {
      "x": -5,
      "y": 8,
      "z": 2,
      "name": "Empty"
    },
    {
      "x": -5,
      "y": 9,
      "z": 2,
      "name": "Empty"
    },
    {
      "x": -5,
      "y": 10,
      "z": 2,
      "name": "Empty"
    },
    {
      "x": -5,
      "y": 11,
      "z": 2,
      "name": "Empty"
    },
    {
      "x": -5,
      "y": 12,
      "z": 2,
      "name": "Empty"
    },
    {
      "x": -5,
      "y": 13,
      "z": 2,
      "name": "Empty"
    },
    {
      "x": -5,
      "y": 14,
      "z": 2,
      "name": "Empty"
    },
    {
      "x": -5,
      "y": 0,
      "z": 3,
      "name": "Rock_Stone_Cobble"
    },
    {
      "x": -5,
      "y": 1,
      "z": 3,
      "name": "Empty"
    },
    {
      "x": -5,
      "y": 2,
      "z": 3,
      "name": "Empty"
    },
    {
      "x": -5,
      "y": 3,
      "z": 3,
      "name": "Empty"
    },
    {
      "x": -5,
      "y": 4,
      "z": 3,
      "name": "Wood_Redwood_Roof_Hollow",
      "rotation": 3
    },
    {
      "x": -5,
      "y": 5,
      "z": 3,
      "name": "Empty"
    },
    {
      "x": -5,
      "y": 6,
      "z": 3,
      "name": "Empty"
    },
    {
      "x": -5,
      "y": 7,
      "z": 3,
      "name": "Empty"
    },
    {
      "x": -5,
      "y": 8,
      "z": 3,
      "name": "Empty"
    },
    {
      "x": -5,
      "y": 9,
      "z": 3,
      "name": "Empty"
    },
    {
      "x": -5,
      "y": 10,
      "z": 3,
      "name": "Empty"
    },
    {
      "x": -5,
      "y": 11,
      "z": 3,
      "name": "Empty"
    },
    {
      "x": -5,
      "y": 12,
      "z": 3,
      "name": "Empty"
    },
    {
      "x": -5,
      "y": 13,
      "z": 3,
      "name": "Empty"
    },
    {
      "x": -5,
      "y": 14,
      "z": 3,
      "name": "Empty"
    },
    {
      "x": -5,
      "y": 0,
      "z": 4,
      "name": "Rock_Stone_Cobble"
    },
    {
      "x": -5,
      "y": 1,
      "z": 4,
      "name": "Empty"
    },
    {
      "x": -5,
      "y": 2,
      "z": 4,
      "name": "Empty"
    },
    {
      "x": -5,
      "y": 3,
      "z": 4,
      "name": "Empty"
    },
    {
      "x": -5,
      "y": 4,
      "z": 4,
      "name": "Wood_Redwood_Roof_Hollow",
      "rotation": 3
    },
    {
      "x": -5,
      "y": 5,
      "z": 4,
      "name": "Empty"
    },
    {
      "x": -5,
      "y": 6,
      "z": 4,
      "name": "Empty"
    },
    {
      "x": -5,
      "y": 7,
      "z": 4,
      "name": "Empty"
    },
    {
      "x": -5,
      "y": 8,
      "z": 4,
      "name": "Empty"
    },
    {
      "x": -5,
      "y": 9,
      "z": 4,
      "name": "Empty"
    },
    {
      "x": -5,
      "y": 10,
      "z": 4,
      "name": "Empty"
    },
    {
      "x": -5,
      "y": 11,
      "z": 4,
      "name": "Empty"
    },
    {
      "x": -5,
      "y": 12,
      "z": 4,
      "name": "Empty"
    },
    {
      "x": -5,
      "y": 13,
      "z": 4,
      "name": "Empty"
    },
    {
      "x": -5,
      "y": 14,
      "z": 4,
      "name": "Empty"
    },
    {
      "x": -5,
      "y": 0,
      "z": 5,
      "name": "Rock_Stone_Cobble"
    },
    {
      "x": -5,
      "y": 1,
      "z": 5,
      "name": "Empty"
    },
    {
      "x": -5,
      "y": 2,
      "z": 5,
      "name": "Empty"
    },
    {
      "x": -5,
      "y": 3,
      "z": 5,
      "name": "Empty"
    },
    {
      "x": -5,
      "y": 4,
      "z": 5,
      "name": "Wood_Redwood_Roof_Hollow",
      "rotation": 3
    },
    {
      "x": -5,
      "y": 5,
      "z": 5,
      "name": "Empty"
    },
    {
      "x": -5,
      "y": 6,
      "z": 5,
      "name": "Empty"
    },
    {
      "x": -5,
      "y": 7,
      "z": 5,
      "name": "Empty"
    },
    {
      "x": -5,
      "y": 8,
      "z": 5,
      "name": "Empty"
    },
    {
      "x": -5,
      "y": 9,
      "z": 5,
      "name": "Empty"
    },
    {
      "x": -5,
      "y": 10,
      "z": 5,
      "name": "Empty"
    },
    {
      "x": -5,
      "y": 11,
      "z": 5,
      "name": "Empty"
    },
    {
      "x": -5,
      "y": 12,
      "z": 5,
      "name": "Empty"
    },
    {
      "x": -5,
      "y": 13,
      "z": 5,
      "name": "Empty"
    },
    {
      "x": -5,
      "y": 14,
      "z": 5,
      "name": "Empty"
    },
    {
      "x": -5,
      "y": 0,
      "z": 6,
      "name": "Rock_Stone_Cobble"
    },
    {
      "x": -5,
      "y": 1,
      "z": 6,
      "name": "Empty"
    },
    {
      "x": -5,
      "y": 2,
      "z": 6,
      "name": "Empty"
    },
    {
      "x": -5,
      "y": 3,
      "z": 6,
      "name": "Wood_Beech_Branch_Corner",
      "support": 15,
      "rotation": 3
    },
    {
      "x": -5,
      "y": 4,
      "z": 6,
      "name": "Wood_Redwood_Roof",
      "rotation": 3
    },
    {
      "x": -5,
      "y": 5,
      "z": 6,
      "name": "Empty"
    },
    {
      "x": -5,
      "y": 6,
      "z": 6,
      "name": "Empty"
    },
    {
      "x": -5,
      "y": 7,
      "z": 6,
      "name": "Empty"
    },
    {
      "x": -5,
      "y": 8,
      "z": 6,
      "name": "Empty"
    },
    {
      "x": -5,
      "y": 9,
      "z": 6,
      "name": "Empty"
    },
    {
      "x": -5,
      "y": 10,
      "z": 6,
      "name": "Empty"
    },
    {
      "x": -5,
      "y": 11,
      "z": 6,
      "name": "Empty"
    },
    {
      "x": -5,
      "y": 12,
      "z": 6,
      "name": "Empty"
    },
    {
      "x": -5,
      "y": 13,
      "z": 6,
      "name": "Empty"
    },
    {
      "x": -5,
      "y": 14,
      "z": 6,
      "name": "Empty"
    },
    {
      "x": -5,
      "y": 0,
      "z": 7,
      "name": "Rock_Stone_Cobble"
    },
    {
      "x": -5,
      "y": 1,
      "z": 7,
      "name": "Empty"
    },
    {
      "x": -5,
      "y": 2,
      "z": 7,
      "name": "Empty"
    },
    {
      "x": -5,
      "y": 3,
      "z": 7,
      "name": "Empty"
    },
    {
      "x": -5,
      "y": 4,
      "z": 7,
      "name": "Wood_Redwood_Roof_Hollow",
      "rotation": 3
    },
    {
      "x": -5,
      "y": 5,
      "z": 7,
      "name": "Empty"
    },
    {
      "x": -5,
      "y": 6,
      "z": 7,
      "name": "Empty"
    },
    {
      "x": -5,
      "y": 7,
      "z": 7,
      "name": "Empty"
    },
    {
      "x": -5,
      "y": 8,
      "z": 7,
      "name": "Empty"
    },
    {
      "x": -5,
      "y": 9,
      "z": 7,
      "name": "Empty"
    },
    {
      "x": -5,
      "y": 10,
      "z": 7,
      "name": "Empty"
    },
    {
      "x": -5,
      "y": 11,
      "z": 7,
      "name": "Empty"
    },
    {
      "x": -5,
      "y": 12,
      "z": 7,
      "name": "Empty"
    },
    {
      "x": -5,
      "y": 13,
      "z": 7,
      "name": "Empty"
    },
    {
      "x": -5,
      "y": 14,
      "z": 7,
      "name": "Empty"
    },
    {
      "x": -4,
      "y": 0,
      "z": -7,
      "name": "Rock_Stone_Cobble"
    },
    {
      "x": -4,
      "y": 1,
      "z": -7,
      "name": "Empty"
    },
    {
      "x": -4,
      "y": 2,
      "z": -7,
      "name": "Empty"
    },
    {
      "x": -4,
      "y": 3,
      "z": -7,
      "name": "Wood_Beech_Branch_Corner",
      "support": 15,
      "rotation": 2
    },
    {
      "x": -4,
      "y": 4,
      "z": -7,
      "name": "Wood_Redwood_Roof",
      "rotation": 2
    },
    {
      "x": -4,
      "y": 5,
      "z": -7,
      "name": "Empty"
    },
    {
      "x": -4,
      "y": 6,
      "z": -7,
      "name": "Empty"
    },
    {
      "x": -4,
      "y": 7,
      "z": -7,
      "name": "Empty"
    },
    {
      "x": -4,
      "y": 8,
      "z": -7,
      "name": "Empty"
    },
    {
      "x": -4,
      "y": 9,
      "z": -7,
      "name": "Empty"
    },
    {
      "x": -4,
      "y": 10,
      "z": -7,
      "name": "Empty"
    },
    {
      "x": -4,
      "y": 11,
      "z": -7,
      "name": "Empty"
    },
    {
      "x": -4,
      "y": 12,
      "z": -7,
      "name": "Empty"
    },
    {
      "x": -4,
      "y": 13,
      "z": -7,
      "name": "Empty"
    },
    {
      "x": -4,
      "y": 14,
      "z": -7,
      "name": "Empty"
    },
    {
      "x": -4,
      "y": 0,
      "z": -6,
      "name": "Rock_Stone_Cobble",
      "rotation": 1
    },
    {
      "x": -4,
      "y": 1,
      "z": -6,
      "name": "Wood_Beech_Trunk",
      "support": 15,
      "rotation": 1
    },
    {
      "x": -4,
      "y": 2,
      "z": -6,
      "name": "Wood_Beech_Trunk",
      "support": 15,
      "rotation": 1
    },
    {
      "x": -4,
      "y": 3,
      "z": -6,
      "name": "Wood_Beech_Trunk",
      "support": 15,
      "rotation": 1
    },
    {
      "x": -4,
      "y": 4,
      "z": -6,
      "name": "Wood_Beech_Trunk",
      "support": 15,
      "rotation": 1
    },
    {
      "x": -4,
      "y": 5,
      "z": -6,
      "name": "Wood_Softwood_Stairs",
      "rotation": 2
    },
    {
      "x": -4,
      "y": 6,
      "z": -6,
      "name": "Empty"
    },
    {
      "x": -4,
      "y": 7,
      "z": -6,
      "name": "Empty"
    },
    {
      "x": -4,
      "y": 8,
      "z": -6,
      "name": "Wood_Beech_Branch_Short",
      "support": 15,
      "rotation": 3
    },
    {
      "x": -4,
      "y": 9,
      "z": -6,
      "name": "Wood_Beech_Branch_Corner",
      "support": 15,
      "rotation": 3
    },
    {
      "x": -4,
      "y": 10,
      "z": -6,
      "name": "Wood_Redwood_Roof",
      "rotation": 3
    },
    {
      "x": -4,
      "y": 11,
      "z": -6,
      "name": "Empty"
    },
    {
      "x": -4,
      "y": 12,
      "z": -6,
      "name": "Empty"
    },
    {
      "x": -4,
      "y": 13,
      "z": -6,
      "name": "Empty"
    },
    {
      "x": -4,
      "y": 14,
      "z": -6,
      "name": "Empty"
    },
    {
      "x": -4,
      "y": 0,
      "z": -5,
      "name": "Rock_Stone_Cobble",
      "rotation": 1
    },
    {
      "x": -4,
      "y": 1,
      "z": -5,
      "name": "Rock_Stone_Brick",
      "rotation": 1
    },
    {
      "x": -4,
      "y": 2,
      "z": -5,
      "name": "Rock_Stone_Cobble"
    },
    {
      "x": -4,
      "y": 3,
      "z": -5,
      "name": "Wood_Lightwood_Planks"
    },
    {
      "x": -4,
      "y": 4,
      "z": -5,
      "name": "Wood_Beech_Trunk",
      "support": 15,
      "rotation": 6
    },
    {
      "x": -4,
      "y": 5,
      "z": -5,
      "name": "Wood_Lightwood_Planks"
    },
    {
      "x": -4,
      "y": 6,
      "z": -5,
      "name": "Wood_Softwood_Stairs",
      "rotation": 2
    },
    {
      "x": -4,
      "y": 7,
      "z": -5,
      "name": "Empty"
    },
    {
      "x": -4,
      "y": 8,
      "z": -5,
      "name": "Empty"
    },
    {
      "x": -4,
      "y": 9,
      "z": -5,
      "name": "Empty"
    },
    {
      "x": -4,
      "y": 10,
      "z": -5,
      "name": "*Wood_Redwood_Roof_Hollow_State_Definitions_Inverted_Corner_Right",
      "rotation": 3
    },
    {
      "x": -4,
      "y": 11,
      "z": -5,
      "name": "Empty"
    },
    {
      "x": -4,
      "y": 12,
      "z": -5,
      "name": "Empty"
    },
    {
      "x": -4,
      "y": 13,
      "z": -5,
      "name": "Empty"
    },
    {
      "x": -4,
      "y": 14,
      "z": -5,
      "name": "Empty"
    },
    {
      "x": -4,
      "y": 0,
      "z": -4,
      "name": "Rock_Stone_Cobble",
      "rotation": 1
    },
    {
      "x": -4,
      "y": 1,
      "z": -4,
      "name": "Rock_Stone_Brick",
      "rotation": 1
    },
    {
      "x": -4,
      "y": 2,
      "z": -4,
      "name": "Rock_Stone_Cobble"
    },
    {
      "x": -4,
      "y": 3,
      "z": -4,
      "name": "Wood_Lightwood_Planks"
    },
    {
      "x": -4,
      "y": 4,
      "z": -4,
      "name": "Wood_Beech_Trunk",
      "support": 15,
      "rotation": 6
    },
    {
      "x": -4,
      "y": 5,
      "z": -4,
      "name": "Wood_Lightwood_Planks"
    },
    {
      "x": -4,
      "y": 6,
      "z": -4,
      "name": "Wood_Lightwood_Planks"
    },
    {
      "x": -4,
      "y": 7,
      "z": -4,
      "name": "Wood_Softwood_Stairs",
      "rotation": 2
    },
    {
      "x": -4,
      "y": 8,
      "z": -4,
      "name": "Empty"
    },
    {
      "x": -4,
      "y": 9,
      "z": -4,
      "name": "Empty"
    },
    {
      "x": -4,
      "y": 10,
      "z": -4,
      "name": "Empty"
    },
    {
      "x": -4,
      "y": 11,
      "z": -4,
      "name": "Wood_Redwood_Roof_Hollow",
      "rotation": 2
    },
    {
      "x": -4,
      "y": 12,
      "z": -4,
      "name": "Empty"
    },
    {
      "x": -4,
      "y": 13,
      "z": -4,
      "name": "Empty"
    },
    {
      "x": -4,
      "y": 14,
      "z": -4,
      "name": "Empty"
    },
    {
      "x": -4,
      "y": 0,
      "z": -3,
      "name": "Rock_Stone_Cobble",
      "rotation": 1
    },
    {
      "x": -4,
      "y": 1,
      "z": -3,
      "name": "Rock_Stone_Brick",
      "rotation": 1
    },
    {
      "x": -4,
      "y": 2,
      "z": -3,
      "name": "Furniture_Village_Window",
      "rotation": 1
    },
    {
      "x": -4,
      "y": 3,
      "z": -3,
      "name": "Furniture_Village_Window",
      "rotation": 1
    },
    {
      "x": -4,
      "y": 4,
      "z": -3,
      "name": "Wood_Beech_Trunk",
      "support": 15,
      "rotation": 4
    },
    {
      "x": -4,
      "y": 5,
      "z": -3,
      "name": "Wood_Beech_Trunk",
      "support": 15,
      "rotation": 1
    },
    {
      "x": -4,
      "y": 6,
      "z": -3,
      "name": "Wood_Beech_Trunk",
      "support": 15,
      "rotation": 1
    },
    {
      "x": -4,
      "y": 7,
      "z": -3,
      "name": "Wood_Beech_Trunk",
      "support": 15,
      "rotation": 7
    },
    {
      "x": -4,
      "y": 8,
      "z": -3,
      "name": "Wood_Softwood_Planks_Half",
      "rotation": 1
    },
    {
      "x": -4,
      "y": 9,
      "z": -3,
      "name": "Empty"
    },
    {
      "x": -4,
      "y": 10,
      "z": -3,
      "name": "Wood_Beech_Branch_Corner",
      "support": 15,
      "rotation": 3
    },
    {
      "x": -4,
      "y": 11,
      "z": -3,
      "name": "Wood_Beech_Trunk",
      "support": 15,
      "rotation": 5
    },
    {
      "x": -4,
      "y": 12,
      "z": -3,
      "name": "Wood_Redwood_Roof_Flat",
      "rotation": 3
    },
    {
      "x": -4,
      "y": 13,
      "z": -3,
      "name": "Empty"
    },
    {
      "x": -4,
      "y": 14,
      "z": -3,
      "name": "Empty"
    },
    {
      "x": -4,
      "y": 0,
      "z": -2,
      "name": "Rock_Stone_Cobble",
      "rotation": 1
    },
    {
      "x": -4,
      "y": 1,
      "z": -2,
      "name": "Rock_Stone_Brick",
      "rotation": 1
    },
    {
      "x": -4,
      "y": 2,
      "z": -2,
      "name": "Rock_Stone_Cobble"
    },
    {
      "x": -4,
      "y": 3,
      "z": -2,
      "name": "Wood_Lightwood_Planks"
    },
    {
      "x": -4,
      "y": 4,
      "z": -2,
      "name": "Wood_Beech_Trunk",
      "support": 15,
      "rotation": 4
    },
    {
      "x": -4,
      "y": 5,
      "z": -2,
      "name": "Wood_Lightwood_Planks"
    },
    {
      "x": -4,
      "y": 6,
      "z": -2,
      "name": "Wood_Lightwood_Planks"
    },
    {
      "x": -4,
      "y": 7,
      "z": -2,
      "name": "Wood_Softwood_Stairs"
    },
    {
      "x": -4,
      "y": 8,
      "z": -2,
      "name": "Empty"
    },
    {
      "x": -4,
      "y": 9,
      "z": -2,
      "name": "Empty"
    },
    {
      "x": -4,
      "y": 10,
      "z": -2,
      "name": "Empty"
    },
    {
      "x": -4,
      "y": 11,
      "z": -2,
      "name": "Wood_Redwood_Roof_Hollow"
    },
    {
      "x": -4,
      "y": 12,
      "z": -2,
      "name": "Empty"
    },
    {
      "x": -4,
      "y": 13,
      "z": -2,
      "name": "Empty"
    },
    {
      "x": -4,
      "y": 14,
      "z": -2,
      "name": "Empty"
    },
    {
      "x": -4,
      "y": 0,
      "z": -1,
      "name": "Rock_Stone_Cobble",
      "rotation": 1
    },
    {
      "x": -4,
      "y": 1,
      "z": -1,
      "name": "Rock_Stone_Brick",
      "rotation": 1
    },
    {
      "x": -4,
      "y": 2,
      "z": -1,
      "name": "Rock_Stone_Cobble"
    },
    {
      "x": -4,
      "y": 3,
      "z": -1,
      "name": "Wood_Lightwood_Planks"
    },
    {
      "x": -4,
      "y": 4,
      "z": -1,
      "name": "Wood_Beech_Trunk",
      "support": 15,
      "rotation": 4
    },
    {
      "x": -4,
      "y": 5,
      "z": -1,
      "name": "Wood_Lightwood_Planks"
    },
    {
      "x": -4,
      "y": 6,
      "z": -1,
      "name": "Wood_Softwood_Stairs"
    },
    {
      "x": -4,
      "y": 7,
      "z": -1,
      "name": "Empty"
    },
    {
      "x": -4,
      "y": 8,
      "z": -1,
      "name": "Empty"
    },
    {
      "x": -4,
      "y": 9,
      "z": -1,
      "name": "Empty"
    },
    {
      "x": -4,
      "y": 10,
      "z": -1,
      "name": "*Wood_Redwood_Roof_Hollow_State_Definitions_Inverted_Corner_Left",
      "rotation": 3
    },
    {
      "x": -4,
      "y": 11,
      "z": -1,
      "name": "Empty"
    },
    {
      "x": -4,
      "y": 12,
      "z": -1,
      "name": "Empty"
    },
    {
      "x": -4,
      "y": 13,
      "z": -1,
      "name": "Empty"
    },
    {
      "x": -4,
      "y": 14,
      "z": -1,
      "name": "Empty"
    },
    {
      "x": -4,
      "y": 0,
      "z": 0,
      "name": "Rock_Stone_Cobble",
      "rotation": 1
    },
    {
      "x": -4,
      "y": 1,
      "z": 0,
      "name": "Wood_Beech_Trunk",
      "support": 15,
      "rotation": 1
    },
    {
      "x": -4,
      "y": 2,
      "z": 0,
      "name": "Wood_Beech_Trunk",
      "support": 15,
      "rotation": 1
    },
    {
      "x": -4,
      "y": 3,
      "z": 0,
      "name": "Wood_Beech_Trunk",
      "support": 15,
      "rotation": 1
    },
    {
      "x": -4,
      "y": 4,
      "z": 0,
      "name": "Wood_Beech_Trunk",
      "support": 15,
      "rotation": 3
    },
    {
      "x": -4,
      "y": 5,
      "z": 0,
      "name": "*Wood_Redwood_Roof_State_Definitions_Inverted_Corner_Left",
      "rotation": 3
    },
    {
      "x": -4,
      "y": 6,
      "z": 0,
      "name": "Empty"
    },
    {
      "x": -4,
      "y": 7,
      "z": 0,
      "name": "Wood_Beech_Branch_Short",
      "support": 15,
      "rotation": 3
    },
    {
      "x": -4,
      "y": 8,
      "z": 0,
      "name": "Wood_Beech_Branch_Short",
      "support": 15,
      "rotation": 3
    },
    {
      "x": -4,
      "y": 9,
      "z": 0,
      "name": "Wood_Beech_Branch_Corner",
      "support": 15,
      "rotation": 3
    },
    {
      "x": -4,
      "y": 10,
      "z": 0,
      "name": "Wood_Redwood_Roof",
      "rotation": 3
    },
    {
      "x": -4,
      "y": 11,
      "z": 0,
      "name": "Empty"
    },
    {
      "x": -4,
      "y": 12,
      "z": 0,
      "name": "Empty"
    },
    {
      "x": -4,
      "y": 13,
      "z": 0,
      "name": "Empty"
    },
    {
      "x": -4,
      "y": 14,
      "z": 0,
      "name": "Empty"
    },
    {
      "x": -4,
      "y": 0,
      "z": 1,
      "name": "Rock_Stone_Cobble"
    },
    {
      "x": -4,
      "y": 1,
      "z": 1,
      "name": "Rock_Stone_Brick"
    },
    {
      "x": -4,
      "y": 2,
      "z": 1,
      "name": "Rock_Stone_Cobble"
    },
    {
      "x": -4,
      "y": 3,
      "z": 1,
      "name": "Wood_Lightwood_Planks"
    },
    {
      "x": -4,
      "y": 4,
      "z": 1,
      "name": "Wood_Beech_Trunk",
      "support": 15,
      "rotation": 4
    },
    {
      "x": -4,
      "y": 5,
      "z": 1,
      "name": "Wood_Redwood_Roof",
      "rotation": 3
    },
    {
      "x": -4,
      "y": 6,
      "z": 1,
      "name": "Empty"
    },
    {
      "x": -4,
      "y": 7,
      "z": 1,
      "name": "Empty"
    },
    {
      "x": -4,
      "y": 8,
      "z": 1,
      "name": "Empty"
    },
    {
      "x": -4,
      "y": 9,
      "z": 1,
      "name": "Empty"
    },
    {
      "x": -4,
      "y": 10,
      "z": 1,
      "name": "*Wood_Redwood_Roof_Hollow_State_Definitions_Inverted_Corner_Right",
      "rotation": 3
    },
    {
      "x": -4,
      "y": 11,
      "z": 1,
      "name": "Empty"
    },
    {
      "x": -4,
      "y": 12,
      "z": 1,
      "name": "Empty"
    },
    {
      "x": -4,
      "y": 13,
      "z": 1,
      "name": "Empty"
    },
    {
      "x": -4,
      "y": 14,
      "z": 1,
      "name": "Empty"
    },
    {
      "x": -4,
      "y": 0,
      "z": 2,
      "name": "Rock_Stone_Cobble"
    },
    {
      "x": -4,
      "y": 1,
      "z": 2,
      "name": "Rock_Stone_Brick"
    },
    {
      "x": -4,
      "y": 2,
      "z": 2,
      "name": "Rock_Stone_Cobble"
    },
    {
      "x": -4,
      "y": 3,
      "z": 2,
      "name": "Wood_Lightwood_Planks"
    },
    {
      "x": -4,
      "y": 4,
      "z": 2,
      "name": "Wood_Beech_Trunk",
      "support": 15,
      "rotation": 4
    },
    {
      "x": -4,
      "y": 5,
      "z": 2,
      "name": "Wood_Redwood_Roof",
      "rotation": 3
    },
    {
      "x": -4,
      "y": 6,
      "z": 2,
      "name": "Empty"
    },
    {
      "x": -4,
      "y": 7,
      "z": 2,
      "name": "Empty"
    },
    {
      "x": -4,
      "y": 8,
      "z": 2,
      "name": "Empty"
    },
    {
      "x": -4,
      "y": 9,
      "z": 2,
      "name": "Empty"
    },
    {
      "x": -4,
      "y": 10,
      "z": 2,
      "name": "Empty"
    },
    {
      "x": -4,
      "y": 11,
      "z": 2,
      "name": "Wood_Redwood_Roof_Hollow",
      "rotation": 2
    },
    {
      "x": -4,
      "y": 12,
      "z": 2,
      "name": "Empty"
    },
    {
      "x": -4,
      "y": 13,
      "z": 2,
      "name": "Empty"
    },
    {
      "x": -4,
      "y": 14,
      "z": 2,
      "name": "Empty"
    },
    {
      "x": -4,
      "y": 0,
      "z": 3,
      "name": "Rock_Stone_Cobble"
    },
    {
      "x": -4,
      "y": 1,
      "z": 3,
      "name": "Rock_Stone_Brick"
    },
    {
      "x": -4,
      "y": 2,
      "z": 3,
      "name": "Furniture_Village_Window",
      "rotation": 1
    },
    {
      "x": -4,
      "y": 3,
      "z": 3,
      "name": "Furniture_Village_Window",
      "rotation": 1
    },
    {
      "x": -4,
      "y": 4,
      "z": 3,
      "name": "Wood_Beech_Trunk",
      "support": 15,
      "rotation": 4
    },
    {
      "x": -4,
      "y": 5,
      "z": 3,
      "name": "Wood_Redwood_Roof",
      "rotation": 3
    },
    {
      "x": -4,
      "y": 6,
      "z": 3,
      "name": "Empty"
    },
    {
      "x": -4,
      "y": 7,
      "z": 3,
      "name": "Wood_Beech_Branch_Short",
      "support": 15,
      "rotation": 3
    },
    {
      "x": -4,
      "y": 8,
      "z": 3,
      "name": "Empty"
    },
    {
      "x": -4,
      "y": 9,
      "z": 3,
      "name": "Empty"
    },
    {
      "x": -4,
      "y": 10,
      "z": 3,
      "name": "Wood_Beech_Branch_Corner",
      "support": 15,
      "rotation": 3
    },
    {
      "x": -4,
      "y": 11,
      "z": 3,
      "name": "Wood_Beech_Trunk",
      "support": 15,
      "rotation": 5
    },
    {
      "x": -4,
      "y": 12,
      "z": 3,
      "name": "Wood_Redwood_Roof_Flat",
      "rotation": 3
    },
    {
      "x": -4,
      "y": 13,
      "z": 3,
      "name": "Empty"
    },
    {
      "x": -4,
      "y": 14,
      "z": 3,
      "name": "Empty"
    },
    {
      "x": -4,
      "y": 0,
      "z": 4,
      "name": "Rock_Stone_Cobble"
    },
    {
      "x": -4,
      "y": 1,
      "z": 4,
      "name": "Rock_Stone_Brick"
    },
    {
      "x": -4,
      "y": 2,
      "z": 4,
      "name": "Rock_Stone_Cobble"
    },
    {
      "x": -4,
      "y": 3,
      "z": 4,
      "name": "Wood_Lightwood_Planks"
    },
    {
      "x": -4,
      "y": 4,
      "z": 4,
      "name": "Wood_Beech_Trunk",
      "support": 15,
      "rotation": 4
    },
    {
      "x": -4,
      "y": 5,
      "z": 4,
      "name": "Wood_Redwood_Roof",
      "rotation": 3
    },
    {
      "x": -4,
      "y": 6,
      "z": 4,
      "name": "Empty"
    },
    {
      "x": -4,
      "y": 7,
      "z": 4,
      "name": "Empty"
    },
    {
      "x": -4,
      "y": 8,
      "z": 4,
      "name": "Empty"
    },
    {
      "x": -4,
      "y": 9,
      "z": 4,
      "name": "Empty"
    },
    {
      "x": -4,
      "y": 10,
      "z": 4,
      "name": "Empty"
    },
    {
      "x": -4,
      "y": 11,
      "z": 4,
      "name": "Wood_Redwood_Roof_Hollow"
    },
    {
      "x": -4,
      "y": 12,
      "z": 4,
      "name": "Empty"
    },
    {
      "x": -4,
      "y": 13,
      "z": 4,
      "name": "Empty"
    },
    {
      "x": -4,
      "y": 14,
      "z": 4,
      "name": "Empty"
    },
    {
      "x": -4,
      "y": 0,
      "z": 5,
      "name": "Rock_Stone_Cobble"
    },
    {
      "x": -4,
      "y": 1,
      "z": 5,
      "name": "Rock_Stone_Brick"
    },
    {
      "x": -4,
      "y": 2,
      "z": 5,
      "name": "Rock_Stone_Cobble"
    },
    {
      "x": -4,
      "y": 3,
      "z": 5,
      "name": "Wood_Lightwood_Planks"
    },
    {
      "x": -4,
      "y": 4,
      "z": 5,
      "name": "Wood_Beech_Trunk",
      "support": 15,
      "rotation": 4
    },
    {
      "x": -4,
      "y": 5,
      "z": 5,
      "name": "Wood_Redwood_Roof",
      "rotation": 3
    },
    {
      "x": -4,
      "y": 6,
      "z": 5,
      "name": "Empty"
    },
    {
      "x": -4,
      "y": 7,
      "z": 5,
      "name": "Empty"
    },
    {
      "x": -4,
      "y": 8,
      "z": 5,
      "name": "Empty"
    },
    {
      "x": -4,
      "y": 9,
      "z": 5,
      "name": "Empty"
    },
    {
      "x": -4,
      "y": 10,
      "z": 5,
      "name": "*Wood_Redwood_Roof_Hollow_State_Definitions_Inverted_Corner_Left",
      "rotation": 3
    },
    {
      "x": -4,
      "y": 11,
      "z": 5,
      "name": "Empty"
    },
    {
      "x": -4,
      "y": 12,
      "z": 5,
      "name": "Empty"
    },
    {
      "x": -4,
      "y": 13,
      "z": 5,
      "name": "Empty"
    },
    {
      "x": -4,
      "y": 14,
      "z": 5,
      "name": "Empty"
    },
    {
      "x": -4,
      "y": 0,
      "z": 6,
      "name": "Rock_Stone_Cobble"
    },
    {
      "x": -4,
      "y": 1,
      "z": 6,
      "name": "Wood_Beech_Trunk",
      "support": 15
    },
    {
      "x": -4,
      "y": 2,
      "z": 6,
      "name": "Wood_Beech_Trunk",
      "support": 15
    },
    {
      "x": -4,
      "y": 3,
      "z": 6,
      "name": "Wood_Beech_Trunk",
      "support": 15
    },
    {
      "x": -4,
      "y": 4,
      "z": 6,
      "name": "Wood_Beech_Trunk",
      "support": 15
    },
    {
      "x": -4,
      "y": 5,
      "z": 6,
      "name": "Wood_Softwood_Stairs",
      "rotation": 3
    },
    {
      "x": -4,
      "y": 6,
      "z": 6,
      "name": "Empty"
    },
    {
      "x": -4,
      "y": 7,
      "z": 6,
      "name": "Wood_Beech_Branch_Short",
      "support": 15,
      "rotation": 3
    },
    {
      "x": -4,
      "y": 8,
      "z": 6,
      "name": "Empty"
    },
    {
      "x": -4,
      "y": 9,
      "z": 6,
      "name": "Wood_Beech_Branch_Corner",
      "support": 15,
      "rotation": 3
    },
    {
      "x": -4,
      "y": 10,
      "z": 6,
      "name": "Wood_Redwood_Roof",
      "rotation": 3
    },
    {
      "x": -4,
      "y": 11,
      "z": 6,
      "name": "Empty"
    },
    {
      "x": -4,
      "y": 12,
      "z": 6,
      "name": "Empty"
    },
    {
      "x": -4,
      "y": 13,
      "z": 6,
      "name": "Empty"
    },
    {
      "x": -4,
      "y": 14,
      "z": 6,
      "name": "Empty"
    },
    {
      "x": -4,
      "y": 0,
      "z": 7,
      "name": "Rock_Stone_Cobble"
    },
    {
      "x": -4,
      "y": 1,
      "z": 7,
      "name": "Empty"
    },
    {
      "x": -4,
      "y": 2,
      "z": 7,
      "name": "Empty"
    },
    {
      "x": -4,
      "y": 3,
      "z": 7,
      "name": "Empty"
    },
    {
      "x": -4,
      "y": 4,
      "z": 7,
      "name": "Wood_Beech_Branch_Corner",
      "support": 15
    },
    {
      "x": -4,
      "y": 5,
      "z": 7,
      "name": "Wood_Redwood_Roof",
      "rotation": 3
    },
    {
      "x": -4,
      "y": 6,
      "z": 7,
      "name": "Empty"
    },
    {
      "x": -4,
      "y": 7,
      "z": 7,
      "name": "Empty"
    },
    {
      "x": -4,
      "y": 8,
      "z": 7,
      "name": "Empty"
    },
    {
      "x": -4,
      "y": 9,
      "z": 7,
      "name": "Empty"
    },
    {
      "x": -4,
      "y": 10,
      "z": 7,
      "name": "*Wood_Redwood_Roof_Hollow_State_Definitions_Corner_Right"
    },
    {
      "x": -4,
      "y": 11,
      "z": 7,
      "name": "Empty"
    },
    {
      "x": -4,
      "y": 12,
      "z": 7,
      "name": "Empty"
    },
    {
      "x": -4,
      "y": 13,
      "z": 7,
      "name": "Empty"
    },
    {
      "x": -4,
      "y": 14,
      "z": 7,
      "name": "Empty"
    },
    {
      "x": -3,
      "y": 0,
      "z": -7,
      "name": "Rock_Stone_Cobble",
      "rotation": 1
    },
    {
      "x": -3,
      "y": 1,
      "z": -7,
      "name": "Furniture_Tavern_Barrel",
      "rotation": 1
    },
    {
      "x": -3,
      "y": 2,
      "z": -7,
      "name": "Empty"
    },
    {
      "x": -3,
      "y": 3,
      "z": -7,
      "name": "Empty"
    },
    {
      "x": -3,
      "y": 4,
      "z": -7,
      "name": "Wood_Redwood_Roof_Hollow",
      "rotation": 2
    },
    {
      "x": -3,
      "y": 5,
      "z": -7,
      "name": "Empty"
    },
    {
      "x": -3,
      "y": 6,
      "z": -7,
      "name": "Empty"
    },
    {
      "x": -3,
      "y": 7,
      "z": -7,
      "name": "Empty"
    },
    {
      "x": -3,
      "y": 8,
      "z": -7,
      "name": "Wood_Beech_Branch_Short",
      "support": 15,
      "rotation": 2
    },
    {
      "x": -3,
      "y": 9,
      "z": -7,
      "name": "Wood_Beech_Branch_Corner",
      "support": 15,
      "rotation": 2
    },
    {
      "x": -3,
      "y": 10,
      "z": -7,
      "name": "Wood_Redwood_Roof",
      "rotation": 2
    },
    {
      "x": -3,
      "y": 11,
      "z": -7,
      "name": "Empty"
    },
    {
      "x": -3,
      "y": 12,
      "z": -7,
      "name": "Empty"
    },
    {
      "x": -3,
      "y": 13,
      "z": -7,
      "name": "Empty"
    },
    {
      "x": -3,
      "y": 14,
      "z": -7,
      "name": "Empty"
    },
    {
      "x": -3,
      "y": 0,
      "z": -6,
      "name": "Rock_Stone_Cobble",
      "rotation": 1
    },
    {
      "x": -3,
      "y": 1,
      "z": -6,
      "name": "Rock_Stone_Brick",
      "rotation": 1
    },
    {
      "x": -3,
      "y": 2,
      "z": -6,
      "name": "Rock_Stone_Cobble"
    },
    {
      "x": -3,
      "y": 3,
      "z": -6,
      "name": "Wood_Lightwood_Planks"
    },
    {
      "x": -3,
      "y": 4,
      "z": -6,
      "name": "Wood_Beech_Trunk",
      "support": 15,
      "rotation": 5
    },
    {
      "x": -3,
      "y": 5,
      "z": -6,
      "name": "Wood_Beech_Trunk",
      "support": 15
    },
    {
      "x": -3,
      "y": 6,
      "z": -6,
      "name": "Wood_Beech_Trunk",
      "support": 15
    },
    {
      "x": -3,
      "y": 7,
      "z": -6,
      "name": "Wood_Beech_Trunk",
      "support": 15
    },
    {
      "x": -3,
      "y": 8,
      "z": -6,
      "name": "Wood_Beech_Trunk",
      "support": 15
    },
    {
      "x": -3,
      "y": 9,
      "z": -6,
      "name": "Wood_Beech_Trunk",
      "support": 15
    },
    {
      "x": -3,
      "y": 10,
      "z": -6,
      "name": "Wood_Beech_Trunk",
      "support": 15
    },
    {
      "x": -3,
      "y": 11,
      "z": -6,
      "name": "*Wood_Redwood_Roof_State_Definitions_Corner_Right",
      "rotation": 3
    },
    {
      "x": -3,
      "y": 12,
      "z": -6,
      "name": "Empty"
    },
    {
      "x": -3,
      "y": 13,
      "z": -6,
      "name": "Empty"
    },
    {
      "x": -3,
      "y": 14,
      "z": -6,
      "name": "Empty"
    },
    {
      "x": -3,
      "y": 0,
      "z": -5,
      "name": "Wood_Drywood_Planks",
      "rotation": 1
    },
    {
      "x": -3,
      "y": 1,
      "z": -5,
      "name": "Furniture_Village_Crate",
      "rotation": 1
    },
    {
      "x": -3,
      "y": 2,
      "z": -5,
      "name": "Furniture_Village_Crate",
      "rotation": 1
    },
    {
      "x": -3,
      "y": 3,
      "z": -5,
      "name": "Wood_Softwood_Planks_Half",
      "rotation": 8
    },
    {
      "x": -3,
      "y": 4,
      "z": -5,
      "name": "Wood_Lightwood_Planks"
    },
    {
      "x": -3,
      "y": 5,
      "z": -5,
      "name": "Wood_Lightwood_Planks"
    },
    {
      "x": -3,
      "y": 6,
      "z": -5,
      "name": "Wood_Lightwood_Planks"
    },
    {
      "x": -3,
      "y": 7,
      "z": -5,
      "name": "Wood_Lightwood_Planks"
    },
    {
      "x": -3,
      "y": 8,
      "z": -5,
      "name": "Wood_Beech_Trunk",
      "support": 15,
      "rotation": 4
    },
    {
      "x": -3,
      "y": 9,
      "z": -5,
      "name": "Wood_Lightwood_Planks"
    },
    {
      "x": -3,
      "y": 10,
      "z": -5,
      "name": "Wood_Lightwood_Planks"
    },
    {
      "x": -3,
      "y": 11,
      "z": -5,
      "name": "Wood_Redwood_Roof",
      "rotation": 3
    },
    {
      "x": -3,
      "y": 12,
      "z": -5,
      "name": "Empty"
    },
    {
      "x": -3,
      "y": 13,
      "z": -5,
      "name": "Empty"
    },
    {
      "x": -3,
      "y": 14,
      "z": -5,
      "name": "Empty"
    },
    {
      "x": -3,
      "y": 0,
      "z": -4,
      "name": "Wood_Drywood_Planks",
      "rotation": 1
    },
    {
      "x": -3,
      "y": 1,
      "z": -4,
      "name": "Furniture_Tavern_Chest_Small",
      "components": {
        "Components": {
          "ItemContainerBlock": {
            "ItemContainer": {
              "Capacity": 18,
              "Items": {}
            },
            "Capacity": 18
          }
        }
      },
      "rotation": 1
    },
    {
      "x": -3,
      "y": 2,
      "z": -4,
      "name": "Empty"
    },
    {
      "x": -3,
      "y": 3,
      "z": -4,
      "name": "Wood_Softwood_Planks_Half",
      "rotation": 8
    },
    {
      "x": -3,
      "y": 4,
      "z": -4,
      "name": "Wood_Lightwood_Planks"
    },
    {
      "x": -3,
      "y": 5,
      "z": -4,
      "name": "Wood_Lightwood_Planks"
    },
    {
      "x": -3,
      "y": 6,
      "z": -4,
      "name": "Wood_Lightwood_Planks"
    },
    {
      "x": -3,
      "y": 7,
      "z": -4,
      "name": "Wood_Lightwood_Planks"
    },
    {
      "x": -3,
      "y": 8,
      "z": -4,
      "name": "Wood_Beech_Trunk",
      "support": 15,
      "rotation": 4
    },
    {
      "x": -3,
      "y": 9,
      "z": -4,
      "name": "Furniture_Village_Window",
      "rotation": 1
    },
    {
      "x": -3,
      "y": 10,
      "z": -4,
      "name": "Furniture_Village_Window",
      "rotation": 1
    },
    {
      "x": -3,
      "y": 11,
      "z": -4,
      "name": "*Wood_Redwood_Roof_State_Definitions_Inverted_Corner_Left",
      "rotation": 2
    },
    {
      "x": -3,
      "y": 12,
      "z": -4,
      "name": "Empty"
    },
    {
      "x": -3,
      "y": 13,
      "z": -4,
      "name": "Empty"
    },
    {
      "x": -3,
      "y": 14,
      "z": -4,
      "name": "Empty"
    },
    {
      "x": -3,
      "y": 0,
      "z": -3,
      "name": "Wood_Drywood_Planks",
      "rotation": 1
    },
    {
      "x": -3,
      "y": 1,
      "z": -3,
      "name": "Furniture_Crude_Shelf",
      "rotation": 1
    },
    {
      "x": -3,
      "y": 2,
      "z": -3,
      "name": "Empty"
    },
    {
      "x": -3,
      "y": 3,
      "z": -3,
      "name": "Wood_Softwood_Planks_Half",
      "rotation": 8
    },
    {
      "x": -3,
      "y": 4,
      "z": -3,
      "name": "Wood_Lightwood_Planks"
    },
    {
      "x": -3,
      "y": 5,
      "z": -3,
      "name": "Wood_Lightwood_Planks"
    },
    {
      "x": -3,
      "y": 6,
      "z": -3,
      "name": "Wood_Lightwood_Planks"
    },
    {
      "x": -3,
      "y": 7,
      "z": -3,
      "name": "Wood_Lightwood_Planks"
    },
    {
      "x": -3,
      "y": 8,
      "z": -3,
      "name": "Wood_Beech_Trunk",
      "support": 15,
      "rotation": 4
    },
    {
      "x": -3,
      "y": 9,
      "z": -3,
      "name": "Wood_Beech_Trunk",
      "support": 15
    },
    {
      "x": -3,
      "y": 10,
      "z": -3,
      "name": "Wood_Beech_Trunk",
      "support": 15
    },
    {
      "x": -3,
      "y": 11,
      "z": -3,
      "name": "Wood_Beech_Trunk",
      "support": 15,
      "rotation": 5
    },
    {
      "x": -3,
      "y": 12,
      "z": -3,
      "name": "Wood_Softwood_Planks_Half"
    },
    {
      "x": -3,
      "y": 13,
      "z": -3,
      "name": "Empty"
    },
    {
      "x": -3,
      "y": 14,
      "z": -3,
      "name": "Empty"
    },
    {
      "x": -3,
      "y": 0,
      "z": -2,
      "name": "Wood_Drywood_Planks",
      "rotation": 1
    },
    {
      "x": -3,
      "y": 1,
      "z": -2,
      "name": "Bench_Cooking",
      "components": {
        "Components": {
          "BenchBlock": {
            "TierLevel": 1,
            "UpgradeItems": []
          },
          "PlacedByInteraction": {
            "WhoPlacedUuid": {
              "$binary": "QkYlqeXkSsiViUpcfcDqZA==",
              "$type": "04"
            }
          }
        }
      },
      "rotation": 1
    },
    {
      "x": -3,
      "y": 2,
      "z": -2,
      "name": "Bench_Cooking",
      "filler": 1024,
      "rotation": 1
    },
    {
      "x": -3,
      "y": 3,
      "z": -2,
      "name": "Wood_Softwood_Planks_Half",
      "rotation": 8
    },
    {
      "x": -3,
      "y": 4,
      "z": -2,
      "name": "Wood_Lightwood_Planks"
    },
    {
      "x": -3,
      "y": 5,
      "z": -2,
      "name": "Wood_Lightwood_Planks"
    },
    {
      "x": -3,
      "y": 6,
      "z": -2,
      "name": "Wood_Lightwood_Planks"
    },
    {
      "x": -3,
      "y": 7,
      "z": -2,
      "name": "Wood_Lightwood_Planks"
    },
    {
      "x": -3,
      "y": 8,
      "z": -2,
      "name": "Wood_Beech_Trunk",
      "support": 15,
      "rotation": 4
    },
    {
      "x": -3,
      "y": 9,
      "z": -2,
      "name": "Furniture_Village_Window",
      "rotation": 1
    },
    {
      "x": -3,
      "y": 10,
      "z": -2,
      "name": "Furniture_Village_Window",
      "rotation": 1
    },
    {
      "x": -3,
      "y": 11,
      "z": -2,
      "name": "*Wood_Redwood_Roof_State_Definitions_Inverted_Corner_Right"
    },
    {
      "x": -3,
      "y": 12,
      "z": -2,
      "name": "Empty"
    },
    {
      "x": -3,
      "y": 13,
      "z": -2,
      "name": "Empty"
    },
    {
      "x": -3,
      "y": 14,
      "z": -2,
      "name": "Empty"
    },
    {
      "x": -3,
      "y": 0,
      "z": -1,
      "name": "Wood_Drywood_Planks",
      "rotation": 1
    },
    {
      "x": -3,
      "y": 1,
      "z": -1,
      "name": "Bench_Cooking",
      "filler": 32,
      "rotation": 1
    },
    {
      "x": -3,
      "y": 2,
      "z": -1,
      "name": "Bench_Cooking",
      "filler": 1056,
      "rotation": 1
    },
    {
      "x": -3,
      "y": 3,
      "z": -1,
      "name": "Wood_Softwood_Planks_Half",
      "rotation": 8
    },
    {
      "x": -3,
      "y": 4,
      "z": -1,
      "name": "Wood_Lightwood_Planks"
    },
    {
      "x": -3,
      "y": 5,
      "z": -1,
      "name": "Wood_Lightwood_Planks"
    },
    {
      "x": -3,
      "y": 6,
      "z": -1,
      "name": "Wood_Lightwood_Planks"
    },
    {
      "x": -3,
      "y": 7,
      "z": -1,
      "name": "Wood_Lightwood_Planks"
    },
    {
      "x": -3,
      "y": 8,
      "z": -1,
      "name": "Wood_Beech_Trunk",
      "support": 15,
      "rotation": 4
    },
    {
      "x": -3,
      "y": 9,
      "z": -1,
      "name": "Wood_Lightwood_Planks"
    },
    {
      "x": -3,
      "y": 10,
      "z": -1,
      "name": "Wood_Lightwood_Planks"
    },
    {
      "x": -3,
      "y": 11,
      "z": -1,
      "name": "Wood_Redwood_Roof",
      "rotation": 3
    },
    {
      "x": -3,
      "y": 12,
      "z": -1,
      "name": "Empty"
    },
    {
      "x": -3,
      "y": 13,
      "z": -1,
      "name": "Empty"
    },
    {
      "x": -3,
      "y": 14,
      "z": -1,
      "name": "Empty"
    },
    {
      "x": -3,
      "y": 0,
      "z": 0,
      "name": "Rock_Stone_Cobble",
      "rotation": 1
    },
    {
      "x": -3,
      "y": 1,
      "z": 0,
      "name": "Rock_Stone_Brick",
      "rotation": 1
    },
    {
      "x": -3,
      "y": 2,
      "z": 0,
      "name": "Wood_Lightwood_Planks"
    },
    {
      "x": -3,
      "y": 3,
      "z": 0,
      "name": "Wood_Lightwood_Planks"
    },
    {
      "x": -3,
      "y": 4,
      "z": 0,
      "name": "Wood_Beech_Trunk",
      "support": 15,
      "rotation": 7
    },
    {
      "x": -3,
      "y": 5,
      "z": 0,
      "name": "Wood_Beech_Trunk",
      "support": 15
    },
    {
      "x": -3,
      "y": 6,
      "z": 0,
      "name": "Wood_Beech_Trunk",
      "support": 15
    },
    {
      "x": -3,
      "y": 7,
      "z": 0,
      "name": "Wood_Beech_Trunk",
      "support": 15
    },
    {
      "x": -3,
      "y": 8,
      "z": 0,
      "name": "Wood_Beech_Trunk",
      "support": 15
    },
    {
      "x": -3,
      "y": 9,
      "z": 0,
      "name": "Wood_Beech_Trunk",
      "support": 15
    },
    {
      "x": -3,
      "y": 10,
      "z": 0,
      "name": "Wood_Beech_Trunk",
      "support": 15
    },
    {
      "x": -3,
      "y": 11,
      "z": 0,
      "name": "Wood_Redwood_Roof",
      "rotation": 3
    },
    {
      "x": -3,
      "y": 12,
      "z": 0,
      "name": "Empty"
    },
    {
      "x": -3,
      "y": 13,
      "z": 0,
      "name": "Empty"
    },
    {
      "x": -3,
      "y": 14,
      "z": 0,
      "name": "Empty"
    },
    {
      "x": -3,
      "y": 0,
      "z": 1,
      "name": "Wood_Drywood_Planks"
    },
    {
      "x": -3,
      "y": 1,
      "z": 1,
      "name": "Empty"
    },
    {
      "x": -3,
      "y": 2,
      "z": 1,
      "name": "Empty"
    },
    {
      "x": -3,
      "y": 3,
      "z": 1,
      "name": "Empty"
    },
    {
      "x": -3,
      "y": 4,
      "z": 1,
      "name": "Empty"
    },
    {
      "x": -3,
      "y": 5,
      "z": 1,
      "name": "Wood_Softwood_Stairs",
      "rotation": 11
    },
    {
      "x": -3,
      "y": 6,
      "z": 1,
      "name": "Wood_Redwood_Roof",
      "rotation": 3
    },
    {
      "x": -3,
      "y": 7,
      "z": 1,
      "name": "Wood_Beech_Trunk",
      "support": 15,
      "rotation": 4
    },
    {
      "x": -3,
      "y": 8,
      "z": 1,
      "name": "Wood_Lightwood_Planks"
    },
    {
      "x": -3,
      "y": 9,
      "z": 1,
      "name": "Wood_Lightwood_Planks"
    },
    {
      "x": -3,
      "y": 10,
      "z": 1,
      "name": "Wood_Lightwood_Planks"
    },
    {
      "x": -3,
      "y": 11,
      "z": 1,
      "name": "Wood_Redwood_Roof",
      "rotation": 3
    },
    {
      "x": -3,
      "y": 12,
      "z": 1,
      "name": "Empty"
    },
    {
      "x": -3,
      "y": 13,
      "z": 1,
      "name": "Empty"
    },
    {
      "x": -3,
      "y": 14,
      "z": 1,
      "name": "Empty"
    },
    {
      "x": -3,
      "y": 0,
      "z": 2,
      "name": "Wood_Drywood_Planks"
    },
    {
      "x": -3,
      "y": 1,
      "z": 2,
      "name": "Furniture_Village_Chair"
    },
    {
      "x": -3,
      "y": 2,
      "z": 2,
      "name": "Furniture_Village_Chair",
      "filler": 1024
    },
    {
      "x": -3,
      "y": 3,
      "z": 2,
      "name": "Empty"
    },
    {
      "x": -3,
      "y": 4,
      "z": 2,
      "name": "Empty"
    },
    {
      "x": -3,
      "y": 5,
      "z": 2,
      "name": "Wood_Softwood_Stairs",
      "rotation": 11
    },
    {
      "x": -3,
      "y": 6,
      "z": 2,
      "name": "Wood_Redwood_Roof",
      "rotation": 3
    },
    {
      "x": -3,
      "y": 7,
      "z": 2,
      "name": "Wood_Beech_Trunk",
      "support": 15,
      "rotation": 4
    },
    {
      "x": -3,
      "y": 8,
      "z": 2,
      "name": "Wood_Lightwood_Planks"
    },
    {
      "x": -3,
      "y": 9,
      "z": 2,
      "name": "Furniture_Village_Window",
      "rotation": 1
    },
    {
      "x": -3,
      "y": 10,
      "z": 2,
      "name": "Furniture_Village_Window",
      "rotation": 1
    },
    {
      "x": -3,
      "y": 11,
      "z": 2,
      "name": "*Wood_Redwood_Roof_State_Definitions_Inverted_Corner_Right",
      "rotation": 3
    },
    {
      "x": -3,
      "y": 12,
      "z": 2,
      "name": "Empty"
    },
    {
      "x": -3,
      "y": 13,
      "z": 2,
      "name": "Empty"
    },
    {
      "x": -3,
      "y": 14,
      "z": 2,
      "name": "Empty"
    },
    {
      "x": -3,
      "y": 0,
      "z": 3,
      "name": "Wood_Drywood_Planks"
    },
    {
      "x": -3,
      "y": 1,
      "z": 3,
      "name": "Furniture_Village_Table",
      "filler": 1023,
      "rotation": 2
    },
    {
      "x": -3,
      "y": 2,
      "z": 3,
      "name": "Deco_Mug"
    },
    {
      "x": -3,
      "y": 3,
      "z": 3,
      "name": "Furniture_Village_Platform",
      "rotation": 1
    },
    {
      "x": -3,
      "y": 4,
      "z": 3,
      "name": "Empty"
    },
    {
      "x": -3,
      "y": 5,
      "z": 3,
      "name": "Wood_Softwood_Stairs",
      "rotation": 11
    },
    {
      "x": -3,
      "y": 6,
      "z": 3,
      "name": "Wood_Redwood_Roof",
      "rotation": 3
    },
    {
      "x": -3,
      "y": 7,
      "z": 3,
      "name": "Wood_Beech_Trunk",
      "support": 15,
      "rotation": 4
    },
    {
      "x": -3,
      "y": 8,
      "z": 3,
      "name": "Wood_Beech_Trunk",
      "support": 15
    },
    {
      "x": -3,
      "y": 9,
      "z": 3,
      "name": "Wood_Beech_Trunk",
      "support": 15
    },
    {
      "x": -3,
      "y": 10,
      "z": 3,
      "name": "Wood_Beech_Trunk",
      "support": 15
    },
    {
      "x": -3,
      "y": 11,
      "z": 3,
      "name": "Wood_Beech_Trunk",
      "support": 15
    },
    {
      "x": -3,
      "y": 12,
      "z": 3,
      "name": "Wood_Softwood_Planks_Half"
    },
    {
      "x": -3,
      "y": 13,
      "z": 3,
      "name": "Empty"
    },
    {
      "x": -3,
      "y": 14,
      "z": 3,
      "name": "Empty"
    },
    {
      "x": -3,
      "y": 0,
      "z": 4,
      "name": "Wood_Drywood_Planks"
    },
    {
      "x": -3,
      "y": 1,
      "z": 4,
      "name": "Furniture_Village_Table",
      "filler": 31,
      "rotation": 2
    },
    {
      "x": -3,
      "y": 2,
      "z": 4,
      "name": "Furniture_Crude_Candle"
    },
    {
      "x": -3,
      "y": 3,
      "z": 4,
      "name": "Furniture_Village_Platform",
      "rotation": 1
    },
    {
      "x": -3,
      "y": 4,
      "z": 4,
      "name": "Empty"
    },
    {
      "x": -3,
      "y": 5,
      "z": 4,
      "name": "Wood_Softwood_Stairs",
      "rotation": 11
    },
    {
      "x": -3,
      "y": 6,
      "z": 4,
      "name": "Wood_Redwood_Roof",
      "rotation": 3
    },
    {
      "x": -3,
      "y": 7,
      "z": 4,
      "name": "Wood_Beech_Trunk",
      "support": 15,
      "rotation": 4
    },
    {
      "x": -3,
      "y": 8,
      "z": 4,
      "name": "Wood_Lightwood_Planks"
    },
    {
      "x": -3,
      "y": 9,
      "z": 4,
      "name": "Furniture_Village_Window",
      "rotation": 1
    },
    {
      "x": -3,
      "y": 10,
      "z": 4,
      "name": "Furniture_Village_Window",
      "rotation": 1
    },
    {
      "x": -3,
      "y": 11,
      "z": 4,
      "name": "*Wood_Redwood_Roof_State_Definitions_Inverted_Corner_Left",
      "rotation": 3
    },
    {
      "x": -3,
      "y": 12,
      "z": 4,
      "name": "Empty"
    },
    {
      "x": -3,
      "y": 13,
      "z": 4,
      "name": "Empty"
    },
    {
      "x": -3,
      "y": 14,
      "z": 4,
      "name": "Empty"
    },
    {
      "x": -3,
      "y": 0,
      "z": 5,
      "name": "Wood_Drywood_Planks"
    },
    {
      "x": -3,
      "y": 1,
      "z": 5,
      "name": "Empty"
    },
    {
      "x": -3,
      "y": 2,
      "z": 5,
      "name": "Empty"
    },
    {
      "x": -3,
      "y": 3,
      "z": 5,
      "name": "Furniture_Village_Platform",
      "rotation": 1
    },
    {
      "x": -3,
      "y": 4,
      "z": 5,
      "name": "Container_Bucket"
    },
    {
      "x": -3,
      "y": 5,
      "z": 5,
      "name": "Wood_Softwood_Stairs",
      "rotation": 11
    },
    {
      "x": -3,
      "y": 6,
      "z": 5,
      "name": "Wood_Redwood_Roof",
      "rotation": 3
    },
    {
      "x": -3,
      "y": 7,
      "z": 5,
      "name": "Wood_Beech_Trunk",
      "support": 15,
      "rotation": 4
    },
    {
      "x": -3,
      "y": 8,
      "z": 5,
      "name": "Wood_Lightwood_Planks"
    },
    {
      "x": -3,
      "y": 9,
      "z": 5,
      "name": "Wood_Lightwood_Planks"
    },
    {
      "x": -3,
      "y": 10,
      "z": 5,
      "name": "Wood_Lightwood_Planks"
    },
    {
      "x": -3,
      "y": 11,
      "z": 5,
      "name": "Wood_Redwood_Roof",
      "rotation": 3
    },
    {
      "x": -3,
      "y": 12,
      "z": 5,
      "name": "Empty"
    },
    {
      "x": -3,
      "y": 13,
      "z": 5,
      "name": "Empty"
    },
    {
      "x": -3,
      "y": 14,
      "z": 5,
      "name": "Empty"
    },
    {
      "x": -3,
      "y": 0,
      "z": 6,
      "name": "Rock_Stone_Cobble"
    },
    {
      "x": -3,
      "y": 1,
      "z": 6,
      "name": "Rock_Stone_Brick"
    },
    {
      "x": -3,
      "y": 2,
      "z": 6,
      "name": "Rock_Stone_Cobble"
    },
    {
      "x": -3,
      "y": 3,
      "z": 6,
      "name": "Wood_Lightwood_Planks"
    },
    {
      "x": -3,
      "y": 4,
      "z": 6,
      "name": "Wood_Beech_Trunk",
      "support": 15,
      "rotation": 5
    },
    {
      "x": -3,
      "y": 5,
      "z": 6,
      "name": "Wood_Lightwood_Planks"
    },
    {
      "x": -3,
      "y": 6,
      "z": 6,
      "name": "Wood_Beech_Trunk",
      "support": 15
    },
    {
      "x": -3,
      "y": 7,
      "z": 6,
      "name": "Wood_Beech_Trunk",
      "support": 15
    },
    {
      "x": -3,
      "y": 8,
      "z": 6,
      "name": "Wood_Beech_Trunk",
      "support": 15
    },
    {
      "x": -3,
      "y": 9,
      "z": 6,
      "name": "Wood_Beech_Trunk",
      "support": 15
    },
    {
      "x": -3,
      "y": 10,
      "z": 6,
      "name": "Wood_Beech_Trunk",
      "support": 15
    },
    {
      "x": -3,
      "y": 11,
      "z": 6,
      "name": "*Wood_Redwood_Roof_State_Definitions_Corner_Left",
      "rotation": 3
    },
    {
      "x": -3,
      "y": 12,
      "z": 6,
      "name": "Empty"
    },
    {
      "x": -3,
      "y": 13,
      "z": 6,
      "name": "Empty"
    },
    {
      "x": -3,
      "y": 14,
      "z": 6,
      "name": "Empty"
    },
    {
      "x": -3,
      "y": 0,
      "z": 7,
      "name": "Rock_Stone_Cobble"
    },
    {
      "x": -3,
      "y": 1,
      "z": 7,
      "name": "Empty"
    },
    {
      "x": -3,
      "y": 2,
      "z": 7,
      "name": "Empty"
    },
    {
      "x": -3,
      "y": 3,
      "z": 7,
      "name": "Empty"
    },
    {
      "x": -3,
      "y": 4,
      "z": 7,
      "name": "Wood_Beech_Branch_Short",
      "support": 15
    },
    {
      "x": -3,
      "y": 5,
      "z": 7,
      "name": "Wood_Softwood_Planks_Half",
      "rotation": 8
    },
    {
      "x": -3,
      "y": 6,
      "z": 7,
      "name": "Wood_Redwood_Roof",
      "rotation": 3
    },
    {
      "x": -3,
      "y": 7,
      "z": 7,
      "name": "Wood_Beech_Branch_Short",
      "support": 15
    },
    {
      "x": -3,
      "y": 8,
      "z": 7,
      "name": "Empty"
    },
    {
      "x": -3,
      "y": 9,
      "z": 7,
      "name": "Wood_Beech_Branch_Corner",
      "support": 15
    },
    {
      "x": -3,
      "y": 10,
      "z": 7,
      "name": "*Wood_Redwood_Roof_State_Definitions_Inverted_Corner_Left",
      "rotation": 3
    },
    {
      "x": -3,
      "y": 11,
      "z": 7,
      "name": "Empty"
    },
    {
      "x": -3,
      "y": 12,
      "z": 7,
      "name": "Empty"
    },
    {
      "x": -3,
      "y": 13,
      "z": 7,
      "name": "Empty"
    },
    {
      "x": -3,
      "y": 14,
      "z": 7,
      "name": "Empty"
    },
    {
      "x": -2,
      "y": 0,
      "z": -7,
      "name": "Rock_Stone_Cobble",
      "rotation": 1
    },
    {
      "x": -2,
      "y": 1,
      "z": -7,
      "name": "Rock_Stone_Brick_Stairs",
      "rotation": 3
    },
    {
      "x": -2,
      "y": 2,
      "z": -7,
      "name": "Rock_Stone_Brick_Half",
      "rotation": 7
    },
    {
      "x": -2,
      "y": 3,
      "z": -7,
      "name": "Rock_Stone_Brick_Half",
      "rotation": 7
    },
    {
      "x": -2,
      "y": 4,
      "z": -7,
      "name": "Wood_Redwood_Roof_Hollow",
      "rotation": 2
    },
    {
      "x": -2,
      "y": 5,
      "z": -7,
      "name": "Empty"
    },
    {
      "x": -2,
      "y": 6,
      "z": -7,
      "name": "Empty"
    },
    {
      "x": -2,
      "y": 7,
      "z": -7,
      "name": "Empty"
    },
    {
      "x": -2,
      "y": 8,
      "z": -7,
      "name": "Empty"
    },
    {
      "x": -2,
      "y": 9,
      "z": -7,
      "name": "Empty"
    },
    {
      "x": -2,
      "y": 10,
      "z": -7,
      "name": "*Wood_Redwood_Roof_Hollow_State_Definitions_Inverted_Corner_Left",
      "rotation": 2
    },
    {
      "x": -2,
      "y": 11,
      "z": -7,
      "name": "Empty"
    },
    {
      "x": -2,
      "y": 12,
      "z": -7,
      "name": "Empty"
    },
    {
      "x": -2,
      "y": 13,
      "z": -7,
      "name": "Empty"
    },
    {
      "x": -2,
      "y": 14,
      "z": -7,
      "name": "Empty"
    },
    {
      "x": -2,
      "y": 0,
      "z": -6,
      "name": "Rock_Stone_Cobble",
      "rotation": 1
    },
    {
      "x": -2,
      "y": 1,
      "z": -6,
      "name": "Rock_Stone_Brick",
      "rotation": 1
    },
    {
      "x": -2,
      "y": 2,
      "z": -6,
      "name": "Rock_Stone_Brick",
      "rotation": 1
    },
    {
      "x": -2,
      "y": 3,
      "z": -6,
      "name": "Rock_Stone_Brick",
      "rotation": 1
    },
    {
      "x": -2,
      "y": 4,
      "z": -6,
      "name": "Rock_Stone_Brick",
      "rotation": 1
    },
    {
      "x": -2,
      "y": 5,
      "z": -6,
      "name": "Wood_Lightwood_Planks"
    },
    {
      "x": -2,
      "y": 6,
      "z": -6,
      "name": "Wood_Lightwood_Planks"
    },
    {
      "x": -2,
      "y": 7,
      "z": -6,
      "name": "Wood_Lightwood_Planks"
    },
    {
      "x": -2,
      "y": 8,
      "z": -6,
      "name": "Wood_Beech_Trunk",
      "support": 15,
      "rotation": 5
    },
    {
      "x": -2,
      "y": 9,
      "z": -6,
      "name": "Wood_Lightwood_Planks"
    },
    {
      "x": -2,
      "y": 10,
      "z": -6,
      "name": "Wood_Lightwood_Planks"
    },
    {
      "x": -2,
      "y": 11,
      "z": -6,
      "name": "Wood_Redwood_Roof",
      "rotation": 2
    },
    {
      "x": -2,
      "y": 12,
      "z": -6,
      "name": "Empty"
    },
    {
      "x": -2,
      "y": 13,
      "z": -6,
      "name": "Empty"
    },
    {
      "x": -2,
      "y": 14,
      "z": -6,
      "name": "Empty"
    },
    {
      "x": -2,
      "y": 0,
      "z": -5,
      "name": "Rock_Stone_Brick_Smooth",
      "rotation": 1
    },
    {
      "x": -2,
      "y": 1,
      "z": -5,
      "name": "Rock_Stone_Brick_Beam",
      "rotation": 1
    },
    {
      "x": -2,
      "y": 2,
      "z": -5,
      "name": "Rock_Stone_Brick_Beam",
      "rotation": 1
    },
    {
      "x": -2,
      "y": 3,
      "z": -5,
      "name": "Rock_Stone_Brick"
    },
    {
      "x": -2,
      "y": 4,
      "z": -5,
      "name": "Rock_Stone_Brick_Half",
      "rotation": 4
    },
    {
      "x": -2,
      "y": 5,
      "z": -5,
      "name": "Rock_Stone_Brick_Half",
      "rotation": 4
    },
    {
      "x": -2,
      "y": 6,
      "z": -5,
      "name": "Wood_Softwood_Planks"
    },
    {
      "x": -2,
      "y": 7,
      "z": -5,
      "name": "Empty"
    },
    {
      "x": -2,
      "y": 8,
      "z": -5,
      "name": "Empty"
    },
    {
      "x": -2,
      "y": 9,
      "z": -5,
      "name": "Empty"
    },
    {
      "x": -2,
      "y": 10,
      "z": -5,
      "name": "Empty"
    },
    {
      "x": -2,
      "y": 11,
      "z": -5,
      "name": "*Wood_Softwood_Stairs_State_Definitions_Inverted_Corner_Left",
      "rotation": 11
    },
    {
      "x": -2,
      "y": 12,
      "z": -5,
      "name": "*Wood_Redwood_Roof_State_Definitions_Corner_Right",
      "rotation": 3
    },
    {
      "x": -2,
      "y": 13,
      "z": -5,
      "name": "Empty"
    },
    {
      "x": -2,
      "y": 14,
      "z": -5,
      "name": "Empty"
    },
    {
      "x": -2,
      "y": 0,
      "z": -4,
      "name": "Wood_Drywood_Planks",
      "rotation": 1
    },
    {
      "x": -2,
      "y": 1,
      "z": -4,
      "name": "Empty"
    },
    {
      "x": -2,
      "y": 2,
      "z": -4,
      "name": "Empty"
    },
    {
      "x": -2,
      "y": 3,
      "z": -4,
      "name": "Furniture_Village_Platform"
    },
    {
      "x": -2,
      "y": 4,
      "z": -4,
      "name": "Empty"
    },
    {
      "x": -2,
      "y": 5,
      "z": -4,
      "name": "Wood_Softwood_Stairs",
      "rotation": 8
    },
    {
      "x": -2,
      "y": 6,
      "z": -4,
      "name": "Wood_Softwood_Stairs"
    },
    {
      "x": -2,
      "y": 7,
      "z": -4,
      "name": "Empty"
    },
    {
      "x": -2,
      "y": 8,
      "z": -4,
      "name": "Empty"
    },
    {
      "x": -2,
      "y": 9,
      "z": -4,
      "name": "Empty"
    },
    {
      "x": -2,
      "y": 10,
      "z": -4,
      "name": "Empty"
    },
    {
      "x": -2,
      "y": 11,
      "z": -4,
      "name": "Wood_Softwood_Stairs",
      "rotation": 11
    },
    {
      "x": -2,
      "y": 12,
      "z": -4,
      "name": "Wood_Redwood_Roof",
      "rotation": 3
    },
    {
      "x": -2,
      "y": 13,
      "z": -4,
      "name": "Empty"
    },
    {
      "x": -2,
      "y": 14,
      "z": -4,
      "name": "Empty"
    },
    {
      "x": -2,
      "y": 0,
      "z": -3,
      "name": "Wood_Drywood_Planks",
      "rotation": 1
    },
    {
      "x": -2,
      "y": 1,
      "z": -3,
      "name": "Empty"
    },
    {
      "x": -2,
      "y": 2,
      "z": -3,
      "name": "Empty"
    },
    {
      "x": -2,
      "y": 3,
      "z": -3,
      "name": "Furniture_Village_Platform"
    },
    {
      "x": -2,
      "y": 4,
      "z": -3,
      "name": "Wood_Softwood_Stairs",
      "rotation": 8
    },
    {
      "x": -2,
      "y": 5,
      "z": -3,
      "name": "Wood_Softwood_Stairs"
    },
    {
      "x": -2,
      "y": 6,
      "z": -3,
      "name": "Empty"
    },
    {
      "x": -2,
      "y": 7,
      "z": -3,
      "name": "Empty"
    },
    {
      "x": -2,
      "y": 8,
      "z": -3,
      "name": "Empty"
    },
    {
      "x": -2,
      "y": 9,
      "z": -3,
      "name": "Empty"
    },
    {
      "x": -2,
      "y": 10,
      "z": -3,
      "name": "Empty"
    },
    {
      "x": -2,
      "y": 11,
      "z": -3,
      "name": "Wood_Softwood_Stairs",
      "rotation": 11
    },
    {
      "x": -2,
      "y": 12,
      "z": -3,
      "name": "Wood_Softwood_Stairs",
      "rotation": 3
    },
    {
      "x": -2,
      "y": 13,
      "z": -3,
      "name": "Empty"
    },
    {
      "x": -2,
      "y": 14,
      "z": -3,
      "name": "Empty"
    },
    {
      "x": -2,
      "y": 0,
      "z": -2,
      "name": "Wood_Drywood_Planks",
      "rotation": 1
    },
    {
      "x": -2,
      "y": 1,
      "z": -2,
      "name": "Empty"
    },
    {
      "x": -2,
      "y": 2,
      "z": -2,
      "name": "Empty"
    },
    {
      "x": -2,
      "y": 3,
      "z": -2,
      "name": "Furniture_Village_Platform"
    },
    {
      "x": -2,
      "y": 4,
      "z": -2,
      "name": "Wood_Softwood_Stairs"
    },
    {
      "x": -2,
      "y": 5,
      "z": -2,
      "name": "Empty"
    },
    {
      "x": -2,
      "y": 6,
      "z": -2,
      "name": "Empty"
    },
    {
      "x": -2,
      "y": 7,
      "z": -2,
      "name": "Empty"
    },
    {
      "x": -2,
      "y": 8,
      "z": -2,
      "name": "Empty"
    },
    {
      "x": -2,
      "y": 9,
      "z": -2,
      "name": "Empty"
    },
    {
      "x": -2,
      "y": 10,
      "z": -2,
      "name": "Empty"
    },
    {
      "x": -2,
      "y": 11,
      "z": -2,
      "name": "Wood_Softwood_Stairs",
      "rotation": 11
    },
    {
      "x": -2,
      "y": 12,
      "z": -2,
      "name": "Wood_Redwood_Roof",
      "rotation": 3
    },
    {
      "x": -2,
      "y": 13,
      "z": -2,
      "name": "Empty"
    },
    {
      "x": -2,
      "y": 14,
      "z": -2,
      "name": "Empty"
    },
    {
      "x": -2,
      "y": 0,
      "z": -1,
      "name": "Wood_Drywood_Planks",
      "rotation": 1
    },
    {
      "x": -2,
      "y": 1,
      "z": -1,
      "name": "Ingredient_Spices",
      "rotation": 1
    },
    {
      "x": -2,
      "y": 2,
      "z": -1,
      "name": "Empty"
    },
    {
      "x": -2,
      "y": 3,
      "z": -1,
      "name": "Wood_Softwood_Planks_Half",
      "rotation": 8
    },
    {
      "x": -2,
      "y": 4,
      "z": -1,
      "name": "Empty"
    },
    {
      "x": -2,
      "y": 5,
      "z": -1,
      "name": "Empty"
    },
    {
      "x": -2,
      "y": 6,
      "z": -1,
      "name": "Empty"
    },
    {
      "x": -2,
      "y": 7,
      "z": -1,
      "name": "Empty"
    },
    {
      "x": -2,
      "y": 8,
      "z": -1,
      "name": "Empty"
    },
    {
      "x": -2,
      "y": 9,
      "z": -1,
      "name": "Empty"
    },
    {
      "x": -2,
      "y": 10,
      "z": -1,
      "name": "Empty"
    },
    {
      "x": -2,
      "y": 11,
      "z": -1,
      "name": "*Wood_Softwood_Stairs_State_Definitions_Inverted_Corner_Left",
      "rotation": 8
    },
    {
      "x": -2,
      "y": 12,
      "z": -1,
      "name": "*Wood_Redwood_Roof_State_Definitions_Corner_Left",
      "rotation": 3
    },
    {
      "x": -2,
      "y": 13,
      "z": -1,
      "name": "Empty"
    },
    {
      "x": -2,
      "y": 14,
      "z": -1,
      "name": "Empty"
    },
    {
      "x": -2,
      "y": 0,
      "z": 0,
      "name": "Rock_Stone_Cobble",
      "rotation": 1
    },
    {
      "x": -2,
      "y": 1,
      "z": 0,
      "name": "Rock_Stone_Brick",
      "rotation": 1
    },
    {
      "x": -2,
      "y": 2,
      "z": 0,
      "name": "Wood_Lightwood_Planks"
    },
    {
      "x": -2,
      "y": 3,
      "z": 0,
      "name": "Wood_Lightwood_Planks"
    },
    {
      "x": -2,
      "y": 4,
      "z": 0,
      "name": "Wood_Beech_Trunk",
      "support": 15,
      "rotation": 7
    },
    {
      "x": -2,
      "y": 5,
      "z": 0,
      "name": "Wood_Softwood_Planks"
    },
    {
      "x": -2,
      "y": 6,
      "z": 0,
      "name": "Wood_Softwood_Planks"
    },
    {
      "x": -2,
      "y": 7,
      "z": 0,
      "name": "Wood_Drywood_Planks"
    },
    {
      "x": -2,
      "y": 8,
      "z": 0,
      "name": "Wood_Lightwood_Planks"
    },
    {
      "x": -2,
      "y": 9,
      "z": 0,
      "name": "Wood_Lightwood_Planks"
    },
    {
      "x": -2,
      "y": 10,
      "z": 0,
      "name": "Wood_Lightwood_Planks"
    },
    {
      "x": -2,
      "y": 11,
      "z": 0,
      "name": "Wood_Softwood_Planks"
    },
    {
      "x": -2,
      "y": 12,
      "z": 0,
      "name": "Wood_Redwood_Roof_Flat",
      "rotation": 2
    },
    {
      "x": -2,
      "y": 13,
      "z": 0,
      "name": "Empty"
    },
    {
      "x": -2,
      "y": 14,
      "z": 0,
      "name": "Empty"
    },
    {
      "x": -2,
      "y": 0,
      "z": 1,
      "name": "Wood_Drywood_Planks"
    },
    {
      "x": -2,
      "y": 1,
      "z": 1,
      "name": "Empty"
    },
    {
      "x": -2,
      "y": 2,
      "z": 1,
      "name": "Empty"
    },
    {
      "x": -2,
      "y": 3,
      "z": 1,
      "name": "Empty"
    },
    {
      "x": -2,
      "y": 4,
      "z": 1,
      "name": "Empty"
    },
    {
      "x": -2,
      "y": 5,
      "z": 1,
      "name": "Empty"
    },
    {
      "x": -2,
      "y": 6,
      "z": 1,
      "name": "Wood_Softwood_Stairs",
      "rotation": 11
    },
    {
      "x": -2,
      "y": 7,
      "z": 1,
      "name": "Wood_Drywood_Planks"
    },
    {
      "x": -2,
      "y": 8,
      "z": 1,
      "name": "Furniture_Village_Counter",
      "rotation": 1
    },
    {
      "x": -2,
      "y": 9,
      "z": 1,
      "name": "Empty"
    },
    {
      "x": -2,
      "y": 10,
      "z": 1,
      "name": "Empty"
    },
    {
      "x": -2,
      "y": 11,
      "z": 1,
      "name": "*Wood_Softwood_Stairs_State_Definitions_Inverted_Corner_Right",
      "rotation": 10
    },
    {
      "x": -2,
      "y": 12,
      "z": 1,
      "name": "*Wood_Redwood_Roof_State_Definitions_Corner_Left",
      "rotation": 2
    },
    {
      "x": -2,
      "y": 13,
      "z": 1,
      "name": "Empty"
    },
    {
      "x": -2,
      "y": 14,
      "z": 1,
      "name": "Empty"
    },
    {
      "x": -2,
      "y": 0,
      "z": 2,
      "name": "Wood_Drywood_Planks"
    },
    {
      "x": -2,
      "y": 1,
      "z": 2,
      "name": "Empty"
    },
    {
      "x": -2,
      "y": 2,
      "z": 2,
      "name": "Empty"
    },
    {
      "x": -2,
      "y": 3,
      "z": 2,
      "name": "Empty"
    },
    {
      "x": -2,
      "y": 4,
      "z": 2,
      "name": "Empty"
    },
    {
      "x": -2,
      "y": 5,
      "z": 2,
      "name": "Empty"
    },
    {
      "x": -2,
      "y": 6,
      "z": 2,
      "name": "Wood_Softwood_Stairs",
      "rotation": 11
    },
    {
      "x": -2,
      "y": 7,
      "z": 2,
      "name": "Wood_Drywood_Planks"
    },
    {
      "x": -2,
      "y": 8,
      "z": 2,
      "name": "Furniture_Village_Counter",
      "filler": 32,
      "rotation": 1
    },
    {
      "x": -2,
      "y": 9,
      "z": 2,
      "name": "Furniture_Crude_Candle"
    },
    {
      "x": -2,
      "y": 10,
      "z": 2,
      "name": "Empty"
    },
    {
      "x": -2,
      "y": 11,
      "z": 2,
      "name": "Wood_Softwood_Stairs",
      "rotation": 11
    },
    {
      "x": -2,
      "y": 12,
      "z": 2,
      "name": "Wood_Redwood_Roof",
      "rotation": 3
    },
    {
      "x": -2,
      "y": 13,
      "z": 2,
      "name": "Empty"
    },
    {
      "x": -2,
      "y": 14,
      "z": 2,
      "name": "Empty"
    },
    {
      "x": -2,
      "y": 0,
      "z": 3,
      "name": "Wood_Drywood_Planks"
    },
    {
      "x": -2,
      "y": 1,
      "z": 3,
      "name": "Furniture_Village_Table",
      "filler": 992,
      "rotation": 2
    },
    {
      "x": -2,
      "y": 2,
      "z": 3,
      "name": "Empty"
    },
    {
      "x": -2,
      "y": 3,
      "z": 3,
      "name": "Furniture_Village_Platform",
      "rotation": 1
    },
    {
      "x": -2,
      "y": 4,
      "z": 3,
      "name": "Furniture_Lumberjack_Bed",
      "filler": 991,
      "rotation": 2
    },
    {
      "x": -2,
      "y": 5,
      "z": 3,
      "name": "Furniture_Lumberjack_Bed",
      "filler": 2015,
      "rotation": 2
    },
    {
      "x": -2,
      "y": 6,
      "z": 3,
      "name": "Wood_Softwood_Stairs",
      "rotation": 11
    },
    {
      "x": -2,
      "y": 7,
      "z": 3,
      "name": "Wood_Drywood_Planks"
    },
    {
      "x": -2,
      "y": 8,
      "z": 3,
      "name": "Furniture_Lumberjack_Bed",
      "filler": 991,
      "rotation": 2
    },
    {
      "x": -2,
      "y": 9,
      "z": 3,
      "name": "Furniture_Lumberjack_Bed",
      "filler": 2015,
      "rotation": 2
    },
    {
      "x": -2,
      "y": 10,
      "z": 3,
      "name": "Empty"
    },
    {
      "x": -2,
      "y": 11,
      "z": 3,
      "name": "Wood_Softwood_Stairs",
      "rotation": 11
    },
    {
      "x": -2,
      "y": 12,
      "z": 3,
      "name": "Wood_Softwood_Stairs",
      "rotation": 3
    },
    {
      "x": -2,
      "y": 13,
      "z": 3,
      "name": "Empty"
    },
    {
      "x": -2,
      "y": 14,
      "z": 3,
      "name": "Empty"
    },
    {
      "x": -2,
      "y": 0,
      "z": 4,
      "name": "Wood_Drywood_Planks"
    },
    {
      "x": -2,
      "y": 1,
      "z": 4,
      "name": "Furniture_Village_Table",
      "rotation": 2
    },
    {
      "x": -2,
      "y": 2,
      "z": 4,
      "name": "Empty"
    },
    {
      "x": -2,
      "y": 3,
      "z": 4,
      "name": "Furniture_Village_Platform",
      "rotation": 1
    },
    {
      "x": -2,
      "y": 4,
      "z": 4,
      "name": "Furniture_Lumberjack_Bed",
      "filler": 1023,
      "rotation": 2
    },
    {
      "x": -2,
      "y": 5,
      "z": 4,
      "name": "Furniture_Lumberjack_Bed",
      "filler": 2047,
      "rotation": 2
    },
    {
      "x": -2,
      "y": 6,
      "z": 4,
      "name": "Wood_Softwood_Stairs",
      "rotation": 11
    },
    {
      "x": -2,
      "y": 7,
      "z": 4,
      "name": "Wood_Drywood_Planks"
    },
    {
      "x": -2,
      "y": 8,
      "z": 4,
      "name": "Furniture_Lumberjack_Bed",
      "filler": 1023,
      "rotation": 2
    },
    {
      "x": -2,
      "y": 9,
      "z": 4,
      "name": "Furniture_Lumberjack_Bed",
      "filler": 2047,
      "rotation": 2
    },
    {
      "x": -2,
      "y": 10,
      "z": 4,
      "name": "Empty"
    },
    {
      "x": -2,
      "y": 11,
      "z": 4,
      "name": "Wood_Softwood_Stairs",
      "rotation": 11
    },
    {
      "x": -2,
      "y": 12,
      "z": 4,
      "name": "Wood_Redwood_Roof",
      "rotation": 3
    },
    {
      "x": -2,
      "y": 13,
      "z": 4,
      "name": "Empty"
    },
    {
      "x": -2,
      "y": 14,
      "z": 4,
      "name": "Empty"
    },
    {
      "x": -2,
      "y": 0,
      "z": 5,
      "name": "Wood_Drywood_Planks"
    },
    {
      "x": -2,
      "y": 1,
      "z": 5,
      "name": "Furniture_Village_Chair",
      "rotation": 2
    },
    {
      "x": -2,
      "y": 2,
      "z": 5,
      "name": "Furniture_Village_Chair",
      "filler": 1024,
      "rotation": 2
    },
    {
      "x": -2,
      "y": 3,
      "z": 5,
      "name": "Furniture_Village_Platform",
      "rotation": 1
    },
    {
      "x": -2,
      "y": 4,
      "z": 5,
      "name": "Furniture_Lumberjack_Bed",
      "filler": 31,
      "rotation": 2
    },
    {
      "x": -2,
      "y": 5,
      "z": 5,
      "name": "Furniture_Lumberjack_Bed",
      "filler": 1055,
      "rotation": 2
    },
    {
      "x": -2,
      "y": 6,
      "z": 5,
      "name": "Wood_Softwood_Stairs",
      "rotation": 11
    },
    {
      "x": -2,
      "y": 7,
      "z": 5,
      "name": "Wood_Drywood_Planks"
    },
    {
      "x": -2,
      "y": 8,
      "z": 5,
      "name": "Furniture_Lumberjack_Bed",
      "filler": 31,
      "rotation": 2
    },
    {
      "x": -2,
      "y": 9,
      "z": 5,
      "name": "Furniture_Lumberjack_Bed",
      "filler": 1055,
      "rotation": 2
    },
    {
      "x": -2,
      "y": 10,
      "z": 5,
      "name": "Empty"
    },
    {
      "x": -2,
      "y": 11,
      "z": 5,
      "name": "*Wood_Softwood_Stairs_State_Definitions_Inverted_Corner_Right",
      "rotation": 11
    },
    {
      "x": -2,
      "y": 12,
      "z": 5,
      "name": "*Wood_Redwood_Roof_State_Definitions_Corner_Left",
      "rotation": 3
    },
    {
      "x": -2,
      "y": 13,
      "z": 5,
      "name": "Empty"
    },
    {
      "x": -2,
      "y": 14,
      "z": 5,
      "name": "Empty"
    },
    {
      "x": -2,
      "y": 0,
      "z": 6,
      "name": "Rock_Stone_Cobble"
    },
    {
      "x": -2,
      "y": 1,
      "z": 6,
      "name": "Rock_Stone_Brick"
    },
    {
      "x": -2,
      "y": 2,
      "z": 6,
      "name": "Rock_Stone_Cobble"
    },
    {
      "x": -2,
      "y": 3,
      "z": 6,
      "name": "Wood_Lightwood_Planks"
    },
    {
      "x": -2,
      "y": 4,
      "z": 6,
      "name": "Wood_Beech_Trunk",
      "support": 15,
      "rotation": 5
    },
    {
      "x": -2,
      "y": 5,
      "z": 6,
      "name": "Wood_Lightwood_Planks"
    },
    {
      "x": -2,
      "y": 6,
      "z": 6,
      "name": "Wood_Lightwood_Planks"
    },
    {
      "x": -2,
      "y": 7,
      "z": 6,
      "name": "Wood_Beech_Trunk",
      "support": 15,
      "rotation": 5
    },
    {
      "x": -2,
      "y": 8,
      "z": 6,
      "name": "Wood_Lightwood_Planks"
    },
    {
      "x": -2,
      "y": 9,
      "z": 6,
      "name": "Wood_Lightwood_Planks"
    },
    {
      "x": -2,
      "y": 10,
      "z": 6,
      "name": "Wood_Lightwood_Planks"
    },
    {
      "x": -2,
      "y": 11,
      "z": 6,
      "name": "*Wood_Redwood_Roof_State_Definitions_Inverted_Corner_Right"
    },
    {
      "x": -2,
      "y": 12,
      "z": 6,
      "name": "Empty"
    },
    {
      "x": -2,
      "y": 13,
      "z": 6,
      "name": "Empty"
    },
    {
      "x": -2,
      "y": 14,
      "z": 6,
      "name": "Empty"
    },
    {
      "x": -2,
      "y": 0,
      "z": 7,
      "name": "Rock_Stone_Cobble"
    },
    {
      "x": -2,
      "y": 1,
      "z": 7,
      "name": "Empty"
    },
    {
      "x": -2,
      "y": 2,
      "z": 7,
      "name": "Empty"
    },
    {
      "x": -2,
      "y": 3,
      "z": 7,
      "name": "Plant_Vine_Wall",
      "support": 15
    },
    {
      "x": -2,
      "y": 4,
      "z": 7,
      "name": "Plant_Vine",
      "support": 15
    },
    {
      "x": -2,
      "y": 5,
      "z": 7,
      "name": "Empty"
    },
    {
      "x": -2,
      "y": 6,
      "z": 7,
      "name": "Wood_Softwood_Planks_Half",
      "rotation": 8
    },
    {
      "x": -2,
      "y": 7,
      "z": 7,
      "name": "Wood_Redwood_Roof",
      "rotation": 3
    },
    {
      "x": -2,
      "y": 8,
      "z": 7,
      "name": "Empty"
    },
    {
      "x": -2,
      "y": 9,
      "z": 7,
      "name": "Empty"
    },
    {
      "x": -2,
      "y": 10,
      "z": 7,
      "name": "Empty"
    },
    {
      "x": -2,
      "y": 11,
      "z": 7,
      "name": "Wood_Redwood_Roof_Hollow",
      "rotation": 3
    },
    {
      "x": -2,
      "y": 12,
      "z": 7,
      "name": "Empty"
    },
    {
      "x": -2,
      "y": 13,
      "z": 7,
      "name": "Empty"
    },
    {
      "x": -2,
      "y": 14,
      "z": 7,
      "name": "Empty"
    },
    {
      "x": -1,
      "y": 0,
      "z": -7,
      "name": "Rock_Stone_Cobble",
      "rotation": 1
    },
    {
      "x": -1,
      "y": 1,
      "z": -7,
      "name": "Rock_Stone_Brick",
      "rotation": 1
    },
    {
      "x": -1,
      "y": 2,
      "z": -7,
      "name": "Rock_Stone_Brick",
      "rotation": 1
    },
    {
      "x": -1,
      "y": 3,
      "z": -7,
      "name": "Rock_Stone_Brick",
      "rotation": 1
    },
    {
      "x": -1,
      "y": 4,
      "z": -7,
      "name": "Rock_Stone_Brick",
      "rotation": 1
    },
    {
      "x": -1,
      "y": 5,
      "z": -7,
      "name": "Rock_Stone_Brick_Stairs",
      "rotation": 2
    },
    {
      "x": -1,
      "y": 6,
      "z": -7,
      "name": "Rock_Stone_Brick_Half",
      "rotation": 6
    },
    {
      "x": -1,
      "y": 7,
      "z": -7,
      "name": "Rock_Stone_Brick_Half",
      "rotation": 6
    },
    {
      "x": -1,
      "y": 8,
      "z": -7,
      "name": "Rock_Stone_Brick_Half",
      "rotation": 6
    },
    {
      "x": -1,
      "y": 9,
      "z": -7,
      "name": "Rock_Stone_Brick_Half",
      "rotation": 6
    },
    {
      "x": -1,
      "y": 10,
      "z": -7,
      "name": "Rock_Stone_Brick_Half",
      "rotation": 6
    },
    {
      "x": -1,
      "y": 11,
      "z": -7,
      "name": "Wood_Redwood_Roof_Hollow",
      "rotation": 3
    },
    {
      "x": -1,
      "y": 12,
      "z": -7,
      "name": "Empty"
    },
    {
      "x": -1,
      "y": 13,
      "z": -7,
      "name": "Empty"
    },
    {
      "x": -1,
      "y": 14,
      "z": -7,
      "name": "Empty"
    },
    {
      "x": -1,
      "y": 0,
      "z": -6,
      "name": "Soil_Ash",
      "rotation": 1
    },
    {
      "x": -1,
      "y": 1,
      "z": -6,
      "name": "Furniture_Crude_Brazier",
      "rotation": 1
    },
    {
      "x": -1,
      "y": 2,
      "z": -6,
      "name": "Empty"
    },
    {
      "x": -1,
      "y": 3,
      "z": -6,
      "name": "Rock_Stone_Brick"
    },
    {
      "x": -1,
      "y": 4,
      "z": -6,
      "name": "Empty"
    },
    {
      "x": -1,
      "y": 5,
      "z": -6,
      "name": "Rock_Stone_Brick"
    },
    {
      "x": -1,
      "y": 6,
      "z": -6,
      "name": "Rock_Stone_Brick"
    },
    {
      "x": -1,
      "y": 7,
      "z": -6,
      "name": "Rock_Stone_Brick"
    },
    {
      "x": -1,
      "y": 8,
      "z": -6,
      "name": "Wood_Beech_Trunk",
      "support": 15,
      "rotation": 5
    },
    {
      "x": -1,
      "y": 9,
      "z": -6,
      "name": "Wood_Lightwood_Planks"
    },
    {
      "x": -1,
      "y": 10,
      "z": -6,
      "name": "Wood_Lightwood_Planks"
    },
    {
      "x": -1,
      "y": 11,
      "z": -6,
      "name": "Rock_Stone_Brick"
    },
    {
      "x": -1,
      "y": 12,
      "z": -6,
      "name": "Rock_Stone_Brick"
    },
    {
      "x": -1,
      "y": 13,
      "z": -6,
      "name": "Furniture_Village_Planter"
    },
    {
      "x": -1,
      "y": 14,
      "z": -6,
      "name": "Rock_Stone_Brick_Roof_Flat",
      "rotation": 1
    },
    {
      "x": -1,
      "y": 0,
      "z": -5,
      "name": "Rock_Stone_Brick_Smooth",
      "rotation": 1
    },
    {
      "x": -1,
      "y": 1,
      "z": -5,
      "name": "Empty"
    },
    {
      "x": -1,
      "y": 2,
      "z": -5,
      "name": "Empty"
    },
    {
      "x": -1,
      "y": 3,
      "z": -5,
      "name": "Rock_Stone_Brick"
    },
    {
      "x": -1,
      "y": 4,
      "z": -5,
      "name": "Rock_Stone_Brick_Half",
      "rotation": 4
    },
    {
      "x": -1,
      "y": 5,
      "z": -5,
      "name": "Rock_Stone_Brick_Half",
      "rotation": 4
    },
    {
      "x": -1,
      "y": 6,
      "z": -5,
      "name": "Empty"
    },
    {
      "x": -1,
      "y": 7,
      "z": -5,
      "name": "Wood_Softwood_Stairs",
      "rotation": 3
    },
    {
      "x": -1,
      "y": 8,
      "z": -5,
      "name": "Empty"
    },
    {
      "x": -1,
      "y": 9,
      "z": -5,
      "name": "Empty"
    },
    {
      "x": -1,
      "y": 10,
      "z": -5,
      "name": "Empty"
    },
    {
      "x": -1,
      "y": 11,
      "z": -5,
      "name": "Wood_Softwood_Stairs",
      "rotation": 10
    },
    {
      "x": -1,
      "y": 12,
      "z": -5,
      "name": "Wood_Redwood_Roof",
      "rotation": 2
    },
    {
      "x": -1,
      "y": 13,
      "z": -5,
      "name": "Empty"
    },
    {
      "x": -1,
      "y": 14,
      "z": -5,
      "name": "Empty"
    },
    {
      "x": -1,
      "y": 0,
      "z": -4,
      "name": "Wood_Drywood_Planks",
      "rotation": 1
    },
    {
      "x": -1,
      "y": 1,
      "z": -4,
      "name": "Empty"
    },
    {
      "x": -1,
      "y": 2,
      "z": -4,
      "name": "Empty"
    },
    {
      "x": -1,
      "y": 3,
      "z": -4,
      "name": "Furniture_Village_Platform"
    },
    {
      "x": -1,
      "y": 4,
      "z": -4,
      "name": "Furniture_Village_Counter",
      "filler": 31
    },
    {
      "x": -1,
      "y": 5,
      "z": -4,
      "name": "Furniture_Crude_Candle"
    },
    {
      "x": -1,
      "y": 6,
      "z": -4,
      "name": "Empty"
    },
    {
      "x": -1,
      "y": 7,
      "z": -4,
      "name": "Wood_Drywood_Planks"
    },
    {
      "x": -1,
      "y": 8,
      "z": -4,
      "name": "Empty"
    },
    {
      "x": -1,
      "y": 9,
      "z": -4,
      "name": "Empty"
    },
    {
      "x": -1,
      "y": 10,
      "z": -4,
      "name": "Empty"
    },
    {
      "x": -1,
      "y": 11,
      "z": -4,
      "name": "Empty"
    },
    {
      "x": -1,
      "y": 12,
      "z": -4,
      "name": "*Wood_Softwood_Stairs_State_Definitions_Inverted_Corner_Right",
      "rotation": 10
    },
    {
      "x": -1,
      "y": 13,
      "z": -4,
      "name": "*Wood_Redwood_Roof_State_Definitions_Corner_Right",
      "rotation": 3
    },
    {
      "x": -1,
      "y": 14,
      "z": -4,
      "name": "Empty"
    },
    {
      "x": -1,
      "y": 0,
      "z": -3,
      "name": "Wood_Drywood_Planks",
      "rotation": 1
    },
    {
      "x": -1,
      "y": 1,
      "z": -3,
      "name": "Empty"
    },
    {
      "x": -1,
      "y": 2,
      "z": -3,
      "name": "Empty"
    },
    {
      "x": -1,
      "y": 3,
      "z": -3,
      "name": "Furniture_Village_Platform"
    },
    {
      "x": -1,
      "y": 4,
      "z": -3,
      "name": "Empty"
    },
    {
      "x": -1,
      "y": 5,
      "z": -3,
      "name": "Empty"
    },
    {
      "x": -1,
      "y": 6,
      "z": -3,
      "name": "Empty"
    },
    {
      "x": -1,
      "y": 7,
      "z": -3,
      "name": "Wood_Drywood_Planks"
    },
    {
      "x": -1,
      "y": 8,
      "z": -3,
      "name": "Empty"
    },
    {
      "x": -1,
      "y": 9,
      "z": -3,
      "name": "Empty"
    },
    {
      "x": -1,
      "y": 10,
      "z": -3,
      "name": "Empty"
    },
    {
      "x": -1,
      "y": 11,
      "z": -3,
      "name": "Empty"
    },
    {
      "x": -1,
      "y": 12,
      "z": -3,
      "name": "Wood_Softwood_Stairs",
      "rotation": 11
    },
    {
      "x": -1,
      "y": 13,
      "z": -3,
      "name": "Wood_Softwood_Stairs",
      "rotation": 3
    },
    {
      "x": -1,
      "y": 14,
      "z": -3,
      "name": "Empty"
    },
    {
      "x": -1,
      "y": 0,
      "z": -2,
      "name": "Wood_Drywood_Planks",
      "rotation": 1
    },
    {
      "x": -1,
      "y": 1,
      "z": -2,
      "name": "Empty"
    },
    {
      "x": -1,
      "y": 2,
      "z": -2,
      "name": "Empty"
    },
    {
      "x": -1,
      "y": 3,
      "z": -2,
      "name": "Furniture_Village_Platform"
    },
    {
      "x": -1,
      "y": 4,
      "z": -2,
      "name": "Empty"
    },
    {
      "x": -1,
      "y": 5,
      "z": -2,
      "name": "Empty"
    },
    {
      "x": -1,
      "y": 6,
      "z": -2,
      "name": "Empty"
    },
    {
      "x": -1,
      "y": 7,
      "z": -2,
      "name": "Wood_Drywood_Planks"
    },
    {
      "x": -1,
      "y": 8,
      "z": -2,
      "name": "Empty"
    },
    {
      "x": -1,
      "y": 9,
      "z": -2,
      "name": "Empty"
    },
    {
      "x": -1,
      "y": 10,
      "z": -2,
      "name": "Empty"
    },
    {
      "x": -1,
      "y": 11,
      "z": -2,
      "name": "Empty"
    },
    {
      "x": -1,
      "y": 12,
      "z": -2,
      "name": "*Wood_Softwood_Stairs_State_Definitions_Inverted_Corner_Right",
      "rotation": 11
    },
    {
      "x": -1,
      "y": 13,
      "z": -2,
      "name": "*Wood_Redwood_Roof_State_Definitions_Corner_Right"
    },
    {
      "x": -1,
      "y": 14,
      "z": -2,
      "name": "Empty"
    },
    {
      "x": -1,
      "y": 0,
      "z": -1,
      "name": "Wood_Drywood_Planks",
      "rotation": 1
    },
    {
      "x": -1,
      "y": 1,
      "z": -1,
      "name": "*Furniture_Village_Door_State_Definitions_OpenDoorIn",
      "filler": 992,
      "rotation": 2
    },
    {
      "x": -1,
      "y": 2,
      "z": -1,
      "name": "*Furniture_Village_Door_State_Definitions_OpenDoorIn",
      "filler": 2016,
      "rotation": 2
    },
    {
      "x": -1,
      "y": 3,
      "z": -1,
      "name": "Wood_Softwood_Planks_Half",
      "rotation": 8
    },
    {
      "x": -1,
      "y": 4,
      "z": -1,
      "name": "Empty"
    },
    {
      "x": -1,
      "y": 5,
      "z": -1,
      "name": "Empty"
    },
    {
      "x": -1,
      "y": 6,
      "z": -1,
      "name": "Empty"
    },
    {
      "x": -1,
      "y": 7,
      "z": -1,
      "name": "Wood_Drywood_Planks"
    },
    {
      "x": -1,
      "y": 8,
      "z": -1,
      "name": "Empty"
    },
    {
      "x": -1,
      "y": 9,
      "z": -1,
      "name": "Empty"
    },
    {
      "x": -1,
      "y": 10,
      "z": -1,
      "name": "Empty"
    },
    {
      "x": -1,
      "y": 11,
      "z": -1,
      "name": "Wood_Softwood_Stairs",
      "rotation": 8
    },
    {
      "x": -1,
      "y": 12,
      "z": -1,
      "name": "Wood_Redwood_Roof"
    },
    {
      "x": -1,
      "y": 13,
      "z": -1,
      "name": "Empty"
    },
    {
      "x": -1,
      "y": 14,
      "z": -1,
      "name": "Empty"
    },
    {
      "x": -1,
      "y": 0,
      "z": 0,
      "name": "Rock_Stone_Cobble",
      "rotation": 1
    },
    {
      "x": -1,
      "y": 1,
      "z": 0,
      "name": "*Furniture_Village_Door_State_Definitions_OpenDoorIn",
      "rotation": 2
    },
    {
      "x": -1,
      "y": 2,
      "z": 0,
      "name": "*Furniture_Village_Door_State_Definitions_OpenDoorIn",
      "filler": 1024,
      "rotation": 2
    },
    {
      "x": -1,
      "y": 3,
      "z": 0,
      "name": "Wood_Lightwood_Planks"
    },
    {
      "x": -1,
      "y": 4,
      "z": 0,
      "name": "Wood_Beech_Trunk",
      "support": 15,
      "rotation": 7
    },
    {
      "x": -1,
      "y": 5,
      "z": 0,
      "name": "Wood_Softwood_Planks"
    },
    {
      "x": -1,
      "y": 6,
      "z": 0,
      "name": "Wood_Softwood_Planks"
    },
    {
      "x": -1,
      "y": 7,
      "z": 0,
      "name": "Wood_Drywood_Planks"
    },
    {
      "x": -1,
      "y": 8,
      "z": 0,
      "name": "Wood_Lightwood_Planks"
    },
    {
      "x": -1,
      "y": 9,
      "z": 0,
      "name": "Wood_Lightwood_Planks"
    },
    {
      "x": -1,
      "y": 10,
      "z": 0,
      "name": "Wood_Lightwood_Planks"
    },
    {
      "x": -1,
      "y": 11,
      "z": 0,
      "name": "Wood_Softwood_Planks"
    },
    {
      "x": -1,
      "y": 12,
      "z": 0,
      "name": "Wood_Softwood_Planks_Half"
    },
    {
      "x": -1,
      "y": 13,
      "z": 0,
      "name": "Empty"
    },
    {
      "x": -1,
      "y": 14,
      "z": 0,
      "name": "Empty"
    },
    {
      "x": -1,
      "y": 0,
      "z": 1,
      "name": "Wood_Drywood_Planks"
    },
    {
      "x": -1,
      "y": 1,
      "z": 1,
      "name": "Empty"
    },
    {
      "x": -1,
      "y": 2,
      "z": 1,
      "name": "Empty"
    },
    {
      "x": -1,
      "y": 3,
      "z": 1,
      "name": "Empty"
    },
    {
      "x": -1,
      "y": 4,
      "z": 1,
      "name": "Empty"
    },
    {
      "x": -1,
      "y": 5,
      "z": 1,
      "name": "Empty"
    },
    {
      "x": -1,
      "y": 6,
      "z": 1,
      "name": "Empty"
    },
    {
      "x": -1,
      "y": 7,
      "z": 1,
      "name": "Wood_Drywood_Planks"
    },
    {
      "x": -1,
      "y": 8,
      "z": 1,
      "name": "Furniture_Village_Chair",
      "rotation": 3
    },
    {
      "x": -1,
      "y": 9,
      "z": 1,
