{
  "version": 8,
  "blockIdVersion": 11,
  "anchorX": 0,
  "anchorY": 0,
  "anchorZ": 0,
  "blocks": [
    {
      "x": -9,
      "y": 0,
      "z": -11,
      "name": "Rock_Stone"
    },
    {
      "x": -9,
      "y": 1,
      "z": -11,
      "name": "Soil_Dirt"
    },
    {
      "x": -9,
      "y": 2,
      "z": -11,
      "name": "Soil_Dirt"
    },
    {
      "x": -9,
      "y": 3,
      "z": -11,
      "name": "Soil_Dirt"
    },
    {
      "x": -9,
      "y": 4,
      "z": -11,
      "name": "Soil_Grass"
    },
    {
      "x": -9,
      "y": 5,
      "z": -11,
      "name": "Empty"
    },
    {
      "x": -9,
      "y": 6,
      "z": -11,
      "name": "Empty"
    },
    {
      "x": -9,
      "y": 7,
      "z": -11,
      "name": "Empty"
    },
    {
      "x": -9,
      "y": 8,
      "z": -11,
      "name": "Empty"
    },
    {
      "x": -9,
      "y": 9,
      "z": -11,
      "name": "Empty"
    },
    {
      "x": -9,
      "y": 10,
      "z": -11,
      "name": "Empty"
    },
    {
      "x": -9,
      "y": 11,
      "z": -11,
      "name": "Empty"
    },
    {
      "x": -9,
      "y": 12,
      "z": -11,
      "name": "Empty"
    },
    {
      "x": -9,
      "y": 0,
      "z": -10,
      "name": "Rock_Stone"
    },
    {
      "x": -9,
      "y": 1,
      "z": -10,
      "name": "Soil_Dirt"
    },
    {
      "x": -9,
      "y": 2,
      "z": -10,
      "name": "Soil_Dirt"
    },
    {
      "x": -9,
      "y": 3,
      "z": -10,
      "name": "Soil_Dirt"
    },
    {
      "x": -9,
      "y": 4,
      "z": -10,
      "name": "Soil_Grass"
    },
    {
      "x": -9,
      "y": 5,
      "z": -10,
      "name": "Empty"
    },
    {
      "x": -9,
      "y": 6,
      "z": -10,
      "name": "Empty"
    },
    {
      "x": -9,
      "y": 7,
      "z": -10,
      "name": "Empty"
    },
    {
      "x": -9,
      "y": 8,
      "z": -10,
      "name": "Empty"
    },
    {
      "x": -9,
      "y": 9,
      "z": -10,
      "name": "Empty"
    },
    {
      "x": -9,
      "y": 10,
      "z": -10,
      "name": "Empty"
    },
    {
      "x": -9,
      "y": 11,
      "z": -10,
      "name": "Empty"
    },
    {
      "x": -9,
      "y": 12,
      "z": -10,
      "name": "Empty"
    },
    {
      "x": -9,
      "y": 0,
      "z": -9,
      "name": "Rock_Stone"
    },
    {
      "x": -9,
      "y": 1,
      "z": -9,
      "name": "Soil_Dirt"
    },
    {
      "x": -9,
      "y": 2,
      "z": -9,
      "name": "Soil_Dirt"
    },
    {
      "x": -9,
      "y": 3,
      "z": -9,
      "name": "Soil_Dirt"
    },
    {
      "x": -9,
      "y": 4,
      "z": -9,
      "name": "Soil_Grass"
    },
    {
      "x": -9,
      "y": 5,
      "z": -9,
      "name": "Empty"
    },
    {
      "x": -9,
      "y": 6,
      "z": -9,
      "name": "Empty"
    },
    {
      "x": -9,
      "y": 7,
      "z": -9,
      "name": "Empty"
    },
    {
      "x": -9,
      "y": 8,
      "z": -9,
      "name": "Empty"
    },
    {
      "x": -9,
      "y": 9,
      "z": -9,
      "name": "Empty"
    },
    {
      "x": -9,
      "y": 10,
      "z": -9,
      "name": "Empty"
    },
    {
      "x": -9,
      "y": 11,
      "z": -9,
      "name": "Empty"
    },
    {
      "x": -9,
      "y": 12,
      "z": -9,
      "name": "Empty"
    },
    {
      "x": -9,
      "y": 0,
      "z": -8,
      "name": "Rock_Stone"
    },
    {
      "x": -9,
      "y": 1,
      "z": -8,
      "name": "Soil_Dirt"
    },
    {
      "x": -9,
      "y": 2,
      "z": -8,
      "name": "Soil_Dirt"
    },
    {
      "x": -9,
      "y": 3,
      "z": -8,
      "name": "Soil_Dirt"
    },
    {
      "x": -9,
      "y": 4,
      "z": -8,
      "name": "Rock_Stone_Cobble"
    },
    {
      "x": -9,
      "y": 5,
      "z": -8,
      "name": "Empty"
    },
    {
      "x": -9,
      "y": 6,
      "z": -8,
      "name": "Empty"
    },
    {
      "x": -9,
      "y": 7,
      "z": -8,
      "name": "Empty"
    },
    {
      "x": -9,
      "y": 8,
      "z": -8,
      "name": "Wood_Hardwood_Roof",
      "rotation": 2
    },
    {
      "x": -9,
      "y": 9,
      "z": -8,
      "name": "Empty"
    },
    {
      "x": -9,
      "y": 10,
      "z": -8,
      "name": "Empty"
    },
    {
      "x": -9,
      "y": 11,
      "z": -8,
      "name": "Empty"
    },
    {
      "x": -9,
      "y": 12,
      "z": -8,
      "name": "Empty"
    },
    {
      "x": -9,
      "y": 0,
      "z": -7,
      "name": "Rock_Stone"
    },
    {
      "x": -9,
      "y": 1,
      "z": -7,
      "name": "Soil_Dirt"
    },
    {
      "x": -9,
      "y": 2,
      "z": -7,
      "name": "Soil_Dirt"
    },
    {
      "x": -9,
      "y": 3,
      "z": -7,
      "name": "Soil_Dirt"
    },
    {
      "x": -9,
      "y": 4,
      "z": -7,
      "name": "Rock_Stone_Cobble"
    },
    {
      "x": -9,
      "y": 5,
      "z": -7,
      "name": "Empty"
    },
    {
      "x": -9,
      "y": 6,
      "z": -7,
      "name": "Empty"
    },
    {
      "x": -9,
      "y": 7,
      "z": -7,
      "name": "Empty"
    },
    {
      "x": -9,
      "y": 8,
      "z": -7,
      "name": "Wood_Beech_Branch_Corner",
      "support": 15,
      "rotation": 3
    },
    {
      "x": -9,
      "y": 9,
      "z": -7,
      "name": "Wood_Hardwood_Roof",
      "rotation": 2
    },
    {
      "x": -9,
      "y": 10,
      "z": -7,
      "name": "Empty"
    },
    {
      "x": -9,
      "y": 11,
      "z": -7,
      "name": "Empty"
    },
    {
      "x": -9,
      "y": 12,
      "z": -7,
      "name": "Empty"
    },
    {
      "x": -9,
      "y": 0,
      "z": -6,
      "name": "Rock_Stone"
    },
    {
      "x": -9,
      "y": 1,
      "z": -6,
      "name": "Soil_Dirt"
    },
    {
      "x": -9,
      "y": 2,
      "z": -6,
      "name": "Soil_Dirt"
    },
    {
      "x": -9,
      "y": 3,
      "z": -6,
      "name": "Soil_Dirt"
    },
    {
      "x": -9,
      "y": 4,
      "z": -6,
      "name": "Rock_Stone_Cobble"
    },
    {
      "x": -9,
      "y": 5,
      "z": -6,
      "name": "Empty"
    },
    {
      "x": -9,
      "y": 6,
      "z": -6,
      "name": "Empty"
    },
    {
      "x": -9,
      "y": 7,
      "z": -6,
      "name": "Empty"
    },
    {
      "x": -9,
      "y": 8,
      "z": -6,
      "name": "Wood_Beech_Branch_Short",
      "support": 15,
      "rotation": 3
    },
    {
      "x": -9,
      "y": 9,
      "z": -6,
      "name": "Wood_Beech_Branch_Corner",
      "support": 15,
      "rotation": 3
    },
    {
      "x": -9,
      "y": 10,
      "z": -6,
      "name": "Wood_Hardwood_Roof",
      "rotation": 2
    },
    {
      "x": -9,
      "y": 11,
      "z": -6,
      "name": "Empty"
    },
    {
      "x": -9,
      "y": 12,
      "z": -6,
      "name": "Empty"
    },
    {
      "x": -9,
      "y": 0,
      "z": -5,
      "name": "Rock_Stone"
    },
    {
      "x": -9,
      "y": 1,
      "z": -5,
      "name": "Soil_Dirt"
    },
    {
      "x": -9,
      "y": 2,
      "z": -5,
      "name": "Soil_Dirt"
    },
    {
      "x": -9,
      "y": 3,
      "z": -5,
      "name": "Soil_Dirt"
    },
    {
      "x": -9,
      "y": 4,
      "z": -5,
      "name": "Rock_Stone_Cobble"
    },
    {
      "x": -9,
      "y": 5,
      "z": -5,
      "name": "Empty"
    },
    {
      "x": -9,
      "y": 6,
      "z": -5,
      "name": "Empty"
    },
    {
      "x": -9,
      "y": 7,
      "z": -5,
      "name": "Empty"
    },
    {
      "x": -9,
      "y": 8,
      "z": -5,
      "name": "Empty"
    },
    {
      "x": -9,
      "y": 9,
      "z": -5,
      "name": "Empty"
    },
    {
      "x": -9,
      "y": 10,
      "z": -5,
      "name": "Wood_Beech_Branch_Corner",
      "support": 15,
      "rotation": 3
    },
    {
      "x": -9,
      "y": 11,
      "z": -5,
      "name": "Wood_Hardwood_Roof",
      "rotation": 2
    },
    {
      "x": -9,
      "y": 12,
      "z": -5,
      "name": "Empty"
    },
    {
      "x": -9,
      "y": 0,
      "z": -4,
      "name": "Rock_Stone"
    },
    {
      "x": -9,
      "y": 1,
      "z": -4,
      "name": "Soil_Dirt"
    },
    {
      "x": -9,
      "y": 2,
      "z": -4,
      "name": "Soil_Dirt"
    },
    {
      "x": -9,
      "y": 3,
      "z": -4,
      "name": "Soil_Dirt"
    },
    {
      "x": -9,
      "y": 4,
      "z": -4,
      "name": "Rock_Stone_Cobble"
    },
    {
      "x": -9,
      "y": 5,
      "z": -4,
      "name": "Wood_Softwood_Beam"
    },
    {
      "x": -9,
      "y": 6,
      "z": -4,
      "name": "Wood_Softwood_Beam"
    },
    {
      "x": -9,
      "y": 7,
      "z": -4,
      "name": "*Wood_Hardwood_Roof_State_Definitions_Corner_Left",
      "rotation": 2
    },
    {
      "x": -9,
      "y": 8,
      "z": -4,
      "name": "Wood_Beech_Branch_Short",
      "support": 15,
      "rotation": 3
    },
    {
      "x": -9,
      "y": 9,
      "z": -4,
      "name": "Empty"
    },
    {
      "x": -9,
      "y": 10,
      "z": -4,
      "name": "Empty"
    },
    {
      "x": -9,
      "y": 11,
      "z": -4,
      "name": "Wood_Beech_Branch_Corner",
      "support": 15,
      "rotation": 3
    },
    {
      "x": -9,
      "y": 12,
      "z": -4,
      "name": "Wood_Hardwood_Roof_Flat",
      "rotation": 3
    },
    {
      "x": -9,
      "y": 0,
      "z": -3,
      "name": "Rock_Stone"
    },
    {
      "x": -9,
      "y": 1,
      "z": -3,
      "name": "Soil_Dirt"
    },
    {
      "x": -9,
      "y": 2,
      "z": -3,
      "name": "Soil_Dirt"
    },
    {
      "x": -9,
      "y": 3,
      "z": -3,
      "name": "Soil_Dirt"
    },
    {
      "x": -9,
      "y": 4,
      "z": -3,
      "name": "Rock_Stone_Cobble"
    },
    {
      "x": -9,
      "y": 5,
      "z": -3,
      "name": "Empty"
    },
    {
      "x": -9,
      "y": 6,
      "z": -3,
      "name": "Empty"
    },
    {
      "x": -9,
      "y": 7,
      "z": -3,
      "name": "Wood_Hardwood_Roof_Hollow",
      "rotation": 3
    },
    {
      "x": -9,
      "y": 8,
      "z": -3,
      "name": "Empty"
    },
    {
      "x": -9,
      "y": 9,
      "z": -3,
      "name": "Empty"
    },
    {
      "x": -9,
      "y": 10,
      "z": -3,
      "name": "Wood_Beech_Branch_Corner",
      "support": 15,
      "rotation": 3
    },
    {
      "x": -9,
      "y": 11,
      "z": -3,
      "name": "Wood_Beech_Trunk",
      "support": 15,
      "rotation": 5
    },
    {
      "x": -9,
      "y": 12,
      "z": -3,
      "name": "Wood_Hardwood_Roof_Flat",
      "rotation": 3
    },
    {
      "x": -9,
      "y": 0,
      "z": -2,
      "name": "Rock_Stone"
    },
    {
      "x": -9,
      "y": 1,
      "z": -2,
      "name": "Soil_Dirt"
    },
    {
      "x": -9,
      "y": 2,
      "z": -2,
      "name": "Soil_Dirt"
    },
    {
      "x": -9,
      "y": 3,
      "z": -2,
      "name": "Soil_Dirt"
    },
    {
      "x": -9,
      "y": 4,
      "z": -2,
      "name": "Rock_Stone_Cobble"
    },
    {
      "x": -9,
      "y": 5,
      "z": -2,
      "name": "Wood_Softwood_Beam"
    },
    {
      "x": -9,
      "y": 6,
      "z": -2,
      "name": "Wood_Softwood_Beam"
    },
    {
      "x": -9,
      "y": 7,
      "z": -2,
      "name": "*Wood_Hardwood_Roof_State_Definitions_Corner_Right"
    },
    {
      "x": -9,
      "y": 8,
      "z": -2,
      "name": "Wood_Beech_Branch_Short",
      "support": 15,
      "rotation": 3
    },
    {
      "x": -9,
      "y": 9,
      "z": -2,
      "name": "Empty"
    },
    {
      "x": -9,
      "y": 10,
      "z": -2,
      "name": "Empty"
    },
    {
      "x": -9,
      "y": 11,
      "z": -2,
      "name": "Empty"
    },
    {
      "x": -9,
      "y": 12,
      "z": -2,
      "name": "Wood_Hardwood_Roof_Flat",
      "rotation": 3
    },
    {
      "x": -9,
      "y": 0,
      "z": -1,
      "name": "Rock_Stone"
    },
    {
      "x": -9,
      "y": 1,
      "z": -1,
      "name": "Soil_Dirt"
    },
    {
      "x": -9,
      "y": 2,
      "z": -1,
      "name": "Soil_Dirt"
    },
    {
      "x": -9,
      "y": 3,
      "z": -1,
      "name": "Soil_Dirt"
    },
    {
      "x": -9,
      "y": 4,
      "z": -1,
      "name": "Rock_Stone_Cobble"
    },
    {
      "x": -9,
      "y": 5,
      "z": -1,
      "name": "Empty"
    },
    {
      "x": -9,
      "y": 6,
      "z": -1,
      "name": "Empty"
    },
    {
      "x": -9,
      "y": 7,
      "z": -1,
      "name": "Empty"
    },
    {
      "x": -9,
      "y": 8,
      "z": -1,
      "name": "Empty"
    },
    {
      "x": -9,
      "y": 9,
      "z": -1,
      "name": "Empty"
    },
    {
      "x": -9,
      "y": 10,
      "z": -1,
      "name": "Wood_Beech_Branch_Corner",
      "support": 15,
      "rotation": 3
    },
    {
      "x": -9,
      "y": 11,
      "z": -1,
      "name": "Wood_Hardwood_Roof"
    },
    {
      "x": -9,
      "y": 12,
      "z": -1,
      "name": "Empty"
    },
    {
      "x": -9,
      "y": 0,
      "z": 0,
      "name": "Rock_Stone"
    },
    {
      "x": -9,
      "y": 1,
      "z": 0,
      "name": "Soil_Dirt"
    },
    {
      "x": -9,
      "y": 2,
      "z": 0,
      "name": "Soil_Dirt"
    },
    {
      "x": -9,
      "y": 3,
      "z": 0,
      "name": "Soil_Dirt"
    },
    {
      "x": -9,
      "y": 4,
      "z": 0,
      "name": "Rock_Stone_Cobble"
    },
    {
      "x": -9,
      "y": 5,
      "z": 0,
      "name": "Empty"
    },
    {
      "x": -9,
      "y": 6,
      "z": 0,
      "name": "Empty"
    },
    {
      "x": -9,
      "y": 7,
      "z": 0,
      "name": "Empty"
    },
    {
      "x": -9,
      "y": 8,
      "z": 0,
      "name": "Wood_Beech_Branch_Short",
      "support": 15,
      "rotation": 3
    },
    {
      "x": -9,
      "y": 9,
      "z": 0,
      "name": "Wood_Beech_Branch_Corner",
      "support": 15,
      "rotation": 3
    },
    {
      "x": -9,
      "y": 10,
      "z": 0,
      "name": "Wood_Hardwood_Roof"
    },
    {
      "x": -9,
      "y": 11,
      "z": 0,
      "name": "Empty"
    },
    {
      "x": -9,
      "y": 12,
      "z": 0,
      "name": "Empty"
    },
    {
      "x": -9,
      "y": 0,
      "z": 1,
      "name": "Rock_Stone"
    },
    {
      "x": -9,
      "y": 1,
      "z": 1,
      "name": "Soil_Dirt"
    },
    {
      "x": -9,
      "y": 2,
      "z": 1,
      "name": "Soil_Dirt"
    },
    {
      "x": -9,
      "y": 3,
      "z": 1,
      "name": "Soil_Dirt"
    },
    {
      "x": -9,
      "y": 4,
      "z": 1,
      "name": "Rock_Stone_Cobble"
    },
    {
      "x": -9,
      "y": 5,
      "z": 1,
      "name": "Empty"
    },
    {
      "x": -9,
      "y": 6,
      "z": 1,
      "name": "Empty"
    },
    {
      "x": -9,
      "y": 7,
      "z": 1,
      "name": "Empty"
    },
    {
      "x": -9,
      "y": 8,
      "z": 1,
      "name": "Wood_Beech_Branch_Corner",
      "support": 15,
      "rotation": 3
    },
    {
      "x": -9,
      "y": 9,
      "z": 1,
      "name": "Wood_Hardwood_Roof"
    },
    {
      "x": -9,
      "y": 10,
      "z": 1,
      "name": "Empty"
    },
    {
      "x": -9,
      "y": 11,
      "z": 1,
      "name": "Empty"
    },
    {
      "x": -9,
      "y": 12,
      "z": 1,
      "name": "Empty"
    },
    {
      "x": -9,
      "y": 0,
      "z": 2,
      "name": "Rock_Stone"
    },
    {
      "x": -9,
      "y": 1,
      "z": 2,
      "name": "Soil_Dirt"
    },
    {
      "x": -9,
      "y": 2,
      "z": 2,
      "name": "Soil_Dirt"
    },
    {
      "x": -9,
      "y": 3,
      "z": 2,
      "name": "Soil_Dirt"
    },
    {
      "x": -9,
      "y": 4,
      "z": 2,
      "name": "Rock_Stone_Cobble"
    },
    {
      "x": -9,
      "y": 5,
      "z": 2,
      "name": "Empty"
    },
    {
      "x": -9,
      "y": 6,
      "z": 2,
      "name": "Empty"
    },
    {
      "x": -9,
      "y": 7,
      "z": 2,
      "name": "Empty"
    },
    {
      "x": -9,
      "y": 8,
      "z": 2,
      "name": "Wood_Hardwood_Roof"
    },
    {
      "x": -9,
      "y": 9,
      "z": 2,
      "name": "Empty"
    },
    {
      "x": -9,
      "y": 10,
      "z": 2,
      "name": "Empty"
    },
    {
      "x": -9,
      "y": 11,
      "z": 2,
      "name": "Empty"
    },
    {
      "x": -9,
      "y": 12,
      "z": 2,
      "name": "Empty"
    },
    {
      "x": -9,
      "y": 0,
      "z": 3,
      "name": "Rock_Stone"
    },
    {
      "x": -9,
      "y": 1,
      "z": 3,
      "name": "Soil_Dirt"
    },
    {
      "x": -9,
      "y": 2,
      "z": 3,
      "name": "Soil_Dirt"
    },
    {
      "x": -9,
      "y": 3,
      "z": 3,
      "name": "Soil_Dirt"
    },
    {
      "x": -9,
      "y": 4,
      "z": 3,
      "name": "Soil_Grass"
    },
    {
      "x": -9,
      "y": 5,
      "z": 3,
      "name": "Empty"
    },
    {
      "x": -9,
      "y": 6,
      "z": 3,
      "name": "Empty"
    },
    {
      "x": -9,
      "y": 7,
      "z": 3,
      "name": "Empty"
    },
    {
      "x": -9,
      "y": 8,
      "z": 3,
      "name": "Empty"
    },
    {
      "x": -9,
      "y": 9,
      "z": 3,
      "name": "Empty"
    },
    {
      "x": -9,
      "y": 10,
      "z": 3,
      "name": "Empty"
    },
    {
      "x": -9,
      "y": 11,
      "z": 3,
      "name": "Empty"
    },
    {
      "x": -9,
      "y": 12,
      "z": 3,
      "name": "Empty"
    },
    {
      "x": -9,
      "y": 0,
      "z": 4,
      "name": "Rock_Stone"
    },
    {
      "x": -9,
      "y": 1,
      "z": 4,
      "name": "Soil_Dirt"
    },
    {
      "x": -9,
      "y": 2,
      "z": 4,
      "name": "Soil_Dirt"
    },
    {
      "x": -9,
      "y": 3,
      "z": 4,
      "name": "Soil_Dirt"
    },
    {
      "x": -9,
      "y": 4,
      "z": 4,
      "name": "Soil_Grass"
    },
    {
      "x": -9,
      "y": 5,
      "z": 4,
      "name": "Empty"
    },
    {
      "x": -9,
      "y": 6,
      "z": 4,
      "name": "Empty"
    },
    {
      "x": -9,
      "y": 7,
      "z": 4,
      "name": "Empty"
    },
    {
      "x": -9,
      "y": 8,
      "z": 4,
      "name": "Empty"
    },
    {
      "x": -9,
      "y": 9,
      "z": 4,
      "name": "Empty"
    },
    {
      "x": -9,
      "y": 10,
      "z": 4,
      "name": "Empty"
    },
    {
      "x": -9,
      "y": 11,
      "z": 4,
      "name": "Empty"
    },
    {
      "x": -9,
      "y": 12,
      "z": 4,
      "name": "Empty"
    },
    {
      "x": -9,
      "y": 0,
      "z": 5,
      "name": "Rock_Stone"
    },
    {
      "x": -9,
      "y": 1,
      "z": 5,
      "name": "Soil_Dirt"
    },
    {
      "x": -9,
      "y": 2,
      "z": 5,
      "name": "Soil_Dirt"
    },
    {
      "x": -9,
      "y": 3,
      "z": 5,
      "name": "Soil_Dirt"
    },
    {
      "x": -9,
      "y": 4,
      "z": 5,
      "name": "Soil_Grass"
    },
    {
      "x": -9,
      "y": 5,
      "z": 5,
      "name": "Empty"
    },
    {
      "x": -9,
      "y": 6,
      "z": 5,
      "name": "Empty"
    },
    {
      "x": -9,
      "y": 7,
      "z": 5,
      "name": "Empty"
    },
    {
      "x": -9,
      "y": 8,
      "z": 5,
      "name": "Empty"
    },
    {
      "x": -9,
      "y": 9,
      "z": 5,
      "name": "Empty"
    },
    {
      "x": -9,
      "y": 10,
      "z": 5,
      "name": "Empty"
    },
    {
      "x": -9,
      "y": 11,
      "z": 5,
      "name": "Empty"
    },
    {
      "x": -9,
      "y": 12,
      "z": 5,
      "name": "Empty"
    },
    {
      "x": -9,
      "y": 0,
      "z": 6,
      "name": "Rock_Stone"
    },
    {
      "x": -9,
      "y": 1,
      "z": 6,
      "name": "Soil_Dirt"
    },
    {
      "x": -9,
      "y": 2,
      "z": 6,
      "name": "Soil_Dirt"
    },
    {
      "x": -9,
      "y": 3,
      "z": 6,
      "name": "Soil_Dirt"
    },
    {
      "x": -9,
      "y": 4,
      "z": 6,
      "name": "Soil_Grass"
    },
    {
      "x": -9,
      "y": 5,
      "z": 6,
      "name": "Empty"
    },
    {
      "x": -9,
      "y": 6,
      "z": 6,
      "name": "Empty"
    },
    {
      "x": -9,
      "y": 7,
      "z": 6,
      "name": "Empty"
    },
    {
      "x": -9,
      "y": 8,
      "z": 6,
      "name": "Empty"
    },
    {
      "x": -9,
      "y": 9,
      "z": 6,
      "name": "Empty"
    },
    {
      "x": -9,
      "y": 10,
      "z": 6,
      "name": "Empty"
    },
    {
      "x": -9,
      "y": 11,
      "z": 6,
      "name": "Empty"
    },
    {
      "x": -9,
      "y": 12,
      "z": 6,
      "name": "Empty"
    },
    {
      "x": -9,
      "y": 0,
      "z": 7,
      "name": "Rock_Stone"
    },
    {
      "x": -9,
      "y": 1,
      "z": 7,
      "name": "Soil_Dirt"
    },
    {
      "x": -9,
      "y": 2,
      "z": 7,
      "name": "Soil_Dirt"
    },
    {
      "x": -9,
      "y": 3,
      "z": 7,
      "name": "Soil_Dirt"
    },
    {
      "x": -9,
      "y": 4,
      "z": 7,
      "name": "Soil_Grass"
    },
    {
      "x": -9,
      "y": 5,
      "z": 7,
      "name": "Empty"
    },
    {
      "x": -9,
      "y": 6,
      "z": 7,
      "name": "Empty"
    },
    {
      "x": -9,
      "y": 7,
      "z": 7,
      "name": "Empty"
    },
    {
      "x": -9,
      "y": 8,
      "z": 7,
      "name": "Empty"
    },
    {
      "x": -9,
      "y": 9,
      "z": 7,
      "name": "Empty"
    },
    {
      "x": -9,
      "y": 10,
      "z": 7,
      "name": "Empty"
    },
    {
      "x": -9,
      "y": 11,
      "z": 7,
      "name": "Empty"
    },
    {
      "x": -9,
      "y": 12,
      "z": 7,
      "name": "Empty"
    },
    {
      "x": -9,
      "y": 0,
      "z": 8,
      "name": "Rock_Stone"
    },
    {
      "x": -9,
      "y": 1,
      "z": 8,
      "name": "Soil_Dirt"
    },
    {
      "x": -9,
      "y": 2,
      "z": 8,
      "name": "Soil_Dirt"
    },
    {
      "x": -9,
      "y": 3,
      "z": 8,
      "name": "Soil_Dirt"
    },
    {
      "x": -9,
      "y": 4,
      "z": 8,
      "name": "Soil_Grass"
    },
    {
      "x": -9,
      "y": 5,
      "z": 8,
      "name": "Empty"
    },
    {
      "x": -9,
      "y": 6,
      "z": 8,
      "name": "Empty"
    },
    {
      "x": -9,
      "y": 7,
      "z": 8,
      "name": "Empty"
    },
    {
      "x": -9,
      "y": 8,
      "z": 8,
      "name": "Empty"
    },
    {
      "x": -9,
      "y": 9,
      "z": 8,
      "name": "Empty"
    },
    {
      "x": -9,
      "y": 10,
      "z": 8,
      "name": "Empty"
    },
    {
      "x": -9,
      "y": 11,
      "z": 8,
      "name": "Empty"
    },
    {
      "x": -9,
      "y": 12,
      "z": 8,
      "name": "Empty"
    },
    {
      "x": -9,
      "y": 0,
      "z": 9,
      "name": "Rock_Stone"
    },
    {
      "x": -9,
      "y": 1,
      "z": 9,
      "name": "Soil_Dirt"
    },
    {
      "x": -9,
      "y": 2,
      "z": 9,
      "name": "Soil_Dirt"
    },
    {
      "x": -9,
      "y": 3,
      "z": 9,
      "name": "Soil_Dirt"
    },
    {
      "x": -9,
      "y": 4,
      "z": 9,
      "name": "Soil_Grass"
    },
    {
      "x": -9,
      "y": 5,
      "z": 9,
      "name": "Empty"
    },
    {
      "x": -9,
      "y": 6,
      "z": 9,
      "name": "Empty"
    },
    {
      "x": -9,
      "y": 7,
      "z": 9,
      "name": "Empty"
    },
    {
      "x": -9,
      "y": 8,
      "z": 9,
      "name": "Empty"
    },
    {
      "x": -9,
      "y": 9,
      "z": 9,
      "name": "Empty"
    },
    {
      "x": -9,
      "y": 10,
      "z": 9,
      "name": "Empty"
    },
    {
      "x": -9,
      "y": 11,
      "z": 9,
      "name": "Empty"
    },
    {
      "x": -9,
      "y": 12,
      "z": 9,
      "name": "Empty"
    },
    {
      "x": -9,
      "y": 0,
      "z": 10,
      "name": "Rock_Stone"
    },
    {
      "x": -9,
      "y": 1,
      "z": 10,
      "name": "Soil_Dirt"
    },
    {
      "x": -9,
      "y": 2,
      "z": 10,
      "name": "Soil_Dirt"
    },
    {
      "x": -9,
      "y": 3,
      "z": 10,
      "name": "Soil_Dirt"
    },
    {
      "x": -9,
      "y": 4,
      "z": 10,
      "name": "Soil_Grass"
    },
    {
      "x": -9,
      "y": 5,
      "z": 10,
      "name": "Empty"
    },
    {
      "x": -9,
      "y": 6,
      "z": 10,
      "name": "Empty"
    },
    {
      "x": -9,
      "y": 7,
      "z": 10,
      "name": "Empty"
    },
    {
      "x": -9,
      "y": 8,
      "z": 10,
      "name": "Empty"
    },
    {
      "x": -9,
      "y": 9,
      "z": 10,
      "name": "Empty"
    },
    {
      "x": -9,
      "y": 10,
      "z": 10,
      "name": "Empty"
    },
    {
      "x": -9,
      "y": 11,
      "z": 10,
      "name": "Empty"
    },
    {
      "x": -9,
      "y": 12,
      "z": 10,
      "name": "Empty"
    },
    {
      "x": -9,
      "y": 0,
      "z": 11,
      "name": "Rock_Stone"
    },
    {
      "x": -9,
      "y": 1,
      "z": 11,
      "name": "Soil_Dirt"
    },
    {
      "x": -9,
      "y": 2,
      "z": 11,
      "name": "Soil_Dirt"
    },
    {
      "x": -9,
      "y": 3,
      "z": 11,
      "name": "Soil_Dirt"
    },
    {
      "x": -9,
      "y": 4,
      "z": 11,
      "name": "Soil_Grass"
    },
    {
      "x": -9,
      "y": 5,
      "z": 11,
      "name": "Empty"
    },
    {
      "x": -9,
      "y": 6,
      "z": 11,
      "name": "Empty"
    },
    {
      "x": -9,
      "y": 7,
      "z": 11,
      "name": "Empty"
    },
    {
      "x": -9,
      "y": 8,
      "z": 11,
      "name": "Empty"
    },
    {
      "x": -9,
      "y": 9,
      "z": 11,
      "name": "Empty"
    },
    {
      "x": -9,
      "y": 10,
      "z": 11,
      "name": "Empty"
    },
    {
      "x": -9,
      "y": 11,
      "z": 11,
      "name": "Empty"
    },
    {
      "x": -9,
      "y": 12,
      "z": 11,
      "name": "Empty"
    },
    {
      "x": -9,
      "y": 0,
      "z": 12,
      "name": "Rock_Stone"
    },
    {
      "x": -9,
      "y": 1,
      "z": 12,
      "name": "Soil_Dirt"
    },
    {
      "x": -9,
      "y": 2,
      "z": 12,
      "name": "Soil_Dirt"
    },
    {
      "x": -9,
      "y": 3,
      "z": 12,
      "name": "Soil_Dirt"
    },
    {
      "x": -9,
      "y": 4,
      "z": 12,
      "name": "Soil_Grass"
    },
    {
      "x": -9,
      "y": 5,
      "z": 12,
      "name": "Empty"
    },
    {
      "x": -9,
      "y": 6,
      "z": 12,
      "name": "Empty"
    },
    {
      "x": -9,
      "y": 7,
      "z": 12,
      "name": "Empty"
    },
    {
      "x": -9,
      "y": 8,
      "z": 12,
      "name": "Empty"
    },
    {
      "x": -9,
      "y": 9,
      "z": 12,
      "name": "Empty"
    },
    {
      "x": -9,
      "y": 10,
      "z": 12,
      "name": "Empty"
    },
    {
      "x": -9,
      "y": 11,
      "z": 12,
      "name": "Empty"
    },
    {
      "x": -9,
      "y": 12,
      "z": 12,
      "name": "Empty"
    },
    {
      "x": -8,
      "y": 0,
      "z": -11,
      "name": "Rock_Stone"
    },
    {
      "x": -8,
      "y": 1,
      "z": -11,
      "name": "Soil_Dirt"
    },
    {
      "x": -8,
      "y": 2,
      "z": -11,
      "name": "Soil_Dirt"
    },
    {
      "x": -8,
      "y": 3,
      "z": -11,
      "name": "Soil_Dirt"
    },
    {
      "x": -8,
      "y": 4,
      "z": -11,
      "name": "Soil_Grass"
    },
    {
      "x": -8,
      "y": 5,
      "z": -11,
      "name": "Empty"
    },
    {
      "x": -8,
      "y": 6,
      "z": -11,
      "name": "Empty"
    },
    {
      "x": -8,
      "y": 7,
      "z": -11,
      "name": "Empty"
    },
    {
      "x": -8,
      "y": 8,
      "z": -11,
      "name": "Empty"
    },
    {
      "x": -8,
      "y": 9,
      "z": -11,
      "name": "Empty"
    },
    {
      "x": -8,
      "y": 10,
      "z": -11,
      "name": "Empty"
    },
    {
      "x": -8,
      "y": 11,
      "z": -11,
      "name": "Empty"
    },
    {
      "x": -8,
      "y": 12,
      "z": -11,
      "name": "Empty"
    },
    {
      "x": -8,
      "y": 0,
      "z": -10,
      "name": "Rock_Stone"
    },
    {
      "x": -8,
      "y": 1,
      "z": -10,
      "name": "Soil_Dirt"
    },
    {
      "x": -8,
      "y": 2,
      "z": -10,
      "name": "Soil_Dirt"
    },
    {
      "x": -8,
      "y": 3,
      "z": -10,
      "name": "Soil_Dirt"
    },
    {
      "x": -8,
      "y": 4,
      "z": -10,
      "name": "Soil_Grass"
    },
    {
      "x": -8,
      "y": 5,
      "z": -10,
      "name": "Empty"
    },
    {
      "x": -8,
      "y": 6,
      "z": -10,
      "name": "Empty"
    },
    {
      "x": -8,
      "y": 7,
      "z": -10,
      "name": "Empty"
    },
    {
      "x": -8,
      "y": 8,
      "z": -10,
      "name": "Empty"
    },
    {
      "x": -8,
      "y": 9,
      "z": -10,
      "name": "Empty"
    },
    {
      "x": -8,
      "y": 10,
      "z": -10,
      "name": "Empty"
    },
    {
      "x": -8,
      "y": 11,
      "z": -10,
      "name": "Empty"
    },
    {
      "x": -8,
      "y": 12,
      "z": -10,
      "name": "Empty"
    },
    {
      "x": -8,
      "y": 0,
      "z": -9,
      "name": "Rock_Stone"
    },
    {
      "x": -8,
      "y": 1,
      "z": -9,
      "name": "Soil_Dirt"
    },
    {
      "x": -8,
      "y": 2,
      "z": -9,
      "name": "Soil_Dirt"
    },
    {
      "x": -8,
      "y": 3,
      "z": -9,
      "name": "Soil_Dirt"
    },
    {
      "x": -8,
      "y": 4,
      "z": -9,
      "name": "Soil_Grass"
    },
    {
      "x": -8,
      "y": 5,
      "z": -9,
      "name": "Empty"
    },
    {
      "x": -8,
      "y": 6,
      "z": -9,
      "name": "Empty"
    },
    {
      "x": -8,
      "y": 7,
      "z": -9,
      "name": "Empty"
    },
    {
      "x": -8,
      "y": 8,
      "z": -9,
      "name": "Empty"
    },
    {
      "x": -8,
      "y": 9,
      "z": -9,
      "name": "Empty"
    },
    {
      "x": -8,
      "y": 10,
      "z": -9,
      "name": "Empty"
    },
    {
      "x": -8,
      "y": 11,
      "z": -9,
      "name": "Empty"
    },
    {
      "x": -8,
      "y": 12,
      "z": -9,
      "name": "Empty"
    },
    {
      "x": -8,
      "y": 0,
      "z": -8,
      "name": "Rock_Stone"
    },
    {
      "x": -8,
      "y": 1,
      "z": -8,
      "name": "Soil_Dirt"
    },
    {
      "x": -8,
      "y": 2,
      "z": -8,
      "name": "Soil_Dirt"
    },
    {
      "x": -8,
      "y": 3,
      "z": -8,
      "name": "Soil_Dirt"
    },
    {
      "x": -8,
      "y": 4,
      "z": -8,
      "name": "Rock_Stone_Cobble"
    },
    {
      "x": -8,
      "y": 5,
      "z": -8,
      "name": "Empty"
    },
    {
      "x": -8,
      "y": 6,
      "z": -8,
      "name": "Empty"
    },
    {
      "x": -8,
      "y": 7,
      "z": -8,
      "name": "Empty"
    },
    {
      "x": -8,
      "y": 8,
      "z": -8,
      "name": "Wood_Hardwood_Roof",
      "rotation": 2
    },
    {
      "x": -8,
      "y": 9,
      "z": -8,
      "name": "Empty"
    },
    {
      "x": -8,
      "y": 10,
      "z": -8,
      "name": "Empty"
    },
    {
      "x": -8,
      "y": 11,
      "z": -8,
      "name": "Empty"
    },
    {
      "x": -8,
      "y": 12,
      "z": -8,
      "name": "Empty"
    },
    {
      "x": -8,
      "y": 0,
      "z": -7,
      "name": "Rock_Stone"
    },
    {
      "x": -8,
      "y": 1,
      "z": -7,
      "name": "Soil_Dirt"
    },
    {
      "x": -8,
      "y": 2,
      "z": -7,
      "name": "Soil_Dirt"
    },
    {
      "x": -8,
      "y": 3,
      "z": -7,
      "name": "Soil_Dirt"
    },
    {
      "x": -8,
      "y": 4,
      "z": -7,
      "name": "Rock_Stone_Cobble"
    },
    {
      "x": -8,
      "y": 5,
      "z": -7,
      "name": "Wood_Beech_Trunk",
      "support": 15
    },
    {
      "x": -8,
      "y": 6,
      "z": -7,
      "name": "Wood_Beech_Trunk",
      "support": 15
    },
    {
      "x": -8,
      "y": 7,
      "z": -7,
      "name": "Wood_Beech_Trunk",
      "support": 15
    },
    {
      "x": -8,
      "y": 8,
      "z": -7,
      "name": "Wood_Beech_Trunk",
      "support": 15,
      "rotation": 4
    },
    {
      "x": -8,
      "y": 9,
      "z": -7,
      "name": "Wood_Softwood_Stairs",
      "rotation": 2
    },
    {
      "x": -8,
      "y": 10,
      "z": -7,
      "name": "Empty"
    },
    {
      "x": -8,
      "y": 11,
      "z": -7,
      "name": "Empty"
    },
    {
      "x": -8,
      "y": 12,
      "z": -7,
      "name": "Empty"
    },
    {
      "x": -8,
      "y": 0,
      "z": -6,
      "name": "Rock_Stone"
    },
    {
      "x": -8,
      "y": 1,
      "z": -6,
      "name": "Soil_Dirt"
    },
    {
      "x": -8,
      "y": 2,
      "z": -6,
      "name": "Soil_Dirt"
    },
    {
      "x": -8,
      "y": 3,
      "z": -6,
      "name": "Soil_Dirt"
    },
    {
      "x": -8,
      "y": 4,
      "z": -6,
      "name": "Soil_Dirt"
    },
    {
      "x": -8,
      "y": 5,
      "z": -6,
      "name": "Rock_Stone_Brick"
    },
    {
      "x": -8,
      "y": 6,
      "z": -6,
      "name": "Rock_Stone_Brick"
    },
    {
      "x": -8,
      "y": 7,
      "z": -6,
      "name": "Rock_Stone_Brick"
    },
    {
      "x": -8,
      "y": 8,
      "z": -6,
      "name": "Wood_Beech_Trunk",
      "support": 15,
      "rotation": 4
    },
    {
      "x": -8,
      "y": 9,
      "z": -6,
      "name": "Wood_Village_Wall_Full"
    },
    {
      "x": -8,
      "y": 10,
      "z": -6,
      "name": "Wood_Softwood_Stairs",
      "rotation": 2
    },
    {
      "x": -8,
      "y": 11,
      "z": -6,
      "name": "Empty"
    },
    {
      "x": -8,
      "y": 12,
      "z": -6,
      "name": "Empty"
    },
    {
      "x": -8,
      "y": 0,
      "z": -5,
      "name": "Rock_Stone"
    },
    {
      "x": -8,
      "y": 1,
      "z": -5,
      "name": "Soil_Dirt"
    },
    {
      "x": -8,
      "y": 2,
      "z": -5,
      "name": "Soil_Dirt"
    },
    {
      "x": -8,
      "y": 3,
      "z": -5,
      "name": "Soil_Dirt"
    },
    {
      "x": -8,
      "y": 4,
      "z": -5,
      "name": "Rock_Stone_Cobble"
    },
    {
      "x": -8,
      "y": 5,
      "z": -5,
      "name": "Rock_Stone_Brick"
    },
    {
      "x": -8,
      "y": 6,
      "z": -5,
      "name": "Rock_Stone_Brick"
    },
    {
      "x": -8,
      "y": 7,
      "z": -5,
      "name": "Rock_Stone_Brick"
    },
    {
      "x": -8,
      "y": 8,
      "z": -5,
      "name": "Wood_Beech_Trunk",
      "support": 15,
      "rotation": 4
    },
    {
      "x": -8,
      "y": 9,
      "z": -5,
      "name": "*Wood_Village_Wall_Full_State_Definitions_Bottom"
    },
    {
      "x": -8,
      "y": 10,
      "z": -5,
      "name": "*Wood_Village_Wall_Full_State_Definitions_Top"
    },
    {
      "x": -8,
      "y": 11,
      "z": -5,
      "name": "Wood_Softwood_Stairs",
      "rotation": 2
    },
    {
      "x": -8,
      "y": 12,
      "z": -5,
      "name": "Empty"
    },
    {
      "x": -8,
      "y": 0,
      "z": -4,
      "name": "Rock_Stone"
    },
    {
      "x": -8,
      "y": 1,
      "z": -4,
      "name": "Soil_Dirt"
    },
    {
      "x": -8,
      "y": 2,
      "z": -4,
      "name": "Soil_Dirt"
    },
    {
      "x": -8,
      "y": 3,
      "z": -4,
      "name": "Soil_Dirt"
    },
    {
      "x": -8,
      "y": 4,
      "z": -4,
      "name": "Rock_Stone_Cobble"
    },
    {
      "x": -8,
      "y": 5,
      "z": -4,
      "name": "Wood_Beech_Trunk",
      "support": 15
    },
    {
      "x": -8,
      "y": 6,
      "z": -4,
      "name": "Wood_Beech_Trunk",
      "support": 15
    },
    {
      "x": -8,
      "y": 7,
      "z": -4,
      "name": "Wood_Beech_Trunk",
      "support": 15
    },
    {
      "x": -8,
      "y": 8,
      "z": -4,
      "name": "Wood_Beech_Trunk",
      "support": 15,
      "rotation": 4
    },
    {
      "x": -8,
      "y": 9,
      "z": -4,
      "name": "*Wood_Village_Wall_Full_State_Definitions_Bottom"
    },
    {
      "x": -8,
      "y": 10,
      "z": -4,
      "name": "*Wood_Village_Wall_Full_State_Definitions_Middle"
    },
    {
      "x": -8,
      "y": 11,
      "z": -4,
      "name": "*Wood_Village_Wall_Full_State_Definitions_Top"
    },
    {
      "x": -8,
      "y": 12,
      "z": -4,
      "name": "Wood_Softwood_Planks_Half"
    },
    {
      "x": -8,
      "y": 0,
      "z": -3,
      "name": "Rock_Stone"
    },
    {
      "x": -8,
      "y": 1,
      "z": -3,
      "name": "Soil_Dirt"
    },
    {
      "x": -8,
      "y": 2,
      "z": -3,
      "name": "Soil_Dirt"
    },
    {
      "x": -8,
      "y": 3,
      "z": -3,
      "name": "Soil_Dirt"
    },
    {
      "x": -8,
      "y": 4,
      "z": -3,
      "name": "Rock_Stone_Cobble"
    },
    {
      "x": -8,
      "y": 5,
      "z": -3,
      "name": "*Furniture_Village_Door_State_Definitions_CloseDoorOut",
      "rotation": 3
    },
    {
      "x": -8,
      "y": 6,
      "z": -3,
      "name": "*Furniture_Village_Door_State_Definitions_CloseDoorOut",
      "filler": 1024,
      "rotation": 3
    },
    {
      "x": -8,
      "y": 7,
      "z": -3,
      "name": "Wood_Beech_Trunk",
      "support": 15,
      "rotation": 4
    },
    {
      "x": -8,
      "y": 8,
      "z": -3,
      "name": "Wood_Beech_Trunk",
      "support": 15,
      "rotation": 4
    },
    {
      "x": -8,
      "y": 9,
      "z": -3,
      "name": "Furniture_Village_Window",
      "rotation": 1
    },
    {
      "x": -8,
      "y": 10,
      "z": -3,
      "name": "Wood_Beech_Trunk",
      "support": 15
    },
    {
      "x": -8,
      "y": 11,
      "z": -3,
      "name": "Wood_Beech_Trunk",
      "support": 15
    },
    {
      "x": -8,
      "y": 12,
      "z": -3,
      "name": "Wood_Softwood_Planks_Half"
    },
    {
      "x": -8,
      "y": 0,
      "z": -2,
      "name": "Rock_Stone"
    },
    {
      "x": -8,
      "y": 1,
      "z": -2,
      "name": "Soil_Dirt"
    },
    {
      "x": -8,
      "y": 2,
      "z": -2,
      "name": "Soil_Dirt"
    },
    {
      "x": -8,
      "y": 3,
      "z": -2,
      "name": "Soil_Dirt"
    },
    {
      "x": -8,
      "y": 4,
      "z": -2,
      "name": "Rock_Stone_Cobble"
    },
    {
      "x": -8,
      "y": 5,
      "z": -2,
      "name": "Wood_Beech_Trunk",
      "support": 15
    },
    {
      "x": -8,
      "y": 6,
      "z": -2,
      "name": "Wood_Beech_Trunk",
      "support": 15
    },
    {
      "x": -8,
      "y": 7,
      "z": -2,
      "name": "Wood_Beech_Trunk",
      "support": 15
    },
    {
      "x": -8,
      "y": 8,
      "z": -2,
      "name": "Wood_Beech_Trunk",
      "support": 15,
      "rotation": 4
    },
    {
      "x": -8,
      "y": 9,
      "z": -2,
      "name": "*Wood_Village_Wall_Full_State_Definitions_Bottom"
    },
    {
      "x": -8,
      "y": 10,
      "z": -2,
      "name": "*Wood_Village_Wall_Full_State_Definitions_Middle"
    },
    {
      "x": -8,
      "y": 11,
      "z": -2,
      "name": "*Wood_Village_Wall_Full_State_Definitions_Top"
    },
    {
      "x": -8,
      "y": 12,
      "z": -2,
      "name": "Wood_Softwood_Planks_Half"
    },
    {
      "x": -8,
      "y": 0,
      "z": -1,
      "name": "Rock_Stone"
    },
    {
      "x": -8,
      "y": 1,
      "z": -1,
      "name": "Soil_Dirt"
    },
    {
      "x": -8,
      "y": 2,
      "z": -1,
      "name": "Soil_Dirt"
    },
    {
      "x": -8,
      "y": 3,
      "z": -1,
      "name": "Soil_Dirt"
    },
    {
      "x": -8,
      "y": 4,
      "z": -1,
      "name": "Rock_Stone_Cobble"
    },
    {
      "x": -8,
      "y": 5,
      "z": -1,
      "name": "Rock_Stone_Brick"
    },
    {
      "x": -8,
      "y": 6,
      "z": -1,
      "name": "Rock_Stone_Brick"
    },
    {
      "x": -8,
      "y": 7,
      "z": -1,
      "name": "Rock_Stone_Brick"
    },
    {
      "x": -8,
      "y": 8,
      "z": -1,
      "name": "Wood_Beech_Trunk",
      "support": 15,
      "rotation": 4
    },
    {
      "x": -8,
      "y": 9,
      "z": -1,
      "name": "*Wood_Village_Wall_Full_State_Definitions_Bottom"
    },
    {
      "x": -8,
      "y": 10,
      "z": -1,
      "name": "*Wood_Village_Wall_Full_State_Definitions_Top"
    },
    {
      "x": -8,
      "y": 11,
      "z": -1,
      "name": "Wood_Softwood_Stairs"
    },
    {
      "x": -8,
      "y": 12,
      "z": -1,
      "name": "Empty"
    },
    {
      "x": -8,
      "y": 0,
      "z": 0,
      "name": "Rock_Stone"
    },
    {
      "x": -8,
      "y": 1,
      "z": 0,
      "name": "Soil_Dirt"
    },
    {
      "x": -8,
      "y": 2,
      "z": 0,
      "name": "Soil_Dirt"
    },
    {
      "x": -8,
      "y": 3,
      "z": 0,
      "name": "Soil_Dirt"
    },
    {
      "x": -8,
      "y": 4,
      "z": 0,
      "name": "Rock_Stone_Cobble"
    },
    {
      "x": -8,
      "y": 5,
      "z": 0,
      "name": "Rock_Stone_Brick"
    },
    {
      "x": -8,
      "y": 6,
      "z": 0,
      "name": "Rock_Stone_Brick"
    },
    {
      "x": -8,
      "y": 7,
      "z": 0,
      "name": "Rock_Stone_Brick"
    },
    {
      "x": -8,
      "y": 8,
      "z": 0,
      "name": "Wood_Beech_Trunk",
      "support": 15,
      "rotation": 4
    },
    {
      "x": -8,
      "y": 9,
      "z": 0,
      "name": "Wood_Village_Wall_Full"
    },
    {
      "x": -8,
      "y": 10,
      "z": 0,
      "name": "Wood_Softwood_Stairs"
    },
    {
      "x": -8,
      "y": 11,
      "z": 0,
      "name": "Empty"
    },
    {
      "x": -8,
      "y": 12,
      "z": 0,
      "name": "Empty"
    },
    {
      "x": -8,
      "y": 0,
      "z": 1,
      "name": "Rock_Stone"
    },
    {
      "x": -8,
      "y": 1,
      "z": 1,
      "name": "Soil_Dirt"
    },
    {
      "x": -8,
      "y": 2,
      "z": 1,
      "name": "Soil_Dirt"
    },
    {
      "x": -8,
      "y": 3,
      "z": 1,
      "name": "Soil_Dirt"
    },
    {
      "x": -8,
      "y": 4,
      "z": 1,
      "name": "Rock_Stone_Cobble"
    },
    {
      "x": -8,
      "y": 5,
      "z": 1,
      "name": "Wood_Beech_Trunk",
      "support": 15
    },
    {
      "x": -8,
      "y": 6,
      "z": 1,
      "name": "Wood_Beech_Trunk",
      "support": 15
    },
    {
      "x": -8,
      "y": 7,
      "z": 1,
      "name": "Wood_Beech_Trunk",
      "support": 15
    },
    {
      "x": -8,
      "y": 8,
      "z": 1,
      "name": "Wood_Beech_Trunk",
      "support": 15
    },
    {
      "x": -8,
      "y": 9,
      "z": 1,
      "name": "Wood_Softwood_Stairs"
    },
    {
      "x": -8,
      "y": 10,
      "z": 1,
      "name": "Empty"
    },
    {
      "x": -8,
      "y": 11,
      "z": 1,
      "name": "Empty"
    },
    {
      "x": -8,
      "y": 12,
      "z": 1,
      "name": "Empty"
    },
    {
      "x": -8,
      "y": 0,
      "z": 2,
      "name": "Rock_Stone"
    },
    {
      "x": -8,
      "y": 1,
      "z": 2,
      "name": "Soil_Dirt"
    },
    {
      "x": -8,
      "y": 2,
      "z": 2,
      "name": "Soil_Dirt"
    },
    {
      "x": -8,
      "y": 3,
      "z": 2,
      "name": "Soil_Dirt"
    },
    {
      "x": -8,
      "y": 4,
      "z": 2,
      "name": "Rock_Stone_Cobble"
    },
    {
      "x": -8,
      "y": 5,
      "z": 2,
      "name": "Empty"
    },
    {
      "x": -8,
      "y": 6,
      "z": 2,
      "name": "Empty"
    },
    {
      "x": -8,
      "y": 7,
      "z": 2,
      "name": "Empty"
    },
    {
      "x": -8,
      "y": 8,
      "z": 2,
      "name": "Wood_Hardwood_Roof"
    },
    {
      "x": -8,
      "y": 9,
      "z": 2,
      "name": "Empty"
    },
    {
      "x": -8,
      "y": 10,
      "z": 2,
      "name": "Empty"
    },
    {
      "x": -8,
      "y": 11,
      "z": 2,
      "name": "Empty"
    },
    {
      "x": -8,
      "y": 12,
      "z": 2,
      "name": "Empty"
    },
    {
      "x": -8,
      "y": 0,
      "z": 3,
      "name": "Rock_Stone"
    },
    {
      "x": -8,
      "y": 1,
      "z": 3,
      "name": "Soil_Dirt"
    },
    {
      "x": -8,
      "y": 2,
      "z": 3,
      "name": "Soil_Dirt"
    },
    {
      "x": -8,
      "y": 3,
      "z": 3,
      "name": "Soil_Dirt"
    },
    {
      "x": -8,
      "y": 4,
      "z": 3,
      "name": "Soil_Grass"
    },
    {
      "x": -8,
      "y": 5,
      "z": 3,
      "name": "Empty"
    },
    {
      "x": -8,
      "y": 6,
      "z": 3,
      "name": "Empty"
    },
    {
      "x": -8,
      "y": 7,
      "z": 3,
      "name": "Empty"
    },
    {
      "x": -8,
      "y": 8,
      "z": 3,
      "name": "Empty"
    },
    {
      "x": -8,
      "y": 9,
      "z": 3,
      "name": "Empty"
    },
    {
      "x": -8,
      "y": 10,
      "z": 3,
      "name": "Empty"
    },
    {
      "x": -8,
      "y": 11,
      "z": 3,
      "name": "Empty"
    },
    {
      "x": -8,
      "y": 12,
      "z": 3,
      "name": "Empty"
    },
    {
      "x": -8,
      "y": 0,
      "z": 4,
      "name": "Rock_Stone"
    },
    {
      "x": -8,
      "y": 1,
      "z": 4,
      "name": "Soil_Dirt"
    },
    {
      "x": -8,
      "y": 2,
      "z": 4,
      "name": "Soil_Dirt"
    },
    {
      "x": -8,
      "y": 3,
      "z": 4,
      "name": "Soil_Dirt"
    },
    {
      "x": -8,
      "y": 4,
      "z": 4,
      "name": "Soil_Grass"
    },
    {
      "x": -8,
      "y": 5,
      "z": 4,
      "name": "Empty"
    },
    {
      "x": -8,
      "y": 6,
      "z": 4,
      "name": "Empty"
    },
    {
      "x": -8,
      "y": 7,
      "z": 4,
      "name": "Empty"
    },
    {
      "x": -8,
      "y": 8,
      "z": 4,
      "name": "Empty"
    },
    {
      "x": -8,
      "y": 9,
      "z": 4,
      "name": "Empty"
    },
    {
      "x": -8,
      "y": 10,
      "z": 4,
      "name": "Empty"
    },
    {
      "x": -8,
      "y": 11,
      "z": 4,
      "name": "Empty"
    },
    {
      "x": -8,
      "y": 12,
      "z": 4,
      "name": "Empty"
    },
    {
      "x": -8,
      "y": 0,
      "z": 5,
      "name": "Rock_Stone"
    },
    {
      "x": -8,
      "y": 1,
      "z": 5,
      "name": "Soil_Dirt"
    },
    {
      "x": -8,
      "y": 2,
      "z": 5,
      "name": "Soil_Dirt"
    },
    {
      "x": -8,
      "y": 3,
      "z": 5,
      "name": "Soil_Dirt"
    },
    {
      "x": -8,
      "y": 4,
      "z": 5,
      "name": "Soil_Grass"
    },
    {
      "x": -8,
      "y": 5,
      "z": 5,
      "name": "Empty"
    },
    {
      "x": -8,
      "y": 6,
      "z": 5,
      "name": "Empty"
    },
    {
      "x": -8,
      "y": 7,
      "z": 5,
      "name": "Empty"
    },
    {
      "x": -8,
      "y": 8,
      "z": 5,
      "name": "Empty"
    },
    {
      "x": -8,
      "y": 9,
      "z": 5,
      "name": "Empty"
    },
    {
      "x": -8,
      "y": 10,
      "z": 5,
      "name": "Empty"
    },
    {
      "x": -8,
      "y": 11,
      "z": 5,
      "name": "Empty"
    },
    {
      "x": -8,
      "y": 12,
      "z": 5,
      "name": "Empty"
    },
    {
      "x": -8,
      "y": 0,
      "z": 6,
      "name": "Rock_Stone"
    },
    {
      "x": -8,
      "y": 1,
      "z": 6,
      "name": "Soil_Dirt"
    },
    {
      "x": -8,
      "y": 2,
      "z": 6,
      "name": "Soil_Dirt"
    },
    {
      "x": -8,
      "y": 3,
      "z": 6,
      "name": "Soil_Dirt"
    },
    {
      "x": -8,
      "y": 4,
      "z": 6,
      "name": "Soil_Grass"
    },
    {
      "x": -8,
      "y": 5,
      "z": 6,
      "name": "Empty"
    },
    {
      "x": -8,
      "y": 6,
      "z": 6,
      "name": "Empty"
    },
    {
      "x": -8,
      "y": 7,
      "z": 6,
      "name": "Empty"
    },
    {
      "x": -8,
      "y": 8,
      "z": 6,
      "name": "Empty"
    },
    {
      "x": -8,
      "y": 9,
      "z": 6,
      "name": "Empty"
    },
    {
      "x": -8,
      "y": 10,
      "z": 6,
      "name": "Empty"
    },
    {
      "x": -8,
      "y": 11,
      "z": 6,
      "name": "Empty"
    },
    {
      "x": -8,
      "y": 12,
      "z": 6,
      "name": "Empty"
    },
    {
      "x": -8,
      "y": 0,
      "z": 7,
      "name": "Rock_Stone"
    },
    {
      "x": -8,
      "y": 1,
      "z": 7,
      "name": "Soil_Dirt"
    },
    {
      "x": -8,
      "y": 2,
      "z": 7,
      "name": "Soil_Dirt"
    },
    {
      "x": -8,
      "y": 3,
      "z": 7,
      "name": "Soil_Dirt"
    },
    {
      "x": -8,
      "y": 4,
      "z": 7,
      "name": "Soil_Grass"
    },
    {
      "x": -8,
      "y": 5,
      "z": 7,
      "name": "Empty"
    },
    {
      "x": -8,
      "y": 6,
      "z": 7,
      "name": "Empty"
    },
    {
      "x": -8,
      "y": 7,
      "z": 7,
      "name": "Empty"
    },
    {
      "x": -8,
      "y": 8,
      "z": 7,
      "name": "Empty"
    },
    {
      "x": -8,
      "y": 9,
      "z": 7,
      "name": "Empty"
    },
    {
      "x": -8,
      "y": 10,
      "z": 7,
      "name": "Empty"
    },
    {
      "x": -8,
      "y": 11,
      "z": 7,
      "name": "Empty"
    },
    {
      "x": -8,
      "y": 12,
      "z": 7,
      "name": "Empty"
    },
    {
      "x": -8,
      "y": 0,
      "z": 8,
      "name": "Rock_Stone"
    },
    {
      "x": -8,
      "y": 1,
      "z": 8,
      "name": "Soil_Dirt"
    },
    {
      "x": -8,
      "y": 2,
      "z": 8,
      "name": "Soil_Dirt"
    },
    {
      "x": -8,
      "y": 3,
      "z": 8,
      "name": "Soil_Dirt"
    },
    {
      "x": -8,
      "y": 4,
      "z": 8,
      "name": "Soil_Grass"
    },
    {
      "x": -8,
      "y": 5,
      "z": 8,
      "name": "Empty"
    },
    {
      "x": -8,
      "y": 6,
      "z": 8,
      "name": "Empty"
    },
    {
      "x": -8,
      "y": 7,
      "z": 8,
      "name": "Empty"
    },
    {
      "x": -8,
      "y": 8,
      "z": 8,
      "name": "Empty"
    },
    {
      "x": -8,
      "y": 9,
      "z": 8,
      "name": "Empty"
    },
    {
      "x": -8,
      "y": 10,
      "z": 8,
      "name": "Empty"
    },
    {
      "x": -8,
      "y": 11,
      "z": 8,
      "name": "Empty"
    },
    {
      "x": -8,
      "y": 12,
      "z": 8,
      "name": "Empty"
    },
    {
      "x": -8,
      "y": 0,
      "z": 9,
      "name": "Rock_Stone"
    },
    {
      "x": -8,
      "y": 1,
      "z": 9,
      "name": "Soil_Dirt"
    },
    {
      "x": -8,
      "y": 2,
      "z": 9,
      "name": "Soil_Dirt"
    },
    {
      "x": -8,
      "y": 3,
      "z": 9,
      "name": "Soil_Dirt"
    },
    {
      "x": -8,
      "y": 4,
      "z": 9,
      "name": "Soil_Grass"
    },
    {
      "x": -8,
      "y": 5,
      "z": 9,
      "name": "Empty"
    },
    {
      "x": -8,
      "y": 6,
      "z": 9,
      "name": "Empty"
    },
    {
      "x": -8,
      "y": 7,
      "z": 9,
      "name": "Empty"
    },
    {
      "x": -8,
      "y": 8,
      "z": 9,
      "name": "Empty"
    },
    {
      "x": -8,
      "y": 9,
      "z": 9,
      "name": "Empty"
    },
    {
      "x": -8,
      "y": 10,
      "z": 9,
      "name": "Empty"
    },
    {
      "x": -8,
      "y": 11,
      "z": 9,
      "name": "Empty"
    },
    {
      "x": -8,
      "y": 12,
      "z": 9,
      "name": "Empty"
    },
    {
      "x": -8,
      "y": 0,
      "z": 10,
      "name": "Rock_Stone"
    },
    {
      "x": -8,
      "y": 1,
      "z": 10,
      "name": "Soil_Dirt"
    },
    {
      "x": -8,
      "y": 2,
      "z": 10,
      "name": "Soil_Dirt"
    },
    {
      "x": -8,
      "y": 3,
      "z": 10,
      "name": "Soil_Dirt"
    },
    {
      "x": -8,
      "y": 4,
      "z": 10,
      "name": "Soil_Grass"
    },
    {
      "x": -8,
      "y": 5,
      "z": 10,
      "name": "Empty"
    },
    {
      "x": -8,
      "y": 6,
      "z": 10,
      "name": "Empty"
    },
    {
      "x": -8,
      "y": 7,
      "z": 10,
      "name": "Empty"
    },
    {
      "x": -8,
      "y": 8,
      "z": 10,
      "name": "Empty"
    },
    {
      "x": -8,
      "y": 9,
      "z": 10,
      "name": "Empty"
    },
    {
      "x": -8,
      "y": 10,
      "z": 10,
      "name": "Empty"
    },
    {
      "x": -8,
      "y": 11,
      "z": 10,
      "name": "Empty"
    },
    {
      "x": -8,
      "y": 12,
      "z": 10,
      "name": "Empty"
    },
    {
      "x": -8,
      "y": 0,
      "z": 11,
      "name": "Rock_Stone"
    },
    {
      "x": -8,
      "y": 1,
      "z": 11,
      "name": "Soil_Dirt"
    },
    {
      "x": -8,
      "y": 2,
      "z": 11,
      "name": "Soil_Dirt"
    },
    {
      "x": -8,
      "y": 3,
      "z": 11,
      "name": "Soil_Dirt"
    },
    {
      "x": -8,
      "y": 4,
      "z": 11,
      "name": "Soil_Grass"
    },
    {
      "x": -8,
      "y": 5,
      "z": 11,
      "name": "Empty"
    },
    {
      "x": -8,
      "y": 6,
      "z": 11,
      "name": "Empty"
    },
    {
      "x": -8,
      "y": 7,
      "z": 11,
      "name": "Empty"
    },
    {
      "x": -8,
      "y": 8,
      "z": 11,
      "name": "Empty"
    },
    {
      "x": -8,
      "y": 9,
      "z": 11,
      "name": "Empty"
    },
    {
      "x": -8,
      "y": 10,
      "z": 11,
      "name": "Empty"
    },
    {
      "x": -8,
      "y": 11,
      "z": 11,
      "name": "Empty"
    },
    {
      "x": -8,
      "y": 12,
      "z": 11,
      "name": "Empty"
    },
    {
      "x": -8,
      "y": 0,
      "z": 12,
      "name": "Rock_Stone"
    },
    {
      "x": -8,
      "y": 1,
      "z": 12,
      "name": "Soil_Dirt"
    },
    {
      "x": -8,
      "y": 2,
      "z": 12,
      "name": "Soil_Dirt"
    },
    {
      "x": -8,
      "y": 3,
      "z": 12,
      "name": "Soil_Dirt"
    },
    {
      "x": -8,
      "y": 4,
      "z": 12,
      "name": "Soil_Grass"
    },
    {
      "x": -8,
      "y": 5,
      "z": 12,
      "name": "Empty"
    },
    {
      "x": -8,
      "y": 6,
      "z": 12,
      "name": "Empty"
    },
    {
      "x": -8,
      "y": 7,
      "z": 12,
      "name": "Empty"
    },
    {
      "x": -8,
      "y": 8,
      "z": 12,
      "name": "Empty"
    },
    {
      "x": -8,
      "y": 9,
      "z": 12,
      "name": "Empty"
    },
    {
      "x": -8,
      "y": 10,
      "z": 12,
      "name": "Empty"
    },
    {
      "x": -8,
      "y": 11,
      "z": 12,
      "name": "Empty"
    },
    {
      "x": -8,
      "y": 12,
      "z": 12,
      "name": "Empty"
    },
    {
      "x": -7,
      "y": 0,
      "z": -11,
      "name": "Rock_Stone"
    },
    {
      "x": -7,
      "y": 1,
      "z": -11,
      "name": "Soil_Dirt"
    },
    {
      "x": -7,
      "y": 2,
      "z": -11,
      "name": "Soil_Dirt"
    },
    {
      "x": -7,
      "y": 3,
      "z": -11,
      "name": "Soil_Dirt"
    },
    {
      "x": -7,
      "y": 4,
      "z": -11,
      "name": "Soil_Grass"
    },
    {
      "x": -7,
      "y": 5,
      "z": -11,
      "name": "Empty"
    },
    {
      "x": -7,
      "y": 6,
      "z": -11,
      "name": "Empty"
    },
    {
      "x": -7,
      "y": 7,
      "z": -11,
      "name": "Empty"
    },
    {
      "x": -7,
      "y": 8,
      "z": -11,
      "name": "Empty"
    },
    {
      "x": -7,
      "y": 9,
      "z": -11,
      "name": "Empty"
    },
    {
      "x": -7,
      "y": 10,
      "z": -11,
      "name": "Empty"
    },
    {
      "x": -7,
      "y": 11,
      "z": -11,
      "name": "Empty"
    },
    {
      "x": -7,
      "y": 12,
      "z": -11,
      "name": "Empty"
    },
    {
      "x": -7,
      "y": 0,
      "z": -10,
      "name": "Rock_Stone"
    },
    {
      "x": -7,
      "y": 1,
      "z": -10,
      "name": "Soil_Dirt"
    },
    {
      "x": -7,
      "y": 2,
      "z": -10,
      "name": "Soil_Dirt"
    },
    {
      "x": -7,
      "y": 3,
      "z": -10,
      "name": "Soil_Dirt"
    },
    {
      "x": -7,
      "y": 4,
      "z": -10,
      "name": "Soil_Grass"
    },
    {
      "x": -7,
      "y": 5,
      "z": -10,
      "name": "Empty"
    },
    {
      "x": -7,
      "y": 6,
      "z": -10,
      "name": "Empty"
    },
    {
      "x": -7,
      "y": 7,
      "z": -10,
      "name": "Empty"
    },
    {
      "x": -7,
      "y": 8,
      "z": -10,
      "name": "Empty"
    },
    {
      "x": -7,
      "y": 9,
      "z": -10,
      "name": "Empty"
    },
    {
      "x": -7,
      "y": 10,
      "z": -10,
      "name": "Empty"
    },
    {
      "x": -7,
      "y": 11,
      "z": -10,
      "name": "Empty"
    },
    {
      "x": -7,
      "y": 12,
      "z": -10,
      "name": "Empty"
    },
    {
      "x": -7,
      "y": 0,
      "z": -9,
      "name": "Rock_Stone"
    },
    {
      "x": -7,
      "y": 1,
      "z": -9,
      "name": "Soil_Dirt"
    },
    {
      "x": -7,
      "y": 2,
      "z": -9,
      "name": "Soil_Dirt"
    },
    {
      "x": -7,
      "y": 3,
      "z": -9,
      "name": "Soil_Dirt"
    },
    {
      "x": -7,
      "y": 4,
      "z": -9,
      "name": "Soil_Grass"
    },
    {
      "x": -7,
      "y": 5,
      "z": -9,
      "name": "Empty"
    },
    {
      "x": -7,
      "y": 6,
      "z": -9,
      "name": "Empty"
    },
    {
      "x": -7,
      "y": 7,
      "z": -9,
      "name": "Empty"
    },
    {
      "x": -7,
      "y": 8,
      "z": -9,
      "name": "Empty"
    },
    {
      "x": -7,
      "y": 9,
      "z": -9,
      "name": "Empty"
    },
    {
      "x": -7,
      "y": 10,
      "z": -9,
      "name": "Empty"
    },
    {
      "x": -7,
      "y": 11,
      "z": -9,
      "name": "Empty"
    },
    {
      "x": -7,
      "y": 12,
      "z": -9,
      "name": "Empty"
    },
    {
      "x": -7,
      "y": 0,
      "z": -8,
      "name": "Rock_Stone"
    },
    {
      "x": -7,
      "y": 1,
      "z": -8,
      "name": "Soil_Dirt"
    },
    {
      "x": -7,
      "y": 2,
      "z": -8,
      "name": "Soil_Dirt"
    },
    {
      "x": -7,
      "y": 3,
      "z": -8,
      "name": "Soil_Dirt"
    },
    {
      "x": -7,
      "y": 4,
      "z": -8,
      "name": "Rock_Stone_Cobble"
    },
    {
      "x": -7,
      "y": 5,
      "z": -8,
      "name": "Empty"
    },
    {
      "x": -7,
      "y": 6,
      "z": -8,
      "name": "Empty"
    },
    {
      "x": -7,
      "y": 7,
      "z": -8,
      "name": "Empty"
    },
    {
      "x": -7,
      "y": 8,
      "z": -8,
      "name": "Wood_Hardwood_Roof",
      "rotation": 2
    },
    {
      "x": -7,
      "y": 9,
      "z": -8,
      "name": "Empty"
    },
    {
      "x": -7,
      "y": 10,
      "z": -8,
      "name": "Empty"
    },
    {
      "x": -7,
      "y": 11,
      "z": -8,
      "name": "Empty"
    },
    {
      "x": -7,
      "y": 12,
      "z": -8,
      "name": "Empty"
    },
    {
      "x": -7,
      "y": 0,
      "z": -7,
      "name": "Rock_Stone"
    },
    {
      "x": -7,
      "y": 1,
      "z": -7,
      "name": "Soil_Dirt"
    },
    {
      "x": -7,
      "y": 2,
      "z": -7,
      "name": "Soil_Dirt"
    },
    {
      "x": -7,
      "y": 3,
      "z": -7,
      "name": "Soil_Dirt"
    },
    {
      "x": -7,
      "y": 4,
      "z": -7,
      "name": "Rock_Stone_Cobble"
    },
    {
      "x": -7,
      "y": 5,
      "z": -7,
      "name": "Rock_Stone_Brick"
    },
    {
      "x": -7,
      "y": 6,
      "z": -7,
      "name": "Rock_Stone_Brick"
    },
    {
      "x": -7,
      "y": 7,
      "z": -7,
      "name": "Rock_Stone_Brick"
    },
    {
      "x": -7,
      "y": 8,
      "z": -7,
      "name": "Wood_Beech_Trunk",
      "support": 15,
      "rotation": 5
    },
    {
      "x": -7,
      "y": 9,
      "z": -7,
      "name": "Wood_Hardwood_Roof",
      "rotation": 2
    },
    {
      "x": -7,
      "y": 10,
      "z": -7,
      "name": "Empty"
    },
    {
      "x": -7,
      "y": 11,
      "z": -7,
      "name": "Empty"
    },
    {
      "x": -7,
      "y": 12,
      "z": -7,
      "name": "Empty"
    },
    {
      "x": -7,
      "y": 0,
      "z": -6,
      "name": "Rock_Stone"
    },
    {
      "x": -7,
      "y": 1,
      "z": -6,
      "name": "Soil_Dirt"
    },
    {
      "x": -7,
      "y": 2,
      "z": -6,
      "name": "Soil_Dirt"
    },
    {
      "x": -7,
      "y": 3,
      "z": -6,
      "name": "Soil_Dirt"
    },
    {
      "x": -7,
      "y": 4,
      "z": -6,
      "name": "Rock_Stone_Cobble"
    },
    {
      "x": -7,
      "y": 5,
      "z": -6,
      "name": "Furniture_Village_Chest_Large",
      "components": {
        "Components": {
          "PlacedByInteraction": {
            "WhoPlacedUuid": {
              "$binary": "USKM52bHQue/WRvBbPCYwg==",
              "$type": "04"
            }
          },
          "ItemContainerBlock": {
            "ItemContainer": {
              "Capacity": 36,
              "Items": {}
            },
            "Capacity": 36
          }
        }
      },
      "rotation": 1
    },
    {
      "x": -7,
      "y": 6,
      "z": -6,
      "name": "Empty"
    },
    {
      "x": -7,
      "y": 7,
      "z": -6,
      "name": "Furniture_Village_Platform",
      "rotation": 1
    },
    {
      "x": -7,
      "y": 8,
      "z": -6,
      "name": "Empty"
    },
    {
      "x": -7,
      "y": 9,
      "z": -6,
      "name": "Wood_Softwood_Stairs",
      "rotation": 10
    },
    {
      "x": -7,
      "y": 10,
      "z": -6,
      "name": "Wood_Hardwood_Roof",
      "rotation": 2
    },
    {
      "x": -7,
      "y": 11,
      "z": -6,
      "name": "Empty"
    },
    {
      "x": -7,
      "y": 12,
      "z": -6,
      "name": "Empty"
    },
    {
      "x": -7,
      "y": 0,
      "z": -5,
      "name": "Rock_Stone"
    },
    {
      "x": -7,
      "y": 1,
      "z": -5,
      "name": "Soil_Dirt"
    },
    {
      "x": -7,
      "y": 2,
      "z": -5,
      "name": "Soil_Dirt"
    },
    {
      "x": -7,
      "y": 3,
      "z": -5,
      "name": "Soil_Dirt"
    },
    {
      "x": -7,
      "y": 4,
      "z": -5,
      "name": "Rock_Stone_Cobble"
    },
    {
      "x": -7,
      "y": 5,
      "z": -5,
      "name": "Furniture_Village_Chest_Large",
      "filler": 32,
      "rotation": 1
    },
    {
      "x": -7,
      "y": 6,
      "z": -5,
      "name": "Empty"
    },
    {
      "x": -7,
      "y": 7,
      "z": -5,
      "name": "Furniture_Village_Platform",
      "rotation": 1
    },
    {
      "x": -7,
      "y": 8,
      "z": -5,
      "name": "Wood_Hardwood_Fence"
    },
    {
      "x": -7,
      "y": 9,
      "z": -5,
      "name": "Empty"
    },
    {
      "x": -7,
      "y": 10,
      "z": -5,
      "name": "Wood_Softwood_Stairs",
      "rotation": 10
    },
    {
      "x": -7,
      "y": 11,
      "z": -5,
      "name": "Wood_Hardwood_Roof",
      "rotation": 2
    },
    {
      "x": -7,
      "y": 12,
      "z": -5,
      "name": "Empty"
    },
    {
      "x": -7,
      "y": 0,
      "z": -4,
      "name": "Rock_Stone"
    },
    {
      "x": -7,
      "y": 1,
      "z": -4,
      "name": "Soil_Dirt"
    },
    {
      "x": -7,
      "y": 2,
      "z": -4,
      "name": "Soil_Dirt"
    },
    {
      "x": -7,
      "y": 3,
      "z": -4,
      "name": "Soil_Dirt"
    },
    {
      "x": -7,
      "y": 4,
      "z": -4,
      "name": "Rock_Stone_Cobble"
    },
    {
      "x": -7,
      "y": 5,
      "z": -4,
      "name": "Empty"
    },
    {
      "x": -7,
      "y": 6,
      "z": -4,
      "name": "Wood_Torch_Wall",
      "rotation": 1
    },
    {
      "x": -7,
      "y": 7,
      "z": -4,
      "name": "Empty"
    },
    {
      "x": -7,
      "y": 8,
      "z": -4,
      "name": "Empty"
    },
    {
      "x": -7,
      "y": 9,
      "z": -4,
      "name": "Empty"
    },
    {
      "x": -7,
      "y": 10,
      "z": -4,
      "name": "Empty"
    },
    {
      "x": -7,
      "y": 11,
      "z": -4,
      "name": "Wood_Softwood_Stairs",
      "rotation": 10
    },
    {
      "x": -7,
      "y": 12,
      "z": -4,
      "name": "Wood_Hardwood_Roof_Flat",
      "rotation": 2
    },
    {
      "x": -7,
      "y": 0,
      "z": -3,
      "name": "Rock_Stone"
    },
    {
      "x": -7,
      "y": 1,
      "z": -3,
      "name": "Soil_Dirt"
    },
    {
      "x": -7,
      "y": 2,
      "z": -3,
      "name": "Soil_Dirt"
    },
    {
      "x": -7,
      "y": 3,
      "z": -3,
      "name": "Soil_Dirt"
    },
    {
      "x": -7,
      "y": 4,
      "z": -3,
      "name": "Rock_Stone_Cobble"
    },
    {
      "x": -7,
      "y": 5,
      "z": -3,
      "name": "Empty"
    },
    {
      "x": -7,
      "y": 6,
      "z": -3,
      "name": "Empty"
    },
    {
      "x": -7,
      "y": 7,
      "z": -3,
      "name": "Empty"
    },
    {
      "x": -7,
      "y": 8,
      "z": -3,
      "name": "Empty"
    },
    {
      "x": -7,
      "y": 9,
      "z": -3,
      "name": "Empty"
    },
    {
      "x": -7,
      "y": 10,
      "z": -3,
      "name": "Empty"
    },
    {
      "x": -7,
      "y": 11,
      "z": -3,
      "name": "Wood_Softwood_Planks_Half",
      "rotation": 8
    },
    {
      "x": -7,
      "y": 12,
      "z": -3,
      "name": "Wood_Softwood_Planks_Half"
    },
    {
      "x": -7,
      "y": 0,
      "z": -2,
      "name": "Rock_Stone"
    },
    {
      "x": -7,
      "y": 1,
      "z": -2,
      "name": "Soil_Dirt"
    },
    {
      "x": -7,
      "y": 2,
      "z": -2,
      "name": "Soil_Dirt"
    },
    {
      "x": -7,
      "y": 3,
      "z": -2,
      "name": "Soil_Dirt"
    },
    {
      "x": -7,
      "y": 4,
      "z": -2,
      "name": "Rock_Stone_Cobble"
    },
    {
      "x": -7,
      "y": 5,
      "z": -2,
      "name": "Empty"
    },
    {
      "x": -7,
      "y": 6,
      "z": -2,
      "name": "Wood_Torch_Wall",
      "rotation": 1
    },
    {
      "x": -7,
      "y": 7,
      "z": -2,
      "name": "Empty"
    },
    {
      "x": -7,
      "y": 8,
      "z": -2,
      "name": "Empty"
    },
    {
      "x": -7,
      "y": 9,
      "z": -2,
      "name": "Empty"
    },
    {
      "x": -7,
      "y": 10,
      "z": -2,
      "name": "Empty"
    },
    {
      "x": -7,
      "y": 11,
      "z": -2,
      "name": "Wood_Softwood_Stairs",
      "rotation": 8
    },
    {
      "x": -7,
      "y": 12,
      "z": -2,
      "name": "Wood_Hardwood_Roof_Flat"
    },
    {
      "x": -7,
      "y": 0,
      "z": -1,
      "name": "Rock_Stone"
    },
    {
      "x": -7,
      "y": 1,
      "z": -1,
      "name": "Soil_Dirt"
    },
    {
      "x": -7,
      "y": 2,
      "z": -1,
      "name": "Soil_Dirt"
    },
    {
      "x": -7,
      "y": 3,
      "z": -1,
      "name": "Soil_Dirt"
    },
    {
      "x": -7,
      "y": 4,
      "z": -1,
      "name": "Rock_Stone_Cobble"
    },
    {
      "x": -7,
      "y": 5,
      "z": -1,
      "name": "Empty"
    },
    {
      "x": -7,
      "y": 6,
      "z": -1,
      "name": "Empty"
    },
    {
      "x": -7,
      "y": 7,
      "z": -1,
      "name": "Empty"
    },
    {
      "x": -7,
      "y": 8,
      "z": -1,
      "name": "Empty"
    },
    {
      "x": -7,
      "y": 9,
      "z": -1,
      "name": "Empty"
    },
    {
      "x": -7,
      "y": 10,
      "z": -1,
      "name": "Wood_Softwood_Stairs",
      "rotation": 8
    },
    {
      "x": -7,
      "y": 11,
      "z": -1,
      "name": "Wood_Hardwood_Roof"
    },
    {
      "x": -7,
      "y": 12,
      "z": -1,
      "name": "Empty"
    },
    {
      "x": -7,
      "y": 0,
      "z": 0,
      "name": "Rock_Stone"
    },
    {
      "x": -7,
      "y": 1,
      "z": 0,
      "name": "Soil_Dirt"
    },
    {
      "x": -7,
      "y": 2,
      "z": 0,
      "name": "Soil_Dirt"
    },
    {
      "x": -7,
      "y": 3,
      "z": 0,
      "name": "Soil_Dirt"
    },
    {
      "x": -7,
      "y": 4,
      "z": 0,
      "name": "Rock_Stone_Cobble"
    },
    {
      "x": -7,
      "y": 5,
      "z": 0,
      "name": "Empty"
    },
    {
      "x": -7,
      "y": 6,
      "z": 0,
      "name": "Empty"
    },
    {
      "x": -7,
      "y": 7,
      "z": 0,
      "name": "Empty"
    },
    {
      "x": -7,
      "y": 8,
      "z": 0,
      "name": "Empty"
    },
    {
      "x": -7,
      "y": 9,
      "z": 0,
      "name": "Wood_Softwood_Stairs",
      "rotation": 8
    },
    {
      "x": -7,
      "y": 10,
      "z": 0,
      "name": "Wood_Hardwood_Roof"
    },
    {
      "x": -7,
      "y": 11,
      "z": 0,
      "name": "Empty"
    },
    {
      "x": -7,
      "y": 12,
      "z": 0,
      "name": "Empty"
    },
    {
      "x": -7,
      "y": 0,
      "z": 1,
      "name": "Rock_Stone"
    },
    {
      "x": -7,
      "y": 1,
      "z": 1,
      "name": "Soil_Dirt"
    },
    {
      "x": -7,
      "y": 2,
      "z": 1,
      "name": "Soil_Dirt"
    },
    {
      "x": -7,
      "y": 3,
      "z": 1,
      "name": "Soil_Dirt"
    },
    {
      "x": -7,
      "y": 4,
      "z": 1,
      "name": "Rock_Stone_Cobble"
    },
    {
      "x": -7,
      "y": 5,
      "z": 1,
      "name": "Rock_Stone_Brick"
    },
    {
      "x": -7,
      "y": 6,
      "z": 1,
      "name": "Rock_Stone_Brick"
    },
    {
      "x": -7,
      "y": 7,
      "z": 1,
      "name": "Rock_Stone_Brick"
    },
    {
      "x": -7,
      "y": 8,
      "z": 1,
      "name": "Wood_Beech_Trunk",
      "support": 15,
      "rotation": 5
    },
    {
      "x": -7,
      "y": 9,
      "z": 1,
      "name": "Wood_Hardwood_Roof"
    },
    {
      "x": -7,
      "y": 10,
      "z": 1,
      "name": "Empty"
    },
    {
      "x": -7,
      "y": 11,
      "z": 1,
      "name": "Empty"
    },
    {
      "x": -7,
      "y": 12,
      "z": 1,
      "name": "Empty"
    },
    {
      "x": -7,
      "y": 0,
      "z": 2,
      "name": "Rock_Stone"
    },
    {
      "x": -7,
      "y": 1,
      "z": 2,
      "name": "Soil_Dirt"
    },
    {
      "x": -7,
      "y": 2,
      "z": 2,
      "name": "Soil_Dirt"
    },
    {
      "x": -7,
      "y": 3,
      "z": 2,
      "name": "Soil_Dirt"
    },
    {
      "x": -7,
      "y": 4,
      "z": 2,
      "name": "Rock_Stone_Cobble"
    },
    {
      "x": -7,
      "y": 5,
      "z": 2,
      "name": "Empty"
    },
    {
      "x": -7,
      "y": 6,
      "z": 2,
      "name": "Empty"
    },
    {
      "x": -7,
      "y": 7,
      "z": 2,
      "name": "Empty"
    },
    {
      "x": -7,
      "y": 8,
      "z": 2,
      "name": "Wood_Hardwood_Roof"
    },
    {
      "x": -7,
      "y": 9,
      "z": 2,
      "name": "Empty"
    },
    {
      "x": -7,
      "y": 10,
      "z": 2,
      "name": "Empty"
    },
    {
      "x": -7,
      "y": 11,
      "z": 2,
      "name": "Empty"
    },
    {
      "x": -7,
      "y": 12,
      "z": 2,
      "name": "Empty"
    },
    {
      "x": -7,
      "y": 0,
      "z": 3,
      "name": "Rock_Stone"
    },
    {
      "x": -7,
      "y": 1,
      "z": 3,
      "name": "Soil_Dirt"
    },
    {
      "x": -7,
      "y": 2,
      "z": 3,
      "name": "Soil_Dirt"
    },
    {
      "x": -7,
      "y": 3,
      "z": 3,
      "name": "Soil_Dirt"
    },
    {
      "x": -7,
      "y": 4,
      "z": 3,
      "name": "Soil_Grass"
    },
    {
      "x": -7,
      "y": 5,
      "z": 3,
      "name": "Empty"
    },
    {
      "x": -7,
      "y": 6,
      "z": 3,
      "name": "Empty"
    },
    {
      "x": -7,
      "y": 7,
      "z": 3,
      "name": "Empty"
    },
    {
      "x": -7,
      "y": 8,
      "z": 3,
      "name": "Empty"
    },
    {
      "x": -7,
      "y": 9,
      "z": 3,
      "name": "Empty"
    },
    {
      "x": -7,
      "y": 10,
      "z": 3,
      "name": "Empty"
    },
    {
      "x": -7,
      "y": 11,
      "z": 3,
      "name": "Empty"
    },
    {
      "x": -7,
      "y": 12,
      "z": 3,
      "name": "Empty"
    },
    {
      "x": -7,
      "y": 0,
      "z": 4,
      "name": "Rock_Stone"
    },
    {
      "x": -7,
      "y": 1,
      "z": 4,
      "name": "Soil_Dirt"
    },
    {
      "x": -7,
      "y": 2,
      "z": 4,
      "name": "Soil_Dirt"
    },
    {
      "x": -7,
      "y": 3,
      "z": 4,
      "name": "Soil_Dirt"
    },
    {
      "x": -7,
      "y": 4,
      "z": 4,
      "name": "Soil_Grass"
    },
    {
      "x": -7,
      "y": 5,
      "z": 4,
      "name": "Empty"
    },
    {
      "x": -7,
      "y": 6,
      "z": 4,
      "name": "Empty"
    },
    {
      "x": -7,
      "y": 7,
      "z": 4,
      "name": "Empty"
    },
    {
      "x": -7,
      "y": 8,
      "z": 4,
      "name": "Empty"
    },
    {
      "x": -7,
      "y": 9,
      "z": 4,
      "name": "Empty"
    },
    {
      "x": -7,
      "y": 10,
      "z": 4,
      "name": "Empty"
    },
    {
      "x": -7,
      "y": 11,
      "z": 4,
      "name": "Empty"
    },
    {
      "x": -7,
      "y": 12,
      "z": 4,
      "name": "Empty"
    },
    {
      "x": -7,
      "y": 0,
      "z": 5,
      "name": "Rock_Stone"
    },
    {
      "x": -7,
      "y": 1,
      "z": 5,
      "name": "Soil_Dirt"
    },
    {
      "x": -7,
      "y": 2,
      "z": 5,
      "name": "Soil_Dirt"
    },
    {
      "x": -7,
      "y": 3,
      "z": 5,
      "name": "Soil_Dirt"
    },
    {
      "x": -7,
      "y": 4,
      "z": 5,
      "name": "Soil_Grass"
    },
    {
      "x": -7,
      "y": 5,
      "z": 5,
      "name": "Empty"
    },
    {
      "x": -7,
      "y": 6,
      "z": 5,
      "name": "Empty"
    },
    {
      "x": -7,
      "y": 7,
      "z": 5,
      "name": "Empty"
    },
    {
      "x": -7,
      "y": 8,
      "z": 5,
      "name": "Empty"
    },
    {
      "x": -7,
      "y": 9,
      "z": 5,
      "name": "Empty"
    },
    {
      "x": -7,
      "y": 10,
      "z": 5,
      "name": "Empty"
    },
    {
      "x": -7,
      "y": 11,
      "z": 5,
      "name": "Empty"
    },
    {
      "x": -7,
      "y": 12,
      "z": 5,
      "name": "Empty"
    },
    {
      "x": -7,
      "y": 0,
      "z": 6,
      "name": "Rock_Stone"
    },
    {
      "x": -7,
      "y": 1,
      "z": 6,
      "name": "Soil_Dirt"
    },
    {
      "x": -7,
      "y": 2,
      "z": 6,
      "name": "Soil_Dirt"
    },
    {
      "x": -7,
      "y": 3,
      "z": 6,
      "name": "Soil_Dirt"
    },
    {
      "x": -7,
      "y": 4,
      "z": 6,
      "name": "Soil_Grass"
    },
    {
      "x": -7,
      "y": 5,
      "z": 6,
      "name": "Empty"
    },
    {
      "x": -7,
      "y": 6,
      "z": 6,
      "name": "Empty"
    },
    {
      "x": -7,
      "y": 7,
      "z": 6,
      "name": "Empty"
    },
    {
      "x": -7,
      "y": 8,
      "z": 6,
      "name": "Empty"
    },
    {
      "x": -7,
      "y": 9,
      "z": 6,
      "name": "Empty"
    },
    {
      "x": -7,
      "y": 10,
      "z": 6,
      "name": "Empty"
    },
    {
      "x": -7,
      "y": 11,
      "z": 6,
      "name": "Empty"
    },
    {
      "x": -7,
      "y": 12,
      "z": 6,
      "name": "Empty"
    },
    {
      "x": -7,
      "y": 0,
      "z": 7,
      "name": "Rock_Stone"
    },
    {
      "x": -7,
      "y": 1,
      "z": 7,
      "name": "Soil_Dirt"
    },
    {
      "x": -7,
      "y": 2,
      "z": 7,
      "name": "Soil_Dirt"
    },
    {
      "x": -7,
      "y": 3,
      "z": 7,
      "name": "Soil_Dirt"
    },
    {
      "x": -7,
      "y": 4,
      "z": 7,
      "name": "Soil_Grass"
    },
    {
      "x": -7,
      "y": 5,
      "z": 7,
      "name": "Empty"
    },
    {
      "x": -7,
      "y": 6,
      "z": 7,
      "name": "Empty"
    },
    {
      "x": -7,
      "y": 7,
      "z": 7,
      "name": "Empty"
    },
    {
      "x": -7,
      "y": 8,
      "z": 7,
      "name": "Empty"
    },
    {
      "x": -7,
      "y": 9,
      "z": 7,
      "name": "Empty"
    },
    {
      "x": -7,
      "y": 10,
      "z": 7,
      "name": "Empty"
    },
    {
      "x": -7,
      "y": 11,
      "z": 7,
      "name": "Empty"
    },
    {
      "x": -7,
      "y": 12,
      "z": 7,
      "name": "Empty"
    },
    {
      "x": -7,
      "y": 0,
      "z": 8,
      "name": "Rock_Stone"
    },
    {
      "x": -7,
      "y": 1,
      "z": 8,
      "name": "Soil_Dirt"
    },
    {
      "x": -7,
      "y": 2,
      "z": 8,
      "name": "Soil_Dirt"
    },
    {
      "x": -7,
      "y": 3,
      "z": 8,
      "name": "Soil_Dirt"
    },
    {
      "x": -7,
      "y": 4,
      "z": 8,
      "name": "Soil_Grass"
    },
    {
      "x": -7,
      "y": 5,
      "z": 8,
      "name": "Empty"
    },
    {
      "x": -7,
      "y": 6,
      "z": 8,
      "name": "Empty"
    },
    {
      "x": -7,
      "y": 7,
      "z": 8,
      "name": "Empty"
    },
    {
      "x": -7,
      "y": 8,
      "z": 8,
      "name": "Empty"
    },
    {
      "x": -7,
      "y": 9,
      "z": 8,
      "name": "Empty"
    },
    {
      "x": -7,
      "y": 10,
      "z": 8,
      "name": "Empty"
    },
    {
      "x": -7,
      "y": 11,
      "z": 8,
      "name": "Empty"
    },
    {
      "x": -7,
      "y": 12,
      "z": 8,
      "name": "Empty"
    },
    {
      "x": -7,
      "y": 0,
      "z": 9,
      "name": "Rock_Stone"
    },
    {
      "x": -7,
      "y": 1,
      "z": 9,
      "name": "Soil_Dirt"
    },
    {
      "x": -7,
      "y": 2,
      "z": 9,
      "name": "Soil_Dirt"
    },
    {
      "x": -7,
      "y": 3,
      "z": 9,
      "name": "Soil_Dirt"
    },
    {
      "x": -7,
      "y": 4,
      "z": 9,
      "name": "Soil_Grass"
    },
    {
      "x": -7,
      "y": 5,
      "z": 9,
      "name": "Empty"
    },
    {
      "x": -7,
      "y": 6,
      "z": 9,
      "name": "Empty"
    },
    {
      "x": -7,
      "y": 7,
      "z": 9,
      "name": "Empty"
    },
    {
      "x": -7,
      "y": 8,
      "z": 9,
      "name": "Empty"
    },
    {
      "x": -7,
      "y": 9,
      "z": 9,
      "name": "Empty"
    },
    {
      "x": -7,
      "y": 10,
      "z": 9,
      "name": "Empty"
    },
    {
      "x": -7,
      "y": 11,
      "z": 9,
      "name": "Empty"
    },
    {
      "x": -7,
      "y": 12,
      "z": 9,
      "name": "Empty"
    },
    {
      "x": -7,
      "y": 0,
      "z": 10,
      "name": "Rock_Stone"
    },
    {
      "x": -7,
      "y": 1,
      "z": 10,
      "name": "Soil_Dirt"
    },
    {
      "x": -7,
      "y": 2,
      "z": 10,
      "name": "Soil_Dirt"
    },
    {
      "x": -7,
      "y": 3,
      "z": 10,
      "name": "Soil_Dirt"
    },
    {
      "x": -7,
      "y": 4,
      "z": 10,
      "name": "Soil_Grass"
    },
    {
      "x": -7,
      "y": 5,
      "z": 10,
      "name": "Empty"
    },
    {
      "x": -7,
      "y": 6,
      "z": 10,
      "name": "Empty"
    },
    {
      "x": -7,
      "y": 7,
      "z": 10,
      "name": "Empty"
    },
    {
      "x": -7,
      "y": 8,
      "z": 10,
      "name": "Empty"
    },
    {
      "x": -7,
      "y": 9,
      "z": 10,
      "name": "Empty"
    },
    {
      "x": -7,
      "y": 10,
      "z": 10,
      "name": "Empty"
    },
    {
      "x": -7,
      "y": 11,
      "z": 10,
      "name": "Empty"
    },
    {
      "x": -7,
      "y": 12,
      "z": 10,
      "name": "Empty"
    },
    {
      "x": -7,
      "y": 0,
      "z": 11,
      "name": "Rock_Stone"
    },
    {
      "x": -7,
      "y": 1,
      "z": 11,
      "name": "Soil_Dirt"
    },
    {
      "x": -7,
      "y": 2,
      "z": 11,
      "name": "Soil_Dirt"
    },
    {
      "x": -7,
      "y": 3,
      "z": 11,
      "name": "Soil_Dirt"
    },
    {
      "x": -7,
      "y": 4,
      "z": 11,
      "name": "Soil_Grass"
    },
    {
      "x": -7,
      "y": 5,
      "z": 11,
      "name": "Empty"
    },
    {
      "x": -7,
      "y": 6,
      "z": 11,
      "name": "Empty"
    },
    {
      "x": -7,
      "y": 7,
      "z": 11,
      "name": "Empty"
    },
    {
      "x": -7,
      "y": 8,
      "z": 11,
      "name": "Empty"
    },
    {
      "x": -7,
      "y": 9,
      "z": 11,
      "name": "Empty"
    },
    {
      "x": -7,
      "y": 10,
      "z": 11,
      "name": "Empty"
    },
    {
      "x": -7,
      "y": 11,
      "z": 11,
      "name": "Empty"
    },
    {
      "x": -7,
      "y": 12,
      "z": 11,
      "name": "Empty"
    },
    {
      "x": -7,
      "y": 0,
      "z": 12,
      "name": "Rock_Stone"
    },
    {
      "x": -7,
      "y": 1,
      "z": 12,
      "name": "Soil_Dirt"
    },
    {
      "x": -7,
      "y": 2,
      "z": 12,
      "name": "Soil_Dirt"
    },
    {
      "x": -7,
      "y": 3,
      "z": 12,
      "name": "Soil_Dirt"
    },
    {
      "x": -7,
      "y": 4,
      "z": 12,
      "name": "Soil_Grass"
    },
    {
      "x": -7,
      "y": 5,
      "z": 12,
      "name": "Empty"
    },
    {
      "x": -7,
      "y": 6,
      "z": 12,
      "name": "Empty"
    },
    {
      "x": -7,
      "y": 7,
      "z": 12,
      "name": "Empty"
    },
    {
      "x": -7,
      "y": 8,
      "z": 12,
      "name": "Empty"
    },
    {
      "x": -7,
      "y": 9,
      "z": 12,
      "name": "Empty"
    },
    {
      "x": -7,
      "y": 10,
      "z": 12,
      "name": "Empty"
    },
    {
      "x": -7,
      "y": 11,
      "z": 12,
      "name": "Empty"
    },
    {
      "x": -7,
      "y": 12,
      "z": 12,
      "name": "Empty"
    },
    {
      "x": -6,
      "y": 0,
      "z": -11,
      "name": "Rock_Stone"
    },
    {
      "x": -6,
      "y": 1,
      "z": -11,
      "name": "Soil_Dirt"
    },
    {
      "x": -6,
      "y": 2,
      "z": -11,
      "name": "Soil_Dirt"
    },
    {
      "x": -6,
      "y": 3,
      "z": -11,
      "name": "Soil_Dirt"
    },
    {
      "x": -6,
      "y": 4,
      "z": -11,
      "name": "Soil_Grass"
    },
    {
      "x": -6,
      "y": 5,
      "z": -11,
      "name": "Empty"
    },
    {
      "x": -6,
      "y": 6,
      "z": -11,
      "name": "Empty"
    },
    {
      "x": -6,
      "y": 7,
      "z": -11,
      "name": "Empty"
    },
    {
      "x": -6,
      "y": 8,
      "z": -11,
      "name": "Empty"
    },
    {
      "x": -6,
      "y": 9,
      "z": -11,
      "name": "Empty"
    },
    {
      "x": -6,
      "y": 10,
      "z": -11,
      "name": "Empty"
    },
    {
      "x": -6,
      "y": 11,
      "z": -11,
      "name": "Empty"
    },
    {
      "x": -6,
      "y": 12,
      "z": -11,
      "name": "Empty"
    },
    {
      "x": -6,
      "y": 0,
      "z": -10,
      "name": "Rock_Stone"
    },
    {
      "x": -6,
      "y": 1,
      "z": -10,
      "name": "Soil_Dirt"
    },
    {
      "x": -6,
      "y": 2,
      "z": -10,
      "name": "Soil_Dirt"
    },
    {
      "x": -6,
      "y": 3,
      "z": -10,
      "name": "Soil_Dirt"
    },
    {
      "x": -6,
      "y": 4,
      "z": -10,
      "name": "Soil_Grass"
    },
    {
      "x": -6,
      "y": 5,
      "z": -10,
      "name": "Empty"
    },
    {
      "x": -6,
      "y": 6,
      "z": -10,
      "name": "Empty"
    },
    {
      "x": -6,
      "y": 7,
      "z": -10,
      "name": "Empty"
    },
    {
      "x": -6,
      "y": 8,
      "z": -10,
      "name": "Empty"
    },
    {
      "x": -6,
      "y": 9,
      "z": -10,
      "name": "Empty"
    },
    {
      "x": -6,
      "y": 10,
      "z": -10,
      "name": "Empty"
    },
    {
      "x": -6,
      "y": 11,
      "z": -10,
      "name": "Empty"
    },
    {
      "x": -6,
      "y": 12,
      "z": -10,
      "name": "Empty"
    },
    {
      "x": -6,
      "y": 0,
      "z": -9,
      "name": "Rock_Stone"
    },
    {
      "x": -6,
      "y": 1,
      "z": -9,
      "name": "Soil_Dirt"
    },
    {
      "x": -6,
      "y": 2,
      "z": -9,
      "name": "Soil_Dirt"
    },
    {
      "x": -6,
      "y": 3,
      "z": -9,
      "name": "Soil_Dirt"
    },
    {
      "x": -6,
      "y": 4,
      "z": -9,
      "name": "Soil_Grass"
    },
    {
      "x": -6,
      "y": 5,
      "z": -9,
      "name": "Empty"
    },
    {
      "x": -6,
      "y": 6,
      "z": -9,
      "name": "Empty"
    },
    {
      "x": -6,
      "y": 7,
      "z": -9,
      "name": "Empty"
    },
    {
      "x": -6,
      "y": 8,
      "z": -9,
      "name": "Empty"
    },
    {
      "x": -6,
      "y": 9,
      "z": -9,
      "name": "Empty"
    },
    {
      "x": -6,
      "y": 10,
      "z": -9,
      "name": "Empty"
    },
    {
      "x": -6,
      "y": 11,
      "z": -9,
      "name": "Empty"
    },
    {
      "x": -6,
      "y": 12,
      "z": -9,
      "name": "Empty"
    },
    {
      "x": -6,
      "y": 0,
      "z": -8,
      "name": "Rock_Stone"
    },
    {
      "x": -6,
      "y": 1,
      "z": -8,
      "name": "Soil_Dirt"
    },
    {
      "x": -6,
      "y": 2,
      "z": -8,
      "name": "Soil_Dirt"
    },
    {
      "x": -6,
      "y": 3,
      "z": -8,
      "name": "Soil_Dirt"
    },
    {
      "x": -6,
      "y": 4,
      "z": -8,
      "name": "Rock_Stone_Cobble"
    },
    {
      "x": -6,
      "y": 5,
      "z": -8,
      "name": "Empty"
    },
    {
      "x": -6,
      "y": 6,
      "z": -8,
      "name": "Empty"
    },
    {
      "x": -6,
      "y": 7,
      "z": -8,
      "name": "Empty"
    },
    {
      "x": -6,
      "y": 8,
      "z": -8,
      "name": "Wood_Hardwood_Roof_Hollow",
      "rotation": 2
    },
    {
      "x": -6,
      "y": 9,
      "z": -8,
      "name": "Empty"
    },
    {
      "x": -6,
      "y": 10,
      "z": -8,
      "name": "Empty"
    },
    {
      "x": -6,
      "y": 11,
      "z": -8,
      "name": "Empty"
    },
    {
      "x": -6,
      "y": 12,
      "z": -8,
      "name": "Empty"
    },
    {
      "x": -6,
      "y": 0,
      "z": -7,
      "name": "Rock_Stone"
    },
    {
      "x": -6,
      "y": 1,
      "z": -7,
      "name": "Soil_Dirt"
    },
    {
      "x": -6,
      "y": 2,
      "z": -7,
      "name": "Soil_Dirt"
    },
    {
      "x": -6,
      "y": 3,
      "z": -7,
      "name": "Soil_Dirt"
    },
    {
      "x": -6,
      "y": 4,
      "z": -7,
      "name": "Rock_Stone_Cobble"
    },
    {
      "x": -6,
      "y": 5,
      "z": -7,
      "name": "Rock_Stone_Brick"
    },
    {
      "x": -6,
      "y": 6,
      "z": -7,
      "name": "Rock_Stone_Brick"
    },
    {
      "x": -6,
      "y": 7,
      "z": -7,
      "name": "Rock_Stone_Brick"
    },
    {
      "x": -6,
      "y": 8,
      "z": -7,
      "name": "Wood_Beech_Trunk",
      "support": 15,
      "rotation": 5
    },
    {
      "x": -6,
      "y": 9,
      "z": -7,
      "name": "Wood_Hardwood_Roof",
      "rotation": 2
    },
    {
      "x": -6,
      "y": 10,
      "z": -7,
      "name": "Empty"
    },
    {
      "x": -6,
      "y": 11,
      "z": -7,
      "name": "Empty"
    },
    {
      "x": -6,
      "y": 12,
      "z": -7,
      "name": "Empty"
    },
    {
      "x": -6,
      "y": 0,
      "z": -6,
      "name": "Rock_Stone"
    },
    {
      "x": -6,
      "y": 1,
      "z": -6,
      "name": "Soil_Dirt"
    },
    {
      "x": -6,
      "y": 2,
      "z": -6,
      "name": "Soil_Dirt"
    },
    {
      "x": -6,
      "y": 3,
      "z": -6,
      "name": "Soil_Dirt"
    },
    {
      "x": -6,
      "y": 4,
      "z": -6,
      "name": "Rock_Stone_Cobble"
    },
    {
      "x": -6,
      "y": 5,
      "z": -6,
      "name": "Empty"
    },
    {
      "x": -6,
      "y": 6,
      "z": -6,
      "name": "Empty"
    },
    {
      "x": -6,
      "y": 7,
      "z": -6,
      "name": "Furniture_Village_Platform",
      "rotation": 1
    },
    {
      "x": -6,
      "y": 8,
      "z": -6,
      "name": "Empty"
    },
    {
      "x": -6,
      "y": 9,
      "z": -6,
      "name": "Wood_Softwood_Stairs",
      "rotation": 10
    },
    {
      "x": -6,
      "y": 10,
      "z": -6,
      "name": "Wood_Hardwood_Roof",
      "rotation": 2
    },
    {
      "x": -6,
      "y": 11,
      "z": -6,
      "name": "Empty"
    },
    {
      "x": -6,
      "y": 12,
      "z": -6,
      "name": "Empty"
    },
    {
      "x": -6,
      "y": 0,
      "z": -5,
      "name": "Rock_Stone"
    },
    {
      "x": -6,
      "y": 1,
      "z": -5,
      "name": "Soil_Dirt"
    },
    {
      "x": -6,
      "y": 2,
      "z": -5,
      "name": "Soil_Dirt"
    },
    {
      "x": -6,
      "y": 3,
      "z": -5,
      "name": "Soil_Dirt"
    },
    {
      "x": -6,
      "y": 4,
      "z": -5,
      "name": "Rock_Stone_Cobble"
    },
    {
      "x": -6,
      "y": 5,
      "z": -5,
      "name": "Empty"
    },
    {
      "x": -6,
      "y": 6,
      "z": -5,
      "name": "Empty"
    },
    {
      "x": -6,
      "y": 7,
      "z": -5,
      "name": "Furniture_Village_Platform",
      "rotation": 1
    },
    {
      "x": -6,
      "y": 8,
      "z": -5,
      "name": "*Wood_Hardwood_Fence_State_Definitions_Corner"
    },
    {
      "x": -6,
      "y": 9,
      "z": -5,
      "name": "Empty"
    },
    {
      "x": -6,
      "y": 10,
      "z": -5,
      "name": "Wood_Softwood_Stairs",
      "rotation": 10
    },
    {
      "x": -6,
      "y": 11,
      "z": -5,
      "name": "Wood_Hardwood_Roof",
      "rotation": 2
    },
    {
      "x": -6,
      "y": 12,
      "z": -5,
      "name": "Empty"
    },
    {
      "x": -6,
      "y": 0,
      "z": -4,
      "name": "Rock_Stone"
    },
    {
      "x": -6,
      "y": 1,
      "z": -4,
      "name": "Soil_Dirt"
    },
    {
      "x": -6,
      "y": 2,
      "z": -4,
      "name": "Soil_Dirt"
    },
    {
      "x": -6,
      "y": 3,
      "z": -4,
      "name": "Soil_Dirt"
    },
    {
      "x": -6,
      "y": 4,
      "z": -4,
      "name": "Rock_Stone_Cobble"
    },
    {
      "x": -6,
      "y": 5,
      "z": -4,
      "name": "Empty"
    },
    {
      "x": -6,
      "y": 6,
      "z": -4,
      "name": "Empty"
    },
    {
      "x": -6,
      "y": 7,
      "z": -4,
      "name": "Furniture_Village_Platform",
      "rotation": 1
    },
    {
      "x": -6,
      "y": 8,
      "z": -4,
      "name": "*Wood_Hardwood_Fence_State_Definitions_Corner",
      "rotation": 2
    },
    {
      "x": -6,
      "y": 9,
      "z": -4,
      "name": "Empty"
    },
    {
      "x": -6,
      "y": 10,
      "z": -4,
      "name": "Empty"
    },
    {
      "x": -6,
      "y": 11,
      "z": -4,
      "name": "Wood_Softwood_Stairs",
      "rotation": 10
    },
    {
      "x": -6,
      "y": 12,
      "z": -4,
      "name": "Wood_Hardwood_Roof_Flat",
      "rotation": 2
    },
    {
      "x": -6,
      "y": 0,
      "z": -3,
      "name": "Rock_Stone"
    },
    {
      "x": -6,
      "y": 1,
      "z": -3,
      "name": "Soil_Dirt"
    },
    {
      "x": -6,
      "y": 2,
      "z": -3,
      "name": "Soil_Dirt"
    },
    {
      "x": -6,
      "y": 3,
      "z": -3,
      "name": "Soil_Dirt"
    },
    {
      "x": -6,
      "y": 4,
      "z": -3,
      "name": "Rock_Stone_Cobble"
    },
    {
      "x": -6,
      "y": 5,
      "z": -3,
      "name": "Empty"
    },
    {
      "x": -6,
      "y": 6,
      "z": -3,
      "name": "Empty"
    },
    {
      "x": -6,
      "y": 7,
      "z": -3,
      "name": "Empty"
    },
    {
      "x": -6,
      "y": 8,
      "z": -3,
      "name": "Empty"
    },
    {
      "x": -6,
      "y": 9,
      "z": -3,
      "name": "Empty"
    },
    {
      "x": -6,
      "y": 10,
      "z": -3,
      "name": "Empty"
    },
    {
      "x": -6,
      "y": 11,
      "z": -3,
      "name": "Wood_Softwood_Planks_Half",
      "rotation": 8
    },
    {
      "x": -6,
      "y": 12,
      "z": -3,
      "name": "Wood_Softwood_Planks_Half"
    },
    {
      "x": -6,
      "y": 0,
      "z": -2,
      "name": "Rock_Stone"
    },
    {
      "x": -6,
      "y": 1,
      "z": -2,
      "name": "Soil_Dirt"
    },
    {
      "x": -6,
      "y": 2,
      "z": -2,
      "name": "Soil_Dirt"
    },
    {
      "x": -6,
      "y": 3,
      "z": -2,
      "name": "Soil_Dirt"
    },
    {
      "x": -6,
      "y": 4,
      "z": -2,
      "name": "Rock_Stone_Cobble"
    },
    {
      "x": -6,
      "y": 5,
      "z": -2,
      "name": "Empty"
    },
    {
      "x": -6,
      "y": 6,
      "z": -2,
      "name": "Empty"
    },
    {
      "x": -6,
      "y": 7,
      "z": -2,
      "name": "Empty"
    },
    {
      "x": -6,
      "y": 8,
      "z": -2,
      "name": "Empty"
    },
    {
      "x": -6,
      "y": 9,
      "z": -2,
      "name": "Empty"
    },
    {
      "x": -6,
      "y": 10,
      "z": -2,
      "name": "Empty"
    },
    {
      "x": -6,
      "y": 11,
      "z": -2,
      "name": "Wood_Softwood_Stairs",
      "rotation": 8
    },
    {
      "x": -6,
      "y": 12,
      "z": -2,
      "name": "Wood_Hardwood_Roof_Flat",
      "rotation": 1
    },
    {
      "x": -6,
      "y": 0,
      "z": -1,
      "name": "Rock_Stone"
    },
    {
      "x": -6,
      "y": 1,
      "z": -1,
      "name": "Soil_Dirt"
    },
    {
      "x": -6,
      "y": 2,
      "z": -1,
      "name": "Soil_Dirt"
    },
    {
      "x": -6,
      "y": 3,
      "z": -1,
      "name": "Soil_Dirt"
    },
    {
      "x": -6,
      "y": 4,
      "z": -1,
      "name": "Rock_Stone_Cobble_Stairs",
      "rotation": 1
    },
    {
      "x": -6,
      "y": 5,
      "z": -1,
      "name": "Empty"
    },
    {
      "x": -6,
      "y": 6,
      "z": -1,
      "name": "Empty"
    },
    {
      "x": -6,
      "y": 7,
      "z": -1,
      "name": "Empty"
    },
    {
      "x": -6,
      "y": 8,
      "z": -1,
      "name": "Empty"
    },
    {
      "x": -6,
      "y": 9,
      "z": -1,
      "name": "Empty"
    },
    {
      "x": -6,
      "y": 10,
      "z": -1,
      "name": "Wood_Softwood_Stairs",
      "rotation": 8
    },
    {
      "x": -6,
      "y": 11,
      "z": -1,
      "name": "Wood_Hardwood_Roof"
    },
    {
      "x": -6,
      "y": 12,
      "z": -1,
      "name": "Empty"
    },
    {
      "x": -6,
      "y": 0,
      "z": 0,
      "name": "Rock_Stone"
    },
    {
      "x": -6,
      "y": 1,
      "z": 0,
      "name": "Soil_Dirt"
    },
    {
      "x": -6,
      "y": 2,
      "z": 0,
      "name": "Soil_Dirt"
    },
    {
      "x": -6,
      "y": 3,
      "z": 0,
      "name": "Soil_Dirt"
    },
    {
      "x": -6,
      "y": 4,
      "z": 0,
      "name": "Rock_Stone_Cobble_Stairs",
      "rotation": 1
    },
    {
      "x": -6,
      "y": 5,
      "z": 0,
      "name": "Empty"
    },
    {
      "x": -6,
      "y": 6,
      "z": 0,
      "name": "Empty"
    },
    {
      "x": -6,
      "y": 7,
      "z": 0,
      "name": "Empty"
    },
    {
      "x": -6,
      "y": 8,
      "z": 0,
      "name": "Empty"
    },
    {
      "x": -6,
      "y": 9,
      "z": 0,
      "name": "Wood_Softwood_Stairs",
      "rotation": 8
    },
    {
      "x": -6,
      "y": 10,
      "z": 0,
      "name": "Wood_Hardwood_Roof"
    },
    {
      "x": -6,
      "y": 11,
      "z": 0,
      "name": "Empty"
    },
    {
      "x": -6,
      "y": 12,
      "z": 0,
      "name": "Empty"
    },
    {
      "x": -6,
      "y": 0,
      "z": 1,
      "name": "Rock_Stone"
    },
    {
      "x": -6,
      "y": 1,
      "z": 1,
      "name": "Soil_Dirt"
    },
    {
      "x": -6,
      "y": 2,
      "z": 1,
      "name": "Soil_Dirt"
    },
    {
      "x": -6,
      "y": 3,
      "z": 1,
      "name": "Soil_Dirt"
    },
    {
      "x": -6,
      "y": 4,
      "z": 1,
      "name": "Rock_Stone_Cobble"
    },
    {
      "x": -6,
      "y": 5,
      "z": 1,
      "name": "Rock_Stone_Brick"
    },
    {
      "x": -6,
      "y": 6,
      "z": 1,
      "name": "Rock_Stone_Brick"
    },
    {
      "x": -6,
      "y": 7,
      "z": 1,
      "name": "Rock_Stone_Brick"
    },
    {
      "x": -6,
      "y": 8,
      "z": 1,
      "name": "Wood_Beech_Trunk",
      "support": 15,
      "rotation": 5
    },
    {
      "x": -6,
      "y": 9,
      "z": 1,
      "name": "Wood_Hardwood_Roof"
    },
    {
      "x": -6,
      "y": 10,
      "z": 1,
      "name": "Empty"
    },
    {
      "x": -6,
      "y": 11,
      "z": 1,
      "name": "Empty"
    },
    {
      "x": -6,
      "y": 12,
      "z": 1,
      "name": "Empty"
    },
    {
      "x": -6,
      "y": 0,
      "z": 2,
      "name": "Rock_Stone"
    },
    {
      "x": -6,
      "y": 1,
      "z": 2,
      "name": "Soil_Dirt"
    },
    {
      "x": -6,
      "y": 2,
      "z": 2,
      "name": "Soil_Dirt"
    },
    {
      "x": -6,
      "y": 3,
      "z": 2,
      "name": "Soil_Dirt"
    },
    {
      "x": -6,
      "y": 4,
      "z": 2,
      "name": "Rock_Stone_Cobble"
    },
    {
      "x": -6,
      "y": 5,
      "z": 2,
      "name": "Empty"
    },
    {
      "x": -6,
      "y": 6,
      "z": 2,
      "name": "Empty"
    },
    {
      "x": -6,
      "y": 7,
      "z": 2,
      "name": "Empty"
    },
    {
      "x": -6,
      "y": 8,
      "z": 2,
      "name": "Wood_Hardwood_Roof_Hollow"
    },
    {
      "x": -6,
      "y": 9,
      "z": 2,
      "name": "Empty"
    },
    {
      "x": -6,
      "y": 10,
      "z": 2,
      "name": "Empty"
    },
    {
      "x": -6,
      "y": 11,
      "z": 2,
      "name": "Empty"
    },
    {
      "x": -6,
      "y": 12,
      "z": 2,
      "name": "Empty"
    },
    {
      "x": -6,
      "y": 0,
      "z": 3,
      "name": "Rock_Stone"
    },
    {
      "x": -6,
      "y": 1,
      "z": 3,
      "name": "Soil_Dirt"
    },
    {
      "x": -6,
      "y": 2,
      "z": 3,
      "name": "Soil_Dirt"
    },
    {
      "x": -6,
      "y": 3,
      "z": 3,
      "name": "Soil_Dirt"
    },
    {
      "x": -6,
      "y": 4,
      "z": 3,
      "name": "Soil_Grass"
    },
    {
      "x": -6,
      "y": 5,
      "z": 3,
      "name": "Empty"
    },
    {
      "x": -6,
      "y": 6,
      "z": 3,
      "name": "Empty"
    },
    {
      "x": -6,
      "y": 7,
      "z": 3,
      "name": "Empty"
    },
    {
      "x": -6,
      "y": 8,
      "z": 3,
      "name": "Empty"
    },
    {
      "x": -6,
      "y": 9,
      "z": 3,
      "name": "Empty"
    },
    {
      "x": -6,
      "y": 10,
      "z": 3,
      "name": "Empty"
    },
    {
      "x": -6,
      "y": 11,
      "z": 3,
      "name": "Empty"
    },
    {
      "x": -6,
      "y": 12,
      "z": 3,
      "name": "Empty"
    },
    {
      "x": -6,
      "y": 0,
      "z": 4,
      "name": "Rock_Stone"
    },
    {
      "x": -6,
      "y": 1,
      "z": 4,
      "name": "Soil_Dirt"
    },
    {
      "x": -6,
      "y": 2,
      "z": 4,
      "name": "Soil_Dirt"
    },
    {
      "x": -6,
      "y": 3,
      "z": 4,
      "name": "Soil_Dirt"
    },
    {
      "x": -6,
      "y": 4,
      "z": 4,
      "name": "Soil_Grass"
    },
    {
      "x": -6,
      "y": 5,
      "z": 4,
      "name": "Empty"
    },
    {
      "x": -6,
      "y": 6,
      "z": 4,
      "name": "Empty"
    },
    {
      "x": -6,
      "y": 7,
      "z": 4,
      "name": "Empty"
    },
    {
      "x": -6,
      "y": 8,
      "z": 4,
      "name": "Empty"
    },
    {
      "x": -6,
      "y": 9,
      "z": 4,
      "name": "Empty"
    },
    {
      "x": -6,
      "y": 10,
      "z": 4,
      "name": "Empty"
    },
    {
      "x": -6,
      "y": 11,
      "z": 4,
      "name": "Empty"
    },
    {
      "x": -6,
      "y": 12,
      "z": 4,
      "name": "Empty"
    },
    {
      "x": -6,
      "y": 0,
      "z": 5,
      "name": "Rock_Stone"
    },
    {
      "x": -6,
      "y": 1,
      "z": 5,
      "name": "Soil_Dirt"
    },
    {
      "x": -6,
      "y": 2,
      "z": 5,
      "name": "Soil_Dirt"
    },
    {
      "x": -6,
      "y": 3,
      "z": 5,
      "name": "Soil_Dirt"
    },
    {
      "x": -6,
      "y": 4,
      "z": 5,
      "name": "Soil_Grass"
    },
    {
      "x": -6,
      "y": 5,
      "z": 5,
      "name": "Empty"
    },
    {
      "x": -6,
      "y": 6,
      "z": 5,
      "name": "Empty"
    },
    {
      "x": -6,
      "y": 7,
      "z": 5,
      "name": "Empty"
    },
    {
      "x": -6,
      "y": 8,
      "z": 5,
      "name": "Empty"
    },
    {
      "x": -6,
      "y": 9,
      "z": 5,
      "name": "Empty"
    },
    {
      "x": -6,
      "y": 10,
      "z": 5,
      "name": "Empty"
    },
    {
      "x": -6,
      "y": 11,
      "z": 5,
      "name": "Empty"
    },
    {
      "x": -6,
      "y": 12,
      "z": 5,
      "name": "Empty"
    },
    {
      "x": -6,
      "y": 0,
      "z": 6,
      "name": "Rock_Stone"
    },
    {
      "x": -6,
      "y": 1,
      "z": 6,
      "name": "Soil_Dirt"
    },
    {
      "x": -6,
      "y": 2,
      "z": 6,
      "name": "Soil_Dirt"
    },
    {
      "x": -6,
      "y": 3,
      "z": 6,
      "name": "Soil_Dirt"
    },
    {
      "x": -6,
      "y": 4,
      "z": 6,
      "name": "Soil_Grass"
    },
    {
      "x": -6,
      "y": 5,
      "z": 6,
      "name": "Empty"
    },
    {
      "x": -6,
      "y": 6,
      "z": 6,
      "name": "Empty"
    },
    {
      "x": -6,
      "y": 7,
      "z": 6,
      "name": "Empty"
